Workbook

Sheet Bess 11 Part Wise
P1: 46144
B2: Container Make | C2: Block No. | D2: Containers | E2: MWH | F2: IDT Charging / Commissioning Start | G2: Trial-Run Start Date | H2: COD | I2: Status | P2: Remarks
I3: Sr. | J3: Activity | K3: Progress | N3: EDC | O3: vendor
K4: S | L4: C | M4: B
B5: CATL | C5: 1, 2, 3 & 4 | D5: 192 | E5: =D5*5.015 -> 962.88 | I5: 1.1 | J5: BCF Precast Erection & Welding | K5: ='BESS 11'!K143+'BESS 11'!K97+'BESS 11'!K51+'BESS 11'!K6 -> 192 | L5: ='BESS 11'!L143+'BESS 11'!L97+'BESS 11'!L51+'BESS 11'!L6 -> 192 | M5: =K5-L5 -> 0 | O5: MSC
I6: =I5+0.1 -> 1.2 | J6: Battery Container Erection | K6: ='BESS 11'!#REF!+'BESS 11'!#REF!+'BESS 11'!#REF!+'BESS 11'!#REF! -> #REF! | L6: ='BESS 11'!#REF!+'BESS 11'!#REF!+'BESS 11'!#REF!+'BESS 11'!#REF! -> #REF! | M6: =K6-L6 -> #REF! | O6: HEFT & Pratibha
I7: =I6+0.1 -> 1.3 | J7: CT Rail Fixing | K7: ='BESS 11'!K144+'BESS 11'!K98+'BESS 11'!K52+'BESS 11'!K7 -> 24 | L7: ='BESS 11'!L144+'BESS 11'!L98+'BESS 11'!L52+'BESS 11'!L7 -> 24 | M7: =K7-L7 -> 0 | O7: MSC
I8: =I7+0.1 -> 1.4 | J8: CT Erection | K8: ='BESS 11'!K155+'BESS 11'!K110+'BESS 11'!K64+'BESS 11'!K18 -> 24 | L8: ='BESS 11'!L155+'BESS 11'!L110+'BESS 11'!L64+'BESS 11'!L18 -> 24 | M8: =K8-L8 -> 0 | O8: Pratibha
I9: =I8+0.1 -> 1.5 | J9: PCS Slab casting | K9: ='BESS 11'!K145+'BESS 11'!K99+'BESS 11'!K53+'BESS 11'!K8 -> 24 | L9: ='BESS 11'!L145+'BESS 11'!L99+'BESS 11'!L53+'BESS 11'!L8 -> 24 | M9: =K9-L9 -> 0 | O9: MSC
I10: =I9+0.1 -> 1.6 | J10: PCS Erection | K10: ='BESS 11'!K156+'BESS 11'!K111+'BESS 11'!#REF!+'BESS 11'!K19 -> #REF! | L10: ='BESS 11'!L156+'BESS 11'!L111+'BESS 11'!#REF!+'BESS 11'!L19 -> #REF! | M10: =K10-L10 -> #REF! | O10: Pratibha
I11: =I10+0.1 -> 1.7 | J11: ACDB Erection | K11: ='BESS 11'!K157+'BESS 11'!K112+'BESS 11'!K66+'BESS 11'!K20 -> 24 | L11: ='BESS 11'!L157+'BESS 11'!L112+'BESS 11'!L66+'BESS 11'!L20 -> 24 | M11: =K11-L11 -> 0 | O11: Pratibha
I12: =I11+0.1 -> 1.8 | J12: ECP Panel Erection (Communication Panel) | K12: ='BESS 11'!K158+'BESS 11'!K113+'BESS 11'!K67+'BESS 11'!K21 -> 24 | L12: ='BESS 11'!L158+'BESS 11'!L113+'BESS 11'!L67+'BESS 11'!L21 -> 12 | M12: =K12-L12 -> 12 | O12: Pratibha
I13: =I12+0.1 -> 1.9 | J13: PCS PEB | K13: ='BESS 11'!K151+'BESS 11'!K106+'BESS 11'!K60+'BESS 11'!K14 -> 24 | L13: ='BESS 11'!L151+'BESS 11'!L106+'BESS 11'!L60+'BESS 11'!L14 -> 24 | M13: =K13-L13 -> 0 | O13: Synergy
I14: =I5 -> 1.1 | J14: SGR Slab Casting | K14: ='BESS 11'!K146+'BESS 11'!K100+'BESS 11'!K54+'BESS 11'!K9 -> 4 | L14: ='BESS 11'!L146+'BESS 11'!L100+'BESS 11'!L54+'BESS 11'!L9 -> 4 | M14: =K14-L14 -> 0 | O14: MSC
I15: =I14+0.01 -> 1.11 | J15: HT Panel Erection | K15: ='BESS 11'!K159+'BESS 11'!K114+'BESS 11'!K68+'BESS 11'!K22 -> 8 | L15: ='BESS 11'!L159+'BESS 11'!L114+'BESS 11'!L68+'BESS 11'!L22 -> 8 | M15: =K15-L15 -> 0 | O15: Pratibha
I16: =I15+0.01 -> 1.12 | J16: SGR PEB | K16: ='BESS 11'!K152+'BESS 11'!K108+'BESS 11'!K61+'BESS 11'!K15 -> 4 | L16: ='BESS 11'!L152+'BESS 11'!L108+'BESS 11'!L61+'BESS 11'!L15 -> 4 | M16: =K16-L16 -> 0 | O16: Synergy
I17: =I16+0.01 -> 1.13 | J17: MCR Slab Casting | K17: ='BESS 11'!K147+'BESS 11'!K101+'BESS 11'!K56+'BESS 11'!K10 -> 4 | L17: ='BESS 11'!L147+'BESS 11'!L101+'BESS 11'!L56+'BESS 11'!L10 -> 4 | M17: =K17-L17 -> 0 | O17: MSC
I18: =I17+0.01 -> 1.14 | J18: EMS Panel Erection | K18: ='BESS 11'!K160+'BESS 11'!K115+'BESS 11'!K69+'BESS 11'!K23 -> 4 | L18: ='BESS 11'!L160+'BESS 11'!L115+'BESS 11'!L69+'BESS 11'!L23 -> 2 | M18: =K18-L18 -> 2 | O18: Pratibha
I19: =I18+0.01 -> 1.15 | J19: MCR PEB | K19: ='BESS 11'!K153+'BESS 11'!K107+'BESS 11'!K62+'BESS 11'!K16 -> 4 | L19: ='BESS 11'!L153+'BESS 11'!L107+'BESS 11'!L62+'BESS 11'!L16 -> 4 | M19: =K19-L19 -> 0 | O19: Synergy
I20: =I19+0.01 -> 1.16 | J20: CSS Slab Casting | K20: ='BESS 11'!K148+'BESS 11'!K102+'BESS 11'!K55+'BESS 11'!K11 -> 4 | L20: ='BESS 11'!L148+'BESS 11'!L102+'BESS 11'!L55+'BESS 11'!L11 -> 4 | M20: =K20-L20 -> 0 | O20: MSC
I21: =I20+0.01 -> 1.17 | J21: CSS Erection | K21: ='BESS 11'!K161+'BESS 11'!K116+'BESS 11'!K70+'BESS 11'!K24 -> 4 | L21: ='BESS 11'!L161+'BESS 11'!L116+'BESS 11'!L70+'BESS 11'!L24 -> 4 | M21: =K21-L21 -> 0 | O21: Pratibha
I22: =I21+0.01 -> 1.18 | J22: NIFPS Precast Erection | K22: ='BESS 11'!K150+'BESS 11'!K105+'BESS 11'!K57+'BESS 11'!K12 -> 17 | L22: ='BESS 11'!L150+'BESS 11'!L105+'BESS 11'!L57+'BESS 11'!L12 -> 15 | M22: =K22-L22 -> 2 | O22: MSC
I23: =I22+0.01 -> 1.19 | J23: NIFPS Panel Erection | K23: ='BESS 11'!K162+'BESS 11'!K117+'BESS 11'!K71+'BESS 11'!K25 -> 24 | L23: ='BESS 11'!L162+'BESS 11'!L117+'BESS 11'!L71+'BESS 11'!L25 -> 12 | M23: =K23-L23 -> 12 | O23: Ornet
I24: =I23+0.01 -> 1.2 | J24: NIFPS Fabrication | K24: ='BESS 11'!K163+'BESS 11'!K118+'BESS 11'!K72+'BESS 11'!K26 -> 24 | L24: ='BESS 11'!L163+'BESS 11'!L118+'BESS 11'!L72+'BESS 11'!L26 -> 12 | M24: =K24-L24 -> 12 | O24: Ornet
I25: =I24+0.01 -> 1.21 | J25: BOT Precast Erection | K25: ='BESS 11'!K104+'BESS 11'!#REF! -> #REF! | L25: ='BESS 11'!L104+'BESS 11'!#REF! -> #REF! | M25: =K25-L25 -> #REF! | O25: Sachi
I26: =I25+0.01 -> 1.22 | J26: BOT Slab casting | K26: ='BESS 11'!K149+'BESS 11'!K103+'BESS 11'!K59+'BESS 11'!K13 -> 16 | L26: ='BESS 11'!L149+'BESS 11'!L103+'BESS 11'!L59+'BESS 11'!L13 -> 16 | M26: =K26-L26 -> 0 | O26: MSC
I27: =I26+0.01 -> 1.23 | J27: HT cable laying | K27: ='BESS 11'!K165+'BESS 11'!K120+'BESS 11'!K74+'BESS 11'!K28 -> 31595 | L27: ='BESS 11'!L165+'BESS 11'!L120+'BESS 11'!L74+'BESS 11'!L28 -> 31595 | M27: =K27-L27 -> 0 | O27: Pratibha
I28: =I27+0.01 -> 1.24 | J28: HT cable termination | K28: ='BESS 11'!K166+'BESS 11'!K121+'BESS 11'!K75+'BESS 11'!K29 -> 112 | L28: ='BESS 11'!L166+'BESS 11'!L121+'BESS 11'!L75+'BESS 11'!L29 -> 112 | M28: =K28-L28 -> 0 | O28: Pratibha
I29: =I28+0.01 -> 1.25 | J29: DC & LT cable laying | K29: ='BESS 11'!K167+'BESS 11'!K122+'BESS 11'!K76+'BESS 11'!K30 -> 53748 | L29: ='BESS 11'!L167+'BESS 11'!L122+'BESS 11'!L76+'BESS 11'!L30 -> 53748 | M29: =K29-L29 -> 0 | O29: Pratibha
I30: =I29+0.01 -> 1.26 | J30: DC & LT cable termination | K30: ='BESS 11'!K169+'BESS 11'!K124+'BESS 11'!K78+'BESS 11'!K32 -> 6144 | L30: ='BESS 11'!L169+'BESS 11'!L124+'BESS 11'!L78+'BESS 11'!L32 -> 3072 | M30: =K30-L30 -> 3072 | O30: Pratibha
I31: =I30+0.01 -> 1.27 | J31: Aux, Control & communication cable laying | K31: ='BESS 11'!K171+'BESS 11'!K126+'BESS 11'!K80+'BESS 11'!K34 -> 32729 | L31: ='BESS 11'!L171+'BESS 11'!L126+'BESS 11'!L80+'BESS 11'!L34 -> 23132 | M31: =K31-L31 -> 9597 | O31: Pratibha
I32: =I31+0.01 -> 1.28 | J32: CT Testing | K32: ='BESS 11'!K177+'BESS 11'!K132+'BESS 11'!K86+'BESS 11'!K40 -> 24 | L32: ='BESS 11'!L177+'BESS 11'!L132+'BESS 11'!L86+'BESS 11'!L40 -> 24 | M32: =K32-L32 -> 0 | O32: Pratibha
I33: =I32+0.01 -> 1.29 | J33: HTP testing | K33: ='BESS 11'!K180+'BESS 11'!K135+'BESS 11'!K89+'BESS 11'!K43 -> 48 | L33: ='BESS 11'!L180+'BESS 11'!L135+'BESS 11'!L89+'BESS 11'!L43 -> 12 | M33: =K33-L33 -> 36 | O33: Pratibha
I34: =I33+0.01 -> 1.3 | J34: Earthing | K34: ='BESS 11'!K185+'BESS 11'!K140+'BESS 11'!K94+'BESS 11'!K48 -> 17921.8 | L34: ='BESS 11'!L185+'BESS 11'!L140+'BESS 11'!L94+'BESS 11'!L48 -> 8507.7 | M34: =K34-L34 -> 9414.1 | O34: Pratibha
I35: =I34+0.01 -> 1.31 | J35: LA | K35: ='BESS 11'!K186+'BESS 11'!K141+'BESS 11'!K95+'BESS 11'!K49 -> 40 | L35: ='BESS 11'!L186+'BESS 11'!L141+'BESS 11'!L95+'BESS 11'!L49 -> 10 | M35: =K35-L35 -> 30 | O35: Pratibha
B36: CATL | C36: 5, 6, 7 & 8 | D36: 48 | E36: 240.72 | I36: 2.1 | J36: BCF Precast Erection & Welding | K36: ='BESS 11'!K188+'BESS 11'!K233+'BESS 11'!K278+'BESS 11'!K323 -> 192 | L36: ='BESS 11'!L188+'BESS 11'!L233+'BESS 11'!L278+'BESS 11'!L323 -> 192 | M36: =K36-L36 -> 0 | O36: MSC
I37: =I36+0.1 -> 2.2 | J37: Battery Container Erection | K37: ='BESS 11'!#REF!+'BESS 11'!#REF!+'BESS 11'!#REF!+'BESS 11'!#REF! -> #REF! | L37: ='BESS 11'!#REF!+'BESS 11'!#REF!+'BESS 11'!#REF!+'BESS 11'!#REF! -> #REF! | M37: =K37-L37 -> #REF! | O37: HEFT & Pratibha
I38: =I37+0.1 -> 2.3 | J38: CT Rail Fixing | K38: ='BESS 11'!K189+'BESS 11'!K234+'BESS 11'!K279+'BESS 11'!K324 -> 24 | L38: ='BESS 11'!L189+'BESS 11'!L234+'BESS 11'!L279+'BESS 11'!L324 -> 24 | M38: =K38-L38 -> 0 | O38: MSC
I39: =I38+0.1 -> 2.4 | J39: CT Erection | K39: ='BESS 11'!K200+'BESS 11'!K245+'BESS 11'!K290+'BESS 11'!K335 -> 24 | L39: ='BESS 11'!L200+'BESS 11'!L245+'BESS 11'!L290+'BESS 11'!L335 -> 12 | M39: =K39-L39 -> 12 | O39: Pratibha
I40: =I39+0.1 -> 2.5 | J40: PCS Slab casting | K40: ='BESS 11'!K190+'BESS 11'!K235+'BESS 11'!K280+'BESS 11'!K325 -> 24 | L40: ='BESS 11'!L190+'BESS 11'!L235+'BESS 11'!L280+'BESS 11'!L325 -> 24 | M40: =K40-L40 -> 0 | O40: MSC
...

Sheet 12 - Daily requirement (2)
B1: IDT Charging / Commissioning Start | C1: ='BESS 11'!$G$2 -> Trial-Run End Date | D1: ='BESS 11'!$H$2 -> COD | E1: Activity | F1: Mandays | G1: Days | H1: Min. Date | I1: 46195 | J1: 46196 | K1: =MIN('BESS 11'!O18:O25,'BESS 11'!O27) -> 0 | L1: =K1+1 -> 1 | M1: =L1+1 -> 2 | N1: =M1+1 -> 3 | O1: =N1+1 -> 4 | P1: =O1+1 -> 5 | Q1: =P1+1 -> 6 | R1: =Q1+1 -> 7 | S1: =R1+1 -> 8 | ... CP1: =CO1+1 -> 83 | CQ1: Average Manpower | CR1: Peak Manpower | CS1: =CR1+1 -> #VALUE! | CT1: 46282 | CU1: 46283 | CV1: 46284 | CW1: 46285 | CX1: 46286 | CY1: 46287 | CZ1: 46288 | DA1: 46289 | DB1: 46290 | DC1: 46291 | DD1: 46292 | DE1: 46293 | DF1: 46294 | DG1: 46295 | DH1: 46296 | DI1: 46297 | DJ1: 46298 | DK1: 46299 | DL1: 46300 | DM1: 46301 | DN1: 46302 | DO1: 46303 | DP1: 46304 | DQ1: 46305 | DR1: 46306 | DS1: 46307 | DT1: 46308 | DU1: 46309 | DV1: 46310 | DW1: 46311 | DX1: 46312 | DY1: 46313 | DZ1: 46314 | EA1: 46315 | EB1: 46316 | EC1: 46317 | ED1: 46318 | EE1: 46319 | EF1: 46320 | EG1: 46321 | EH1: 46322 | EI1: 46323 | EJ1: 46324 | EK1: 46325 | EL1: 46326 | EM1: 46327 | EN1: 46328 | EO1: 46329 | EP1: 46330 | EQ1: 46331 | ER1: 46332 | ES1: 46333 | ET1: 46334 | EU1: 46335 | EV1: 46336 | EW1: 46337 | EX1: 46338 | EY1: 46339 | EZ1: 46340 | FA1: 46341 | FB1: 46342 | FC1: 46343 | FD1: 46344 | FE1: 46345 | FF1: 46346 | FG1: 46347 | FH1: 46348 | FI1: 46349 | FJ1: 46350 | FK1: 46351 | FL1: 46352 | FM1: 46353 | FN1: 46354 | FO1: 46355 | FP1: 46356 | FQ1: 46357 | FR1: 46358 | FS1: 46359 | FT1: 46360 | FU1: 46361 | FV1: 46362 | FW1: 46363 | FX1: 46364 | FY1: 46365 | FZ1: 46366 | GA1: 46367 | GB1: 46368 | GC1: 46369 | GD1: 46370 | GE1: 46371 | GF1: 46372 | GG1: 46373 | GH1: 46374 | GI1: 46375 | GJ1: 46376 | GK1: 46377 | GL1: 46378 | GM1: 46379 | GN1: 46380 | GO1: 46381 | GP1: 46382 | GQ1: 46383 | GR1: 46384 | GS1: 46385 | GT1: 46386 | GU1: 46387
A2: Block 1 | B2: ='BESS 12'!F51 -> 46231 | C2: ='BESS 12'!G51 -> 46236 | D2: ='BESS 12'!H51 -> 46239 | E2: Erection | F2: =SUM('BESS 12'!S64:S71,'BESS 12'!S73) -> #VALUE! | G2: =MAX('BESS 12'!O64:O71,'BESS 12'!O73)-MIN('BESS 12'!O64:O71,'BESS 12'!O73)+1 -> 1 | H2: =MIN('BESS 12'!O64:O71,'BESS 12'!O73) -> 0 | I2: =IF(AND(I$1>=$H2,I$1<($H2+$G2)),ROUND($F2/$G2,0),"-") -> - | J2: =IF(AND(J$1>=$H2,J$1<($H2+$G2)),ROUND($F2/$G2,0),"-") -> - | K2: =IF(AND(K$1>=$H2,K$1<($H2+$G2)),ROUND($F2/$G2,0),"-") -> #VALUE! | L2: =IF(AND(L$1>=$H2,L$1<($H2+$G2)),ROUND($F2/$G2,0),"-") -> - | M2: =IF(AND(M$1>=$H2,M$1<($H2+$G2)),ROUND($F2/$G2,0),"-") -> - | N2: =IF(AND(N$1>=$H2,N$1<($H2+$G2)),ROUND($F2/$G2,0),"-") -> - | O2: =IF(AND(O$1>=$H2,O$1<($H2+$G2)),ROUND($F2/$G2,0),"-") -> - | P2: =IF(AND(P$1>=$H2,P$1<($H2+$G2)),ROUND($F2/$G2,0),"-") -> - | ... CP2: =IF(AND(CP$1>=$H2,CP$1<($H2+$G2)),ROUND($F2/$G2,0),"-") -> -
E3: Cable Laying | F3: =SUM('BESS 12'!S74,'BESS 12'!S76:S77,'BESS 12'!S80:S82) -> #VALUE! | G3: =MAX('BESS 12'!O74,'BESS 12'!O76:O77,'BESS 12'!O80:O82)-MIN('BESS 12'!O74,'BESS 12'!O76:O77,'BESS 12'!O80:O82)+1 -> 1 | H3: =MIN('BESS 12'!O74,'BESS 12'!O76:O77,'BESS 12'!O80:O82) -> 0 | I3: =IF(AND(I$1>=$H3,I$1<($H3+$G3)),ROUND($F3/$G3,0),"-") -> - | J3: =IF(AND(J$1>=$H3,J$1<($H3+$G3)),ROUND($F3/$G3,0),"-") -> - | K3: =IF(AND(K$1>=$H3,K$1<($H3+$G3)),ROUND($F3/$G3,0),"-") -> #VALUE! | L3: =IF(AND(L$1>=$H3,L$1<($H3+$G3)),ROUND($F3/$G3,0),"-") -> - | M3: =IF(AND(M$1>=$H3,M$1<($H3+$G3)),ROUND($F3/$G3,0),"-") -> - | N3: =IF(AND(N$1>=$H3,N$1<($H3+$G3)),ROUND($F3/$G3,0),"-") -> - | O3: =IF(AND(O$1>=$H3,O$1<($H3+$G3)),ROUND($F3/$G3,0),"-") -> - | P3: =IF(AND(P$1>=$H3,P$1<($H3+$G3)),ROUND($F3/$G3,0),"-") -> - | ... CP3: =IF(AND(CP$1>=$H3,CP$1<($H3+$G3)),ROUND($F3/$G3,0),"-") -> -
E4: Termination | F4: =SUM('BESS 12'!S75,'BESS 12'!S78:S79,'BESS 12'!S83:S84) -> #VALUE! | G4: =MAX('BESS 12'!O75,'BESS 12'!O78:O79,'BESS 12'!O83:O84)-MIN('BESS 12'!O75,'BESS 12'!O78:O79,'BESS 12'!O83:O84)+1 -> 1 | H4: =MIN('BESS 12'!O75,'BESS 12'!O78:O79,'BESS 12'!O83:O84) -> 46233 | I4: =IF(AND(I$1>=$H4,I$1<($H4+$G4)),ROUND($F4/$G4,0),"-") -> - | J4: =IF(AND(J$1>=$H4,J$1<($H4+$G4)),ROUND($F4/$G4,0),"-") -> - | K4: =IF(AND(K$1>=$H4,K$1<($H4+$G4)),ROUND($F4/$G4,0),"-") -> - | L4: =IF(AND(L$1>=$H4,L$1<($H4+$G4)),ROUND($F4/$G4,0),"-") -> - | M4: =IF(AND(M$1>=$H4,M$1<($H4+$G4)),ROUND($F4/$G4,0),"-") -> - | N4: =IF(AND(N$1>=$H4,N$1<($H4+$G4)),ROUND($F4/$G4,0),"-") -> - | O4: =IF(AND(O$1>=$H4,O$1<($H4+$G4)),ROUND($F4/$G4,0),"-") -> - | P4: =IF(AND(P$1>=$H4,P$1<($H4+$G4)),ROUND($F4/$G4,0),"-") -> - | ... CP4: =IF(AND(CP$1>=$H4,CP$1<($H4+$G4)),ROUND($F4/$G4,0),"-") -> -
E5: Testing | F5: =SUM('BESS 12'!S88:S95) -> #VALUE! | G5: =MAX('BESS 12'!O88:O95)-MIN('BESS 12'!O88:O95)+1 -> 1 | H5: =MIN('BESS 12'!O88:O95) -> 46233 | I5: =IF(AND(I$1>=$H5,I$1<($H5+$G5)),ROUND($F5/$G5,0),"-") -> - | J5: =IF(AND(J$1>=$H5,J$1<($H5+$G5)),ROUND($F5/$G5,0),"-") -> - | K5: =IF(AND(K$1>=$H5,K$1<($H5+$G5)),ROUND($F5/$G5,0),"-") -> - | L5: =IF(AND(L$1>=$H5,L$1<($H5+$G5)),ROUND($F5/$G5,0),"-") -> - | M5: =IF(AND(M$1>=$H5,M$1<($H5+$G5)),ROUND($F5/$G5,0),"-") -> - | N5: =IF(AND(N$1>=$H5,N$1<($H5+$G5)),ROUND($F5/$G5,0),"-") -> - | O5: =IF(AND(O$1>=$H5,O$1<($H5+$G5)),ROUND($F5/$G5,0),"-") -> - | P5: =IF(AND(P$1>=$H5,P$1<($H5+$G5)),ROUND($F5/$G5,0),"-") -> - | ... CP5: =IF(AND(CP$1>=$H5,CP$1<($H5+$G5)),ROUND($F5/$G5,0),"-") -> -
E6: CFT | F6: 250 | G6: 30 | H6: =B2-3 -> 46228 | T6: 5 | U6: 5 | V6: 5 | W6: 5 | X6: 5 | Y6: 5 | Z6: 5 | AA6: 5 | AB6: 5 | AC6: 5 | AD6: 5 | AE6: 5 | AF6: 5 | AG6: 5 | AH6: 5 | AI6: 5 | AJ6: 5 | AK6: 5 | AL6: 5 | AM6: 5 | AN6: 5 | AO6: 5 | AP6: 5 | AQ6: 5 | AR6: 30 | AS6: 30 | AT6: 30 | AU6: 30 | AV6: 5 | AW6: 5
H7: Total | I7: =SUM(I2:I6) -> 0 | J7: =SUM(J2:J6) -> 0 | K7: =SUM(K2:K6) -> #VALUE! | L7: =SUM(L2:L6) -> 0 | M7: =SUM(M2:M6) -> 0 | N7: =SUM(N2:N6) -> 0 | O7: =SUM(O2:O6) -> 0 | P7: =SUM(P2:P6) -> 0 | ... AW7: =SUM(AW2:AW6) -> 5 | CQ7: =AVERAGE(I7:AY7) -> #VALUE! | CR7: =MAX(I7:AY7) -> #VALUE!
A9: Block 2 | B9: ='BESS 12'!F96 -> 31 Jul 02 Aug | C9: ='BESS 12'!G96 -> 05 Aug 07 Aug | E9: Activity | F9: Mandays | G9: Days | H9: Min. Date | I9: 46195 | J9: 46196 | K9: =MIN('BESS 11'!O26:O33,'BESS 11'!O35) -> 0 | L9: =K9+1 -> 1 | M9: =L9+1 -> 2 | N9: =M9+1 -> 3 | O9: =N9+1 -> 4 | P9: =O9+1 -> 5 | Q9: =P9+1 -> 6 | R9: =Q9+1 -> 7 | S9: =R9+1 -> 8 | ... CP9: =CO9+1 -> 83
D10: ='BESS 12'!H96 -> 08 Aug 10 Aug | E10: Erection | F10: =SUM('BESS 12'!S109:S116,'BESS 12'!S118) -> #VALUE! | G10: =MAX('BESS 11'!O64:O71,'BESS 11'!O73)-MIN('BESS 11'!O64:O71,'BESS 11'!O73)+1 -> 1 | H10: =MIN('BESS 12'!O109:O116,'BESS 12'!O118) -> 46229 | I10: =IF(AND(I$1>=$H10,I$1<($H10+$G10)),ROUND($F10/$G10,0),"-") -> - | J10: =IF(AND(J$1>=$H10,J$1<($H10+$G10)),ROUND($F10/$G10,0),"-") -> - | K10: =IF(AND(K$1>=$H10,K$1<($H10+$G10)),ROUND($F10/$G10,0),"-") -> - | L10: =IF(AND(L$1>=$H10,L$1<($H10+$G10)),ROUND($F10/$G10,0),"-") -> - | M10: =IF(AND(M$1>=$H10,M$1<($H10+$G10)),ROUND($F10/$G10,0),"-") -> - | N10: =IF(AND(N$1>=$H10,N$1<($H10+$G10)),ROUND($F10/$G10,0),"-") -> - | O10: =IF(AND(O$1>=$H10,O$1<($H10+$G10)),ROUND($F10/$G10,0),"-") -> - | P10: =IF(AND(P$1>=$H10,P$1<($H10+$G10)),ROUND($F10/$G10,0),"-") -> - | ... CP10: =IF(AND(CP$1>=$H10,CP$1<($H10+$G10)),ROUND($F10/$G10,0),"-") -> -
E11: Cable Laying | F11: =SUM('BESS 12'!S119,'BESS 12'!S121:S122,'BESS 12'!S125:S127) -> #VALUE! | G11: =MAX('BESS 12'!O119,'BESS 12'!O121:O122,'BESS 12'!O125:O127)-MIN('BESS 12'!O119,'BESS 12'!O121:O122,'BESS 12'!O125:O127)+1 -> 1 | H11: =MIN('BESS 12'!O119,'BESS 12'!O121:O122,'BESS 12'!O125:O127) -> 46233 | I11: =IF(AND(I$1>=$H11,I$1<($H11+$G11)),ROUND($F11/$G11,0),"-") -> - | J11: =IF(AND(J$1>=$H11,J$1<($H11+$G11)),ROUND($F11/$G11,0),"-") -> - | K11: =IF(AND(K$1>=$H11,K$1<($H11+$G11)),ROUND($F11/$G11,0),"-") -> - | L11: =IF(AND(L$1>=$H11,L$1<($H11+$G11)),ROUND($F11/$G11,0),"-") -> - | M11: =IF(AND(M$1>=$H11,M$1<($H11+$G11)),ROUND($F11/$G11,0),"-") -> - | N11: =IF(AND(N$1>=$H11,N$1<($H11+$G11)),ROUND($F11/$G11,0),"-") -> - | O11: =IF(AND(O$1>=$H11,O$1<($H11+$G11)),ROUND($F11/$G11,0),"-") -> - | P11: =IF(AND(P$1>=$H11,P$1<($H11+$G11)),ROUND($F11/$G11,0),"-") -> - | ... CP11: =IF(AND(CP$1>=$H11,CP$1<($H11+$G11)),ROUND($F11/$G11,0),"-") -> -
E12: Termination | F12: =SUM('BESS 12'!S120,'BESS 12'!S123:S124,'BESS 12'!S128:S129) -> #VALUE! | G12: =MAX('BESS 12'!O120,'BESS 12'!O123:O124,'BESS 12'!O128:O129)-MIN('BESS 12'!O120,'BESS 12'!O123:O124,'BESS 12'!O128:O129)+1 -> 32 | H12: =MIN('BESS 12'!O120,'BESS 12'!O123:O124,'BESS 12'!O128:O129) -> 46234 | I12: =IF(AND(I$1>=$H12,I$1<($H12+$G12)),ROUND($F12/$G12,0),"-") -> - | J12: =IF(AND(J$1>=$H12,J$1<($H12+$G12)),ROUND($F12/$G12,0),"-") -> - | K12: =IF(AND(K$1>=$H12,K$1<($H12+$G12)),ROUND($F12/$G12,0),"-") -> - | L12: =IF(AND(L$1>=$H12,L$1<($H12+$G12)),ROUND($F12/$G12,0),"-") -> - | M12: =IF(AND(M$1>=$H12,M$1<($H12+$G12)),ROUND($F12/$G12,0),"-") -> - | N12: =IF(AND(N$1>=$H12,N$1<($H12+$G12)),ROUND($F12/$G12,0),"-") -> - | O12: =IF(AND(O$1>=$H12,O$1<($H12+$G12)),ROUND($F12/$G12,0),"-") -> - | P12: =IF(AND(P$1>=$H12,P$1<($H12+$G12)),ROUND($F12/$G12,0),"-") -> - | ... CP12: =IF(AND(CP$1>=$H12,CP$1<($H12+$G12)),ROUND($F12/$G12,0),"-") -> -
E13: Testing | F13: =SUM('BESS 12'!S133:S140) -> #VALUE! | G13: =MAX('BESS 11'!O87:O95)-MIN('BESS 11'!O87:O95)+1 -> 5 | H13: =MIN('BESS 12'!O133:O140) -> 46235 | I13: =IF(AND(I$1>=$H13,I$1<($H13+$G13)),ROUND($F13/$G13,0),"-") -> - | J13: =IF(AND(J$1>=$H13,J$1<($H13+$G13)),ROUND($F13/$G13,0),"-") -> - | K13: =IF(AND(K$1>=$H13,K$1<($H13+$G13)),ROUND($F13/$G13,0),"-") -> - | L13: =IF(AND(L$1>=$H13,L$1<($H13+$G13)),ROUND($F13/$G13,0),"-") -> - | M13: =IF(AND(M$1>=$H13,M$1<($H13+$G13)),ROUND($F13/$G13,0),"-") -> - | N13: =IF(AND(N$1>=$H13,N$1<($H13+$G13)),ROUND($F13/$G13,0),"-") -> - | O13: =IF(AND(O$1>=$H13,O$1<($H13+$G13)),ROUND($F13/$G13,0),"-") -> - | P13: =IF(AND(P$1>=$H13,P$1<($H13+$G13)),ROUND($F13/$G13,0),"-") -> - | ... CP13: =IF(AND(CP$1>=$H13,CP$1<($H13+$G13)),ROUND($F13/$G13,0),"-") -> -
E14: CFT | F14: 250 | G14: 30 | H14: =B9-3 -> #VALUE! | V14: 5 | W14: 5 | X14: 5 | Y14: 5 | Z14: 5 | AA14: 5 | AB14: 5 | AC14: 5 | AD14: 5 | AE14: 5 | AF14: 5 | AG14: 5 | AH14: 5 | AI14: 5 | AJ14: 5 | AK14: 5 | AL14: 5 | AM14: 5 | AN14: 5 | AO14: 5 | AP14: 5 | AQ14: 5 | AR14: 5 | AS14: 5 | AT14: 30 | AU14: 30 | AV14: 30 | AW14: 30 | AX14: 5 | AY14: 5
H15: Total | I15: =SUM(I10:I14) -> 0 | J15: =SUM(J10:J14) -> 0 | K15: =SUM(K10:K14) -> 0 | L15: =SUM(L10:L14) -> 0 | M15: =SUM(M10:M14) -> 0 | N15: =SUM(N10:N14) -> 0 | O15: =SUM(O10:O14) -> 0 | P15: =SUM(P10:P14) -> 0 | ... AY15: =SUM(AY10:AY14) -> 5 | CQ15: =AVERAGE(I15:BA15) -> 5.8139535 | CR15: =MAX(I15:BA15) -> 30
A17: Block 4 | B17: ='BESS 12'!F5 -> 24 Jul 28 Jul | C17: ='BESS 12'!G5 -> 29 Jul 02 Aug | E17: Activity | F17: Mandays | G17: Days | H17: Min. Date | I17: 46195 | J17: 46196 | K17: 46197 | L17: =K17+1 -> 46198 | M17: =L17+1 -> 46199 | N17: =M17+1 -> 46200 | O17: =N17+1 -> 46201 | P17: =O17+1 -> 46202 | Q17: =P17+1 -> 46203 | R17: =Q17+1 -> 46204 | S17: =R17+1 -> 46205 | ... CP17: =CO17+1 -> 46280
D18: ='BESS 12'!H5 -> 01 Aug 05 Aug | E18: Erection | F18: =SUM('BESS 12'!S19:S26,'BESS 12'!S28) -> #VALUE! | G18: =MAX('BESS 12'!O19:O26,'BESS 12'!O28)-MIN('BESS 12'!O19:O26,'BESS 12'!O28)+1 -> 1 | H18: =MIN('BESS 12'!O19:O26,'BESS 12'!O28) -> 0 | I18: =IF(AND(I$1>=$H18,I$1<($H18+$G18)),ROUND($F18/$G18,0),"-") -> - | J18: =IF(AND(J$1>=$H18,J$1<($H18+$G18)),ROUND($F18/$G18,0),"-") -> - | K18: =IF(AND(K$1>=$H18,K$1<($H18+$G18)),ROUND($F18/$G18,0),"-") -> #VALUE! | L18: =IF(AND(L$1>=$H18,L$1<($H18+$G18)),ROUND($F18/$G18,0),"-") -> - | M18: =IF(AND(M$1>=$H18,M$1<($H18+$G18)),ROUND($F18/$G18,0),"-") -> - | N18: =IF(AND(N$1>=$H18,N$1<($H18+$G18)),ROUND($F18/$G18,0),"-") -> - | O18: =IF(AND(O$1>=$H18,O$1<($H18+$G18)),ROUND($F18/$G18,0),"-") -> - | P18: =IF(AND(P$1>=$H18,P$1<($H18+$G18)),ROUND($F18/$G18,0),"-") -> - | ... CP18: =IF(AND(CP$1>=$H18,CP$1<($H18+$G18)),ROUND($F18/$G18,0),"-") -> -
E19: Cable Laying | F19: =SUM('BESS 12'!S29,'BESS 12'!S31,'BESS 12'!S32,'BESS 12'!S35:S37) -> #VALUE! | G19: =MAX('BESS 12'!O29,'BESS 12'!O31,'BESS 12'!O32,'BESS 12'!O35:O37)-MIN('BESS 12'!O29,'BESS 12'!O31,'BESS 12'!O32,'BESS 12'!O35:O37)+1 -> 1 | H19: =MIN('BESS 12'!O29,'BESS 12'!O31,'BESS 12'!O32,'BESS 12'!O35:O37) -> 0 | I19: =IF(AND(I$1>=$H19,I$1<($H19+$G19)),ROUND($F19/$G19,0),"-") -> - | J19: =IF(AND(J$1>=$H19,J$1<($H19+$G19)),ROUND($F19/$G19,0),"-") -> - | K19: =IF(AND(K$1>=$H19,K$1<($H19+$G19)),ROUND($F19/$G19,0),"-") -> #VALUE! | L19: =IF(AND(L$1>=$H19,L$1<($H19+$G19)),ROUND($F19/$G19,0),"-") -> - | M19: =IF(AND(M$1>=$H19,M$1<($H19+$G19)),ROUND($F19/$G19,0),"-") -> - | N19: =IF(AND(N$1>=$H19,N$1<($H19+$G19)),ROUND($F19/$G19,0),"-") -> - | O19: =IF(AND(O$1>=$H19,O$1<($H19+$G19)),ROUND($F19/$G19,0),"-") -> - | P19: =IF(AND(P$1>=$H19,P$1<($H19+$G19)),ROUND($F19/$G19,0),"-") -> - | ... CP19: =IF(AND(CP$1>=$H19,CP$1<($H19+$G19)),ROUND($F19/$G19,0),"-") -> -
E20: Termination | F20: =SUM('BESS 12'!S30,'BESS 12'!S33:S34,'BESS 12'!S38:S39) -> #VALUE! | G20: =MAX('BESS 12'!O30,'BESS 12'!O32,'BESS 12'!O33,'BESS 12'!O36:O38)-MIN('BESS 12'!O30,'BESS 12'!O32,'BESS 12'!O33,'BESS 12'!O36:O38)+1 -> 1 | H20: =MIN('BESS 12'!O30,'BESS 12'!O33:O34,'BESS 12'!O38:O39) -> 0 | I20: =IF(AND(I$1>=$H20,I$1<($H20+$G20)),ROUND($F20/$G20,0),"-") -> - | J20: =IF(AND(J$1>=$H20,J$1<($H20+$G20)),ROUND($F20/$G20,0),"-") -> - | K20: =IF(AND(K$1>=$H20,K$1<($H20+$G20)),ROUND($F20/$G20,0),"-") -> #VALUE! | L20: =IF(AND(L$1>=$H20,L$1<($H20+$G20)),ROUND($F20/$G20,0),"-") -> - | M20: =IF(AND(M$1>=$H20,M$1<($H20+$G20)),ROUND($F20/$G20,0),"-") -> - | N20: =IF(AND(N$1>=$H20,N$1<($H20+$G20)),ROUND($F20/$G20,0),"-") -> - | O20: =IF(AND(O$1>=$H20,O$1<($H20+$G20)),ROUND($F20/$G20,0),"-") -> - | P20: =IF(AND(P$1>=$H20,P$1<($H20+$G20)),ROUND($F20/$G20,0),"-") -> - | ... CP20: =IF(AND(CP$1>=$H20,CP$1<($H20+$G20)),ROUND($F20/$G20,0),"-") -> -
E21: Testing | F21: =SUM('BESS 12'!S43:S50) -> #VALUE! | G21: =MAX('BESS 12'!O43:O50)-MIN('BESS 12'!O43:O50)+1 -> 1 | H21: =MIN('BESS 12'!O43:O50) -> 0 | I21: =IF(AND(I$1>=$H21,I$1<($H21+$G21)),ROUND($F21/$G21,0),"-") -> - | J21: =IF(AND(J$1>=$H21,J$1<($H21+$G21)),ROUND($F21/$G21,0),"-") -> - | K21: =IF(AND(K$1>=$H21,K$1<($H21+$G21)),ROUND($F21/$G21,0),"-") -> #VALUE! | L21: =IF(AND(L$1>=$H21,L$1<($H21+$G21)),ROUND($F21/$G21,0),"-") -> - | M21: =IF(AND(M$1>=$H21,M$1<($H21+$G21)),ROUND($F21/$G21,0),"-") -> - | N21: =IF(AND(N$1>=$H21,N$1<($H21+$G21)),ROUND($F21/$G21,0),"-") -> - | O21: =IF(AND(O$1>=$H21,O$1<($H21+$G21)),ROUND($F21/$G21,0),"-") -> - | P21: =IF(AND(P$1>=$H21,P$1<($H21+$G21)),ROUND($F21/$G21,0),"-") -> - | ... CP21: =IF(AND(CP$1>=$H21,CP$1<($H21+$G21)),ROUND($F21/$G21,0),"-") -> -
E22: CFT | F22: 250 | G22: 30 | H22: =B17-3 -> #VALUE! | Y22: 5 | Z22: 5 | AA22: 5 | AB22: 5 | AC22: 5 | AD22: 5 | AE22: 5 | AF22: 5 | AG22: 5 | AH22: 5 | AI22: 5 | AJ22: 5 | AK22: 5 | AL22: 5 | AM22: 5 | AN22: 5 | AO22: 5 | AP22: 5 | AQ22: 5 | AR22: 5 | AS22: 5 | AT22: 5 | AU22: 5 | AV22: 5 | AW22: 30 | AX22: 30 | AY22: 30 | AZ22: 30 | BA22: 5 | BB22: 5
H23: Total | I23: =SUM(I18:I22) -> 0 | J23: =SUM(J18:J22) -> 0 | K23: =SUM(K18:K22) -> #VALUE! | L23: =SUM(L18:L22) -> 0 | M23: =SUM(M18:M22) -> 0 | N23: =SUM(N18:N22) -> 0 | O23: =SUM(O18:O22) -> 0 | P23: =SUM(P18:P22) -> 0 | ... BO23: =SUM(BO18:BO22) -> 0 | CQ23: =AVERAGE(I23:BD23) -> #VALUE! | CR23: =MAX(I23:BD23) -> #VALUE!
A25: Block 3 | B25: ='BESS 12'!F141 -> 46240 | C25: ='BESS 12'!G141 -> 46245 | E25: Activity | F25: Mandays | G25: Days | H25: Min. Date | I25: 46195 | J25: 46196 | K25: 46197 | L25: =K25+1 -> 46198 | M25: =L25+1 -> 46199 | N25: =M25+1 -> 46200 | O25: =N25+1 -> 46201 | P25: =O25+1 -> 46202 | Q25: =P25+1 -> 46203 | R25: =Q25+1 -> 46204 | S25: =R25+1 -> 46205 | ... CP25: =CO25+1 -> 46280
D26: ='BESS 12'!H141 -> 46248 | E26: Erection | F26: =SUM('BESS 12'!S154:S161,'BESS 12'!S163) -> #VALUE! | G26: =MAX('BESS 11'!O155:O162,'BESS 11'!O164)-MIN('BESS 11'!O155:O162,'BESS 11'!O164)+1 -> 10 | H26: =MIN('BESS 12'!O154:O161,'BESS 12'!O163) -> 46229 | I26: =IF(AND(I$1>=$H26,I$1<($H26+$G26)),ROUND($F26/$G26,0),"-") -> - | J26: =IF(AND(J$1>=$H26,J$1<($H26+$G26)),ROUND($F26/$G26,0),"-") -> - | K26: =IF(AND(K$1>=$H26,K$1<($H26+$G26)),ROUND($F26/$G26,0),"-") -> - | L26: =IF(AND(L$1>=$H26,L$1<($H26+$G26)),ROUND($F26/$G26,0),"-") -> - | M26: =IF(AND(M$1>=$H26,M$1<($H26+$G26)),ROUND($F26/$G26,0),"-") -> - | N26: =IF(AND(N$1>=$H26,N$1<($H26+$G26)),ROUND($F26/$G26,0),"-") -> - | O26: =IF(AND(O$1>=$H26,O$1<($H26+$G26)),ROUND($F26/$G26,0),"-") -> - | P26: =IF(AND(P$1>=$H26,P$1<($H26+$G26)),ROUND($F26/$G26,0),"-") -> - | ... CP26: =IF(AND(CP$1>=$H26,CP$1<($H26+$G26)),ROUND($F26/$G26,0),"-") -> -
E27: Cable Laying | F27: =SUM('BESS 12'!S164,'BESS 12'!S166:S167,'BESS 12'!S170:S172) -> #VALUE! | G27: =MAX('BESS 11'!O165,'BESS 11'!O167:O168,'BESS 11'!O171:O173)-MIN('BESS 11'!O165,'BESS 11'!O167:O168,'BESS 11'!O171:O173)+1 -> 1 | H27: =MIN('BESS 12'!O164,'BESS 12'!O166:O167,'BESS 12'!O170:O172) -> 46232 | I27: =IF(AND(I$1>=$H27,I$1<($H27+$G27)),ROUND($F27/$G27,0),"-") -> - | J27: =IF(AND(J$1>=$H27,J$1<($H27+$G27)),ROUND($F27/$G27,0),"-") -> - | K27: =IF(AND(K$1>=$H27,K$1<($H27+$G27)),ROUND($F27/$G27,0),"-") -> - | L27: =IF(AND(L$1>=$H27,L$1<($H27+$G27)),ROUND($F27/$G27,0),"-") -> - | M27: =IF(AND(M$1>=$H27,M$1<($H27+$G27)),ROUND($F27/$G27,0),"-") -> - | N27: =IF(AND(N$1>=$H27,N$1<($H27+$G27)),ROUND($F27/$G27,0),"-") -> - | O27: =IF(AND(O$1>=$H27,O$1<($H27+$G27)),ROUND($F27/$G27,0),"-") -> - | P27: =IF(AND(P$1>=$H27,P$1<($H27+$G27)),ROUND($F27/$G27,0),"-") -> - | ... CP27: =IF(AND(CP$1>=$H27,CP$1<($H27+$G27)),ROUND($F27/$G27,0),"-") -> -
E28: Termination | F28: =SUM('BESS 12'!S165,'BESS 12'!S168:S169,'BESS 12'!S173:S174) -> #VALUE! | G28: =MAX('BESS 11'!O166,'BESS 11'!O169:O170,'BESS 11'!O174:O175)-MIN('BESS 11'!O166,'BESS 11'!O169:O170,'BESS 11'!O174:O175)+1 -> 1 | H28: =MIN('BESS 12'!O165,'BESS 12'!O168:O169,'BESS 12'!O173:O174) -> 46232 | I28: =IF(AND(I$1>=$H28,I$1<($H28+$G28)),ROUND($F28/$G28,0),"-") -> - | J28: =IF(AND(J$1>=$H28,J$1<($H28+$G28)),ROUND($F28/$G28,0),"-") -> - | K28: =IF(AND(K$1>=$H28,K$1<($H28+$G28)),ROUND($F28/$G28,0),"-") -> - | L28: =IF(AND(L$1>=$H28,L$1<($H28+$G28)),ROUND($F28/$G28,0),"-") -> - | M28: =IF(AND(M$1>=$H28,M$1<($H28+$G28)),ROUND($F28/$G28,0),"-") -> - | N28: =IF(AND(N$1>=$H28,N$1<($H28+$G28)),ROUND($F28/$G28,0),"-") -> - | O28: =IF(AND(O$1>=$H28,O$1<($H28+$G28)),ROUND($F28/$G28,0),"-") -> - | P28: =IF(AND(P$1>=$H28,P$1<($H28+$G28)),ROUND($F28/$G28,0),"-") -> - | ... CP28: =IF(AND(CP$1>=$H28,CP$1<($H28+$G28)),ROUND($F28/$G28,0),"-") -> -
E29: Testing | F29: =SUM('BESS 12'!S176:S185) -> #VALUE! | G29: =MAX('BESS 11'!O178:O186)-MIN('BESS 11'!O178:O186)+1 -> 11 | H29: =MIN('BESS 12'!O176:O185) -> 46230 | I29: =IF(AND(I$1>=$H29,I$1<($H29+$G29)),ROUND($F29/$G29,0),"-") -> - | J29: =IF(AND(J$1>=$H29,J$1<($H29+$G29)),ROUND($F29/$G29,0),"-") -> - | K29: =IF(AND(K$1>=$H29,K$1<($H29+$G29)),ROUND($F29/$G29,0),"-") -> - | L29: =IF(AND(L$1>=$H29,L$1<($H29+$G29)),ROUND($F29/$G29,0),"-") -> - | M29: =IF(AND(M$1>=$H29,M$1<($H29+$G29)),ROUND($F29/$G29,0),"-") -> - | N29: =IF(AND(N$1>=$H29,N$1<($H29+$G29)),ROUND($F29/$G29,0),"-") -> - | O29: =IF(AND(O$1>=$H29,O$1<($H29+$G29)),ROUND($F29/$G29,0),"-") -> - | P29: =IF(AND(P$1>=$H29,P$1<($H29+$G29)),ROUND($F29/$G29,0),"-") -> - | ... CP29: =IF(AND(CP$1>=$H29,CP$1<($H29+$G29)),ROUND($F29/$G29,0),"-") -> -
E30: CFT | F30: 250 | G30: 30 | H30: =B25-3 -> 46237 | AJ30: 5 | AK30: 5 | AL30: 5 | AM30: 5 | AN30: 5 | AO30: 5 | AP30: 5 | AQ30: 5 | AR30: 5 | AS30: 5 | AT30: 5 | AU30: 5 | AV30: 5 | AW30: 5 | AX30: 5 | AY30: 5 | AZ30: 5 | BA30: 5 | BB30: 5 | BC30: 5 | BD30: 5 | BE30: 5 | BF30: 5 | BG30: 5 | BH30: 30 | BI30: 30 | BJ30: 30 | BK30: 30 | BL30: 5 | BM30: 5
H31: Total | I31: =SUM(I26:I30) -> 0 | J31: =SUM(J26:J30) -> 0 | K31: =SUM(K26:K30) -> 0 | L31: =SUM(L26:L30) -> 0 | M31: =SUM(M26:M30) -> 0 | N31: =SUM(N26:N30) -> 0 | O31: =SUM(O26:O30) -> 0 | P31: =SUM(P26:P30) -> 0 | ... BQ31: =SUM(BQ26:BQ30) -> 0 | CQ31: =AVERAGE(P31:BQ31) -> 4.6296296 | CR31: =MAX(I31:BD31) -> 5
A33: Block 5 | B33: ='BESS 12'!F186 -> 46241 | C33: ='BESS 12'!G186 -> 46246 | E33: Activity | F33: Mandays | G33: Days | H33: Min. Date | I33: 46195 | J33: 46196 | K33: 46197 | L33: =K33+1 -> 46198 | M33: =L33+1 -> 46199 | N33: =M33+1 -> 46200 | O33: =N33+1 -> 46201 | P33: =O33+1 -> 46202 | Q33: =P33+1 -> 46203 | R33: =Q33+1 -> 46204 | S33: =R33+1 -> 46205 | ... CP33: =CO33+1 -> 46280 | CS33: =CR33+1 -> 1 | CT33: =CS33+1 -> 2 | CU33: =CT33+1 -> 3 | CV33: =CU33+1 -> 4 | CW33: =CV33+1 -> 5 | CX33: =CW33+1 -> 6 | CY33: =CX33+1 -> 7 | CZ33: =CY33+1 -> 8 | ... DO33: =DN33+1 -> 23
D34: ='BESS 12'!H186 -> 46249 | E34: Erection | F34: =SUM('BESS 12'!S199:S206,'BESS 12'!S208) -> #VALUE! | G34: =MAX('BESS 12'!O199:O206,'BESS 12'!O208)-MIN('BESS 12'!O199:O206,'BESS 12'!O208)+1 -> 6 | H34: =MIN('BESS 12'!O199:O206,'BESS 12'!O208) -> 46228 | I34: =IF(AND(I$1>=$H34,I$1<($H34+$G34)),ROUND($F34/$G34,0),"-") -> - | J34: =IF(AND(J$1>=$H34,J$1<($H34+$G34)),ROUND($F34/$G34,0),"-") -> - | K34: =IF(AND(K$1>=$H34,K$1<($H34+$G34)),ROUND($F34/$G34,0),"-") -> - | L34: =IF(AND(L$1>=$H34,L$1<($H34+$G34)),ROUND($F34/$G34,0),"-") -> - | M34: =IF(AND(M$1>=$H34,M$1<($H34+$G34)),ROUND($F34/$G34,0),"-") -> - | N34: =IF(AND(N$1>=$H34,N$1<($H34+$G34)),ROUND($F34/$G34,0),"-") -> - | O34: =IF(AND(O$1>=$H34,O$1<($H34+$G34)),ROUND($F34/$G34,0),"-") -> - | P34: =IF(AND(P$1>=$H34,P$1<($H34+$G34)),ROUND($F34/$G34,0),"-") -> - | ... CP34: =IF(AND(CP$1>=$H34,CP$1<($H34+$G34)),ROUND($F34/$G34,0),"-") -> - | CS34: =IF(AND(CS$1>=$H34,CS$1<($H34+$G34)),ROUND($F34/$G34,0),"-") -> #VALUE! | CT34: =IF(AND(CT$1>=$H34,CT$1<($H34+$G34)),ROUND($F34/$G34,0),"-") -> - | CU34: =IF(AND(CU$1>=$H34,CU$1<($H34+$G34)),ROUND($F34/$G34,0),"-") -> - | CV34: =IF(AND(CV$1>=$H34,CV$1<($H34+$G34)),ROUND($F34/$G34,0),"-") -> - | CW34: =IF(AND(CW$1>=$H34,CW$1<($H34+$G34)),ROUND($F34/$G34,0),"-") -> - | CX34: =IF(AND(CX$1>=$H34,CX$1<($H34+$G34)),ROUND($F34/$G34,0),"-") -> - | CY34: =IF(AND(CY$1>=$H34,CY$1<($H34+$G34)),ROUND($F34/$G34,0),"-") -> - | CZ34: =IF(AND(CZ$1>=$H34,CZ$1<($H34+$G34)),ROUND($F34/$G34,0),"-") -> - | ... DO34: =IF(AND(DO$1>=$H34,DO$1<($H34+$G34)),ROUND($F34/$G34,0),"-") -> -
E35: Cable Laying | F35: =SUM('BESS 12'!S209,'BESS 12'!S211:S212,'BESS 12'!S215:S217) -> #VALUE! | G35: =MAX('BESS 12'!O209,'BESS 12'!O211:O212,'BESS 12'!O215:O217)-MIN('BESS 12'!O209,'BESS 12'!O211:O212,'BESS 12'!O215:O217)+1 -> 1 | H35: =MIN('BESS 12'!O209,'BESS 12'!O211:O212,'BESS 12'!O215:O217) -> 46233 | I35: =IF(AND(I$1>=$H35,I$1<($H35+$G35)),ROUND($F35/$G35,0),"-") -> - | J35: =IF(AND(J$1>=$H35,J$1<($H35+$G35)),ROUND($F35/$G35,0),"-") -> - | K35: =IF(AND(K$1>=$H35,K$1<($H35+$G35)),ROUND($F35/$G35,0),"-") -> - | L35: =IF(AND(L$1>=$H35,L$1<($H35+$G35)),ROUND($F35/$G35,0),"-") -> - | M35: =IF(AND(M$1>=$H35,M$1<($H35+$G35)),ROUND($F35/$G35,0),"-") -> - | N35: =IF(AND(N$1>=$H35,N$1<($H35+$G35)),ROUND($F35/$G35,0),"-") -> - | O35: =IF(AND(O$1>=$H35,O$1<($H35+$G35)),ROUND($F35/$G35,0),"-") -> - | P35: =IF(AND(P$1>=$H35,P$1<($H35+$G35)),ROUND($F35/$G35,0),"-") -> - | ... CP35: =IF(AND(CP$1>=$H35,CP$1<($H35+$G35)),ROUND($F35/$G35,0),"-") -> - | CS35: =IF(AND(CS$1>=$H35,CS$1<($H35+$G35)),ROUND($F35/$G35,0),"-") -> #VALUE! | CT35: =IF(AND(CT$1>=$H35,CT$1<($H35+$G35)),ROUND($F35/$G35,0),"-") -> - | CU35: =IF(AND(CU$1>=$H35,CU$1<($H35+$G35)),ROUND($F35/$G35,0),"-") -> - | CV35: =IF(AND(CV$1>=$H35,CV$1<($H35+$G35)),ROUND($F35/$G35,0),"-") -> - | CW35: =IF(AND(CW$1>=$H35,CW$1<($H35+$G35)),ROUND($F35/$G35,0),"-") -> - | CX35: =IF(AND(CX$1>=$H35,CX$1<($H35+$G35)),ROUND($F35/$G35,0),"-") -> - | CY35: =IF(AND(CY$1>=$H35,CY$1<($H35+$G35)),ROUND($F35/$G35,0),"-") -> - | CZ35: =IF(AND(CZ$1>=$H35,CZ$1<($H35+$G35)),ROUND($F35/$G35,0),"-") -> - | ... DO35: =IF(AND(DO$1>=$H35,DO$1<($H35+$G35)),ROUND($F35/$G35,0),"-") -> -
E36: Termination | F36: =SUM('BESS 12'!S210,'BESS 12'!S213:S214,'BESS 12'!S218:S219) -> #VALUE! | G36: =MAX('BESS 12'!O210,'BESS 12'!O213:O214,'BESS 12'!O218:O219)-MIN('BESS 12'!O210,'BESS 12'!O213:O214,'BESS 12'!O218:O219)+1 -> 4 | H36: =MIN('BESS 12'!O210,'BESS 12'!O213:O214,'BESS 12'!O218:O219) -> 46233 | I36: =IF(AND(I$1>=$H36,I$1<($H36+$G36)),ROUND($F36/$G36,0),"-") -> - | J36: =IF(AND(J$1>=$H36,J$1<($H36+$G36)),ROUND($F36/$G36,0),"-") -> - | K36: =IF(AND(K$1>=$H36,K$1<($H36+$G36)),ROUND($F36/$G36,0),"-") -> - | L36: =IF(AND(L$1>=$H36,L$1<($H36+$G36)),ROUND($F36/$G36,0),"-") -> - | M36: =IF(AND(M$1>=$H36,M$1<($H36+$G36)),ROUND($F36/$G36,0),"-") -> - | N36: =IF(AND(N$1>=$H36,N$1<($H36+$G36)),ROUND($F36/$G36,0),"-") -> - | O36: =IF(AND(O$1>=$H36,O$1<($H36+$G36)),ROUND($F36/$G36,0),"-") -> - | P36: =IF(AND(P$1>=$H36,P$1<($H36+$G36)),ROUND($F36/$G36,0),"-") -> - | ... CP36: =IF(AND(CP$1>=$H36,CP$1<($H36+$G36)),ROUND($F36/$G36,0),"-") -> - | CS36: =IF(AND(CS$1>=$H36,CS$1<($H36+$G36)),ROUND($F36/$G36,0),"-") -> #VALUE! | CT36: =IF(AND(CT$1>=$H36,CT$1<($H36+$G36)),ROUND($F36/$G36,0),"-") -> - | CU36: =IF(AND(CU$1>=$H36,CU$1<($H36+$G36)),ROUND($F36/$G36,0),"-") -> - | CV36: =IF(AND(CV$1>=$H36,CV$1<($H36+$G36)),ROUND($F36/$G36,0),"-") -> - | CW36: =IF(AND(CW$1>=$H36,CW$1<($H36+$G36)),ROUND($F36/$G36,0),"-") -> - | CX36: =IF(AND(CX$1>=$H36,CX$1<($H36+$G36)),ROUND($F36/$G36,0),"-") -> - | CY36: =IF(AND(CY$1>=$H36,CY$1<($H36+$G36)),ROUND($F36/$G36,0),"-") -> - | CZ36: =IF(AND(CZ$1>=$H36,CZ$1<($H36+$G36)),ROUND($F36/$G36,0),"-") -> - | ... DO36: =IF(AND(DO$1>=$H36,DO$1<($H36+$G36)),ROUND($F36/$G36,0),"-") -> -
E37: Testing | F37: =SUM('BESS 12'!S221:S230) -> #VALUE! | G37: =MAX('BESS 12'!O221:O230)-MIN('BESS 12'!O221:O230)+1 -> 8 | H37: =MIN('BESS 12'!O221:O230) -> 46231 | I37: =IF(AND(I$1>=$H37,I$1<($H37+$G37)),ROUND($F37/$G37,0),"-") -> - | J37: =IF(AND(J$1>=$H37,J$1<($H37+$G37)),ROUND($F37/$G37,0),"-") -> - | K37: =IF(AND(K$1>=$H37,K$1<($H37+$G37)),ROUND($F37/$G37,0),"-") -> - | L37: =IF(AND(L$1>=$H37,L$1<($H37+$G37)),ROUND($F37/$G37,0),"-") -> - | M37: =IF(AND(M$1>=$H37,M$1<($H37+$G37)),ROUND($F37/$G37,0),"-") -> - | N37: =IF(AND(N$1>=$H37,N$1<($H37+$G37)),ROUND($F37/$G37,0),"-") -> - | O37: =IF(AND(O$1>=$H37,O$1<($H37+$G37)),ROUND($F37/$G37,0),"-") -> - | P37: =IF(AND(P$1>=$H37,P$1<($H37+$G37)),ROUND($F37/$G37,0),"-") -> - | ... CP37: =IF(AND(CP$1>=$H37,CP$1<($H37+$G37)),ROUND($F37/$G37,0),"-") -> - | CS37: =IF(AND(CS$1>=$H37,CS$1<($H37+$G37)),ROUND($F37/$G37,0),"-") -> #VALUE! | CT37: =IF(AND(CT$1>=$H37,CT$1<($H37+$G37)),ROUND($F37/$G37,0),"-") -> - | CU37: =IF(AND(CU$1>=$H37,CU$1<($H37+$G37)),ROUND($F37/$G37,0),"-") -> - | CV37: =IF(AND(CV$1>=$H37,CV$1<($H37+$G37)),ROUND($F37/$G37,0),"-") -> - | CW37: =IF(AND(CW$1>=$H37,CW$1<($H37+$G37)),ROUND($F37/$G37,0),"-") -> - | CX37: =IF(AND(CX$1>=$H37,CX$1<($H37+$G37)),ROUND($F37/$G37,0),"-") -> - | CY37: =IF(AND(CY$1>=$H37,CY$1<($H37+$G37)),ROUND($F37/$G37,0),"-") -> - | CZ37: =IF(AND(CZ$1>=$H37,CZ$1<($H37+$G37)),ROUND($F37/$G37,0),"-") -> - | ... DO37: =IF(AND(DO$1>=$H37,DO$1<($H37+$G37)),ROUND($F37/$G37,0),"-") -> -
E38: CFT | F38: 250 | G38: 30 | H38: =B33-3 -> 46238 | AM38: 5 | AN38: 5 | AO38: 5 | AP38: 5 | AQ38: 5 | AR38: 5 | AS38: 5 | AT38: 5 | AU38: 5 | AV38: 5 | AW38: 5 | AX38: 5 | AY38: 5 | AZ38: 5 | BA38: 5 | BB38: 5 | BC38: 5 | BD38: 5 | BE38: 5 | BF38: 5 | BG38: 5 | BH38: 5 | BI38: 5 | BJ38: 5 | BK38: 30 | BL38: 30 | BM38: 30 | BN38: 30 | BO38: 5 | BP38: 5
H39: Total | I39: =SUM(I34:I38) -> 0 | J39: =SUM(J34:J38) -> 0 | K39: =SUM(K34:K38) -> 0 | L39: =SUM(L34:L38) -> 0 | M39: =SUM(M34:M38) -> 0 | N39: =SUM(N34:N38) -> 0 | O39: =SUM(O34:O38) -> 0 | P39: =SUM(P34:P38) -> 0 | ... CP39: =SUM(CP34:CP38) -> 0 | CS39: =SUM(CS34:CS38) -> #VALUE! | CT39: =SUM(CT34:CT38) -> 0 | CU39: =SUM(CU34:CU38) -> 0 | CV39: =SUM(CV34:CV38) -> 0 | CW39: =SUM(CW34:CW38) -> 0 | CX39: =SUM(CX34:CX38) -> 0 | CY39: =SUM(CY34:CY38) -> 0 | CZ39: =SUM(CZ34:CZ38) -> 0 | ... DO39: =SUM(DO34:DO38) -> 0
A41: Block 6 | B41: ='BESS 12'!F231 -> 46258 | C41: ='BESS 12'!G231 -> 46262 | E41: Activity | F41: Mandays | G41: Days | H41: Min. Date | I41: 46195 | J41: 46196 | K41: 46197 | L41: =K41+1 -> 46198 | M41: =L41+1 -> 46199 | N41: =M41+1 -> 46200 | O41: =N41+1 -> 46201 | P41: =O41+1 -> 46202 | Q41: =P41+1 -> 46203 | R41: =Q41+1 -> 46204 | S41: =R41+1 -> 46205 | ... CP41: =CO41+1 -> 46280 | CS41: =CR41+1 -> 1 | CT41: =CS41+1 -> 2 | CU41: =CT41+1 -> 3 | CV41: =CU41+1 -> 4 | CW41: =CV41+1 -> 5 | CX41: =CW41+1 -> 6 | CY41: =CX41+1 -> 7 | CZ41: =CY41+1 -> 8 | ... DO41: =DN41+1 -> 23
D42: ='BESS 12'!H231 -> 46265 | E42: Erection | F42: =SUM('BESS 12'!S244:S251,'BESS 12'!S253) -> #VALUE! | G42: =MAX('BESS 12'!O244:O251,'BESS 12'!O253)-MIN('BESS 12'!O244:O251,'BESS 12'!O253)+1 -> 7 | H42: =MIN('BESS 12'!O244:O251,'BESS 12'!O253) -> 46236 | I42: =IF(AND(I$1>=$H42,I$1<($H42+$G42)),ROUND($F42/$G42,0),"-") -> - | J42: =IF(AND(J$1>=$H42,J$1<($H42+$G42)),ROUND($F42/$G42,0),"-") -> - | K42: =IF(AND(K$1>=$H42,K$1<($H42+$G42)),ROUND($F42/$G42,0),"-") -> - | L42: =IF(AND(L$1>=$H42,L$1<($H42+$G42)),ROUND($F42/$G42,0),"-") -> - | M42: =IF(AND(M$1>=$H42,M$1<($H42+$G42)),ROUND($F42/$G42,0),"-") -> - | N42: =IF(AND(N$1>=$H42,N$1<($H42+$G42)),ROUND($F42/$G42,0),"-") -> - | O42: =IF(AND(O$1>=$H42,O$1<($H42+$G42)),ROUND($F42/$G42,0),"-") -> - | P42: =IF(AND(P$1>=$H42,P$1<($H42+$G42)),ROUND($F42/$G42,0),"-") -> - | ... CP42: =IF(AND(CP$1>=$H42,CP$1<($H42+$G42)),ROUND($F42/$G42,0),"-") -> - | CS42: =IF(AND(CS$1>=$H42,CS$1<($H42+$G42)),ROUND($F42/$G42,0),"-") -> #VALUE! | CT42: =IF(AND(CT$1>=$H42,CT$1<($H42+$G42)),ROUND($F42/$G42,0),"-") -> - | CU42: =IF(AND(CU$1>=$H42,CU$1<($H42+$G42)),ROUND($F42/$G42,0),"-") -> - | CV42: =IF(AND(CV$1>=$H42,CV$1<($H42+$G42)),ROUND($F42/$G42,0),"-") -> - | CW42: =IF(AND(CW$1>=$H42,CW$1<($H42+$G42)),ROUND($F42/$G42,0),"-") -> - | CX42: =IF(AND(CX$1>=$H42,CX$1<($H42+$G42)),ROUND($F42/$G42,0),"-") -> - | CY42: =IF(AND(CY$1>=$H42,CY$1<($H42+$G42)),ROUND($F42/$G42,0),"-") -> - | CZ42: =IF(AND(CZ$1>=$H42,CZ$1<($H42+$G42)),ROUND($F42/$G42,0),"-") -> - | ... DO42: =IF(AND(DO$1>=$H42,DO$1<($H42+$G42)),ROUND($F42/$G42,0),"-") -> -
E43: Cable Laying | F43: =SUM('BESS 12'!S254,'BESS 12'!S256:S257,'BESS 12'!S260:S262) -> #VALUE! | G43: =MAX('BESS 12'!O254,'BESS 12'!O256:O257,'BESS 12'!O260:O262)-MIN('BESS 12'!O254,'BESS 12'!O256:O257,'BESS 12'!O260:O262)+1 -> 4 | H43: =MIN('BESS 12'!O254,'BESS 12'!O256:O257,'BESS 12'!O260:O262) -> 46243 | I43: =IF(AND(I$1>=$H43,I$1<($H43+$G43)),ROUND($F43/$G43,0),"-") -> - | J43: =IF(AND(J$1>=$H43,J$1<($H43+$G43)),ROUND($F43/$G43,0),"-") -> - | K43: =IF(AND(K$1>=$H43,K$1<($H43+$G43)),ROUND($F43/$G43,0),"-") -> - | L43: =IF(AND(L$1>=$H43,L$1<($H43+$G43)),ROUND($F43/$G43,0),"-") -> - | M43: =IF(AND(M$1>=$H43,M$1<($H43+$G43)),ROUND($F43/$G43,0),"-") -> - | N43: =IF(AND(N$1>=$H43,N$1<($H43+$G43)),ROUND($F43/$G43,0),"-") -> - | O43: =IF(AND(O$1>=$H43,O$1<($H43+$G43)),ROUND($F43/$G43,0),"-") -> - | P43: =IF(AND(P$1>=$H43,P$1<($H43+$G43)),ROUND($F43/$G43,0),"-") -> - | ... CP43: =IF(AND(CP$1>=$H43,CP$1<($H43+$G43)),ROUND($F43/$G43,0),"-") -> - | CS43: =IF(AND(CS$1>=$H43,CS$1<($H43+$G43)),ROUND($F43/$G43,0),"-") -> #VALUE! | CT43: =IF(AND(CT$1>=$H43,CT$1<($H43+$G43)),ROUND($F43/$G43,0),"-") -> - | CU43: =IF(AND(CU$1>=$H43,CU$1<($H43+$G43)),ROUND($F43/$G43,0),"-") -> - | CV43: =IF(AND(CV$1>=$H43,CV$1<($H43+$G43)),ROUND($F43/$G43,0),"-") -> - | CW43: =IF(AND(CW$1>=$H43,CW$1<($H43+$G43)),ROUND($F43/$G43,0),"-") -> - | CX43: =IF(AND(CX$1>=$H43,CX$1<($H43+$G43)),ROUND($F43/$G43,0),"-") -> - | CY43: =IF(AND(CY$1>=$H43,CY$1<($H43+$G43)),ROUND($F43/$G43,0),"-") -> - | CZ43: =IF(AND(CZ$1>=$H43,CZ$1<($H43+$G43)),ROUND($F43/$G43,0),"-") -> - | ... DO43: =IF(AND(DO$1>=$H43,DO$1<($H43+$G43)),ROUND($F43/$G43,0),"-") -> -
E44: Termination | F44: =SUM('BESS 12'!S255,'BESS 12'!S258:S259,'BESS 12'!S263:S264) -> #VALUE! | G44: =MAX('BESS 12'!O255,'BESS 12'!O258:O259,'BESS 12'!O263:O264)-MIN('BESS 12'!O255,'BESS 12'!O258:O259,'BESS 12'!O263:O264)+1 -> 5 | H44: =MIN('BESS 12'!O255,'BESS 12'!O258:O259,'BESS 12'!O263:O264) -> 46246 | I44: =IF(AND(I$1>=$H44,I$1<($H44+$G44)),ROUND($F44/$G44,0),"-") -> - | J44: =IF(AND(J$1>=$H44,J$1<($H44+$G44)),ROUND($F44/$G44,0),"-") -> - | K44: =IF(AND(K$1>=$H44,K$1<($H44+$G44)),ROUND($F44/$G44,0),"-") -> - | L44: =IF(AND(L$1>=$H44,L$1<($H44+$G44)),ROUND($F44/$G44,0),"-") -> - | M44: =IF(AND(M$1>=$H44,M$1<($H44+$G44)),ROUND($F44/$G44,0),"-") -> - | N44: =IF(AND(N$1>=$H44,N$1<($H44+$G44)),ROUND($F44/$G44,0),"-") -> - | O44: =IF(AND(O$1>=$H44,O$1<($H44+$G44)),ROUND($F44/$G44,0),"-") -> - | P44: =IF(AND(P$1>=$H44,P$1<($H44+$G44)),ROUND($F44/$G44,0),"-") -> - | ... CP44: =IF(AND(CP$1>=$H44,CP$1<($H44+$G44)),ROUND($F44/$G44,0),"-") -> - | CS44: =IF(AND(CS$1>=$H44,CS$1<($H44+$G44)),ROUND($F44/$G44,0),"-") -> #VALUE! | CT44: =IF(AND(CT$1>=$H44,CT$1<($H44+$G44)),ROUND($F44/$G44,0),"-") -> - | CU44: =IF(AND(CU$1>=$H44,CU$1<($H44+$G44)),ROUND($F44/$G44,0),"-") -> - | CV44: =IF(AND(CV$1>=$H44,CV$1<($H44+$G44)),ROUND($F44/$G44,0),"-") -> - | CW44: =IF(AND(CW$1>=$H44,CW$1<($H44+$G44)),ROUND($F44/$G44,0),"-") -> - | CX44: =IF(AND(CX$1>=$H44,CX$1<($H44+$G44)),ROUND($F44/$G44,0),"-") -> - | CY44: =IF(AND(CY$1>=$H44,CY$1<($H44+$G44)),ROUND($F44/$G44,0),"-") -> - | CZ44: =IF(AND(CZ$1>=$H44,CZ$1<($H44+$G44)),ROUND($F44/$G44,0),"-") -> - | ... DO44: =IF(AND(DO$1>=$H44,DO$1<($H44+$G44)),ROUND($F44/$G44,0),"-") -> -
E45: Testing | F45: =SUM('BESS 12'!S266:S275) -> #VALUE! | G45: =MAX('BESS 12'!O266:O275)-MIN('BESS 12'!O266:O275)+1 -> 17 | H45: =MIN('BESS 12'!O266:O275) -> 46244 | I45: =IF(AND(I$1>=$H45,I$1<($H45+$G45)),ROUND($F45/$G45,0),"-") -> - | J45: =IF(AND(J$1>=$H45,J$1<($H45+$G45)),ROUND($F45/$G45,0),"-") -> - | K45: =IF(AND(K$1>=$H45,K$1<($H45+$G45)),ROUND($F45/$G45,0),"-") -> - | L45: =IF(AND(L$1>=$H45,L$1<($H45+$G45)),ROUND($F45/$G45,0),"-") -> - | M45: =IF(AND(M$1>=$H45,M$1<($H45+$G45)),ROUND($F45/$G45,0),"-") -> - | N45: =IF(AND(N$1>=$H45,N$1<($H45+$G45)),ROUND($F45/$G45,0),"-") -> - | O45: =IF(AND(O$1>=$H45,O$1<($H45+$G45)),ROUND($F45/$G45,0),"-") -> - | P45: =IF(AND(P$1>=$H45,P$1<($H45+$G45)),ROUND($F45/$G45,0),"-") -> - | ... CP45: =IF(AND(CP$1>=$H45,CP$1<($H45+$G45)),ROUND($F45/$G45,0),"-") -> - | CS45: =IF(AND(CS$1>=$H45,CS$1<($H45+$G45)),ROUND($F45/$G45,0),"-") -> #VALUE! | CT45: =IF(AND(CT$1>=$H45,CT$1<($H45+$G45)),ROUND($F45/$G45,0),"-") -> - | CU45: =IF(AND(CU$1>=$H45,CU$1<($H45+$G45)),ROUND($F45/$G45,0),"-") -> - | CV45: =IF(AND(CV$1>=$H45,CV$1<($H45+$G45)),ROUND($F45/$G45,0),"-") -> - | CW45: =IF(AND(CW$1>=$H45,CW$1<($H45+$G45)),ROUND($F45/$G45,0),"-") -> - | CX45: =IF(AND(CX$1>=$H45,CX$1<($H45+$G45)),ROUND($F45/$G45,0),"-") -> - | CY45: =IF(AND(CY$1>=$H45,CY$1<($H45+$G45)),ROUND($F45/$G45,0),"-") -> - | CZ45: =IF(AND(CZ$1>=$H45,CZ$1<($H45+$G45)),ROUND($F45/$G45,0),"-") -> - | ... DO45: =IF(AND(DO$1>=$H45,DO$1<($H45+$G45)),ROUND($F45/$G45,0),"-") -> -
...

Sheet 10B - Daily requirement (2)
B1: IDT Charging / Commissioning Start | C1: ='BESS 11'!$G$2 -> Trial-Run End Date | D1: ='BESS 11'!$H$2 -> COD | E1: Activity | F1: Mandays | G1: Days | H1: Min. Date | I1: 46195 | J1: 46196 | K1: 46197 | L1: 46198 | M1: 46199 | N1: 46200 | O1: 46201 | P1: 46202 | Q1: 46203 | R1: 46204 | S1: 46205 | T1: 46206 | U1: 46207 | V1: 46208 | W1: 46209 | X1: 46210 | Y1: 46211 | Z1: 46212 | AA1: 46213 | AB1: 46214 | AC1: 46215 | AD1: 46216 | AE1: 46217 | AF1: 46218 | AG1: 46219 | AH1: 46220 | AI1: 46221 | AJ1: 46222 | AK1: 46223 | AL1: 46224 | AM1: 46225 | AN1: 46226 | AO1: 46227 | AP1: 46228 | AQ1: 46229 | AR1: 46230 | AS1: 46231 | AT1: 46232 | AU1: 46233 | AV1: 46234 | AW1: 46235 | AX1: 46236 | AY1: 46237 | AZ1: 46238 | BA1: 46239 | BB1: 46240 | BC1: 46241 | BD1: 46242 | BE1: 46243 | BF1: 46244 | BG1: 46245 | BH1: 46246 | BI1: 46247 | BJ1: 46248 | BK1: 46249 | BL1: 46250 | BM1: 46251 | BN1: 46252 | BO1: 46253 | BP1: 46254 | BQ1: 46255 | BR1: 46256 | BS1: 46257 | BT1: 46258 | BU1: 46259 | BV1: 46260 | BW1: 46261 | BX1: 46262 | BY1: 46263 | BZ1: 46264 | CA1: 46265 | CB1: 46266 | CC1: 46267 | CD1: 46268 | CE1: 46269 | CF1: 46270 | CG1: 46271 | CH1: 46272 | CI1: 46273 | CJ1: 46274 | CK1: 46275 | CL1: 46276 | CM1: 46277 | CN1: 46278 | CO1: 46279 | CP1: 46280 | CQ1: 46281 | CR1: 46282 | CS1: 46283 | CT1: 46284 | CU1: 46312 | CV1: 46313 | CW1: 46314 | CX1: 46315 | CY1: 46316 | CZ1: 46317 | DA1: 46318 | DB1: 46319 | DC1: 46320 | DD1: 46321 | DE1: 46322 | DF1: 46323 | DG1: 46324 | DH1: 46325 | DI1: 46326 | DJ1: 46327 | DK1: 46328 | DL1: 46329 | DM1: 46330 | DN1: 46331 | DO1: 46332 | DP1: 46333 | DQ1: 46334 | DR1: 46335 | DS1: 46336 | DT1: 46337 | DU1: 46338 | DV1: 46339 | DW1: 46340 | DX1: 46341 | DY1: 46342 | DZ1: 46343 | EA1: 46344 | EB1: 46345 | EC1: 46346 | ED1: 46347 | EE1: 46348 | EF1: 46349 | EG1: 46350 | EH1: 46351 | EI1: 46352 | EJ1: 46353 | EK1: 46354 | EL1: 46355 | EM1: 46356 | EN1: 46357 | EO1: 46358 | EP1: 46359 | EQ1: 46360 | ER1: 46361 | ES1: 46362 | ET1: 46363 | EU1: 46364 | EV1: 46365 | EW1: 46366 | EX1: 46367 | EY1: 46368 | EZ1: 46369 | FA1: 46370 | FB1: 46371 | FC1: 46372 | FD1: 46373 | FE1: 46374 | FF1: 46375 | FG1: 46376 | FH1: 46377 | FI1: 46378 | FJ1: 46379 | FK1: 46380 | FL1: 46381 | FM1: 46382 | FN1: 46383 | FO1: 46384 | FP1: 46385 | FQ1: 46386 | FR1: 46387
A2: Block 1 | B2: ='BESS 10B'!F5 -> 46239 | C2: ='BESS 10B'!G5 -> 46244 | D2: ='BESS 10B'!H5 -> 46247 | E2: Erection | F2: =SUM('BESS 10B'!S18:S25,'BESS 10B'!S27) -> #VALUE! | G2: =MAX('BESS 10B'!O18:O25,'BESS 10B'!O27)-MIN('BESS 10B'!O18:O25,'BESS 10B'!O27)+1 -> 1 | H2: =MIN('BESS 10B'!O18:O25,'BESS 10B'!O27) -> 46234 | I2: =IF(AND(I$1>=$H2,I$1<($H2+$G2)),ROUND($F2/$G2,0),"-") -> - | J2: =IF(AND(J$1>=$H2,J$1<($H2+$G2)),ROUND($F2/$G2,0),"-") -> - | K2: =IF(AND(K$1>=$H2,K$1<($H2+$G2)),ROUND($F2/$G2,0),"-") -> - | L2: =IF(AND(L$1>=$H2,L$1<($H2+$G2)),ROUND($F2/$G2,0),"-") -> - | M2: =IF(AND(M$1>=$H2,M$1<($H2+$G2)),ROUND($F2/$G2,0),"-") -> - | N2: =IF(AND(N$1>=$H2,N$1<($H2+$G2)),ROUND($F2/$G2,0),"-") -> - | O2: =IF(AND(O$1>=$H2,O$1<($H2+$G2)),ROUND($F2/$G2,0),"-") -> - | P2: =IF(AND(P$1>=$H2,P$1<($H2+$G2)),ROUND($F2/$G2,0),"-") -> - | ... CT2: =IF(AND(CT$1>=$H2,CT$1<($H2+$G2)),ROUND($F2/$G2,0),"-") -> -
E3: Cable Laying | F3: =SUM('BESS 10B'!S28,'BESS 10B'!S30:S31,'BESS 10B'!S34:S36) -> #VALUE! | G3: =MAX('BESS 10B'!O28,'BESS 10B'!O30:O31,'BESS 10B'!O34:O36)-MIN('BESS 10B'!O28,'BESS 10B'!O30:O31,'BESS 10B'!O34:O36)+1 -> 1 | H3: =MIN('BESS 10B'!O28,'BESS 10B'!O30:O31,'BESS 10B'!O34:O36) -> 46233 | I3: =IF(AND(I$1>=$H3,I$1<($H3+$G3)),ROUND($F3/$G3,0),"-") -> - | J3: =IF(AND(J$1>=$H3,J$1<($H3+$G3)),ROUND($F3/$G3,0),"-") -> - | K3: =IF(AND(K$1>=$H3,K$1<($H3+$G3)),ROUND($F3/$G3,0),"-") -> - | L3: =IF(AND(L$1>=$H3,L$1<($H3+$G3)),ROUND($F3/$G3,0),"-") -> - | M3: =IF(AND(M$1>=$H3,M$1<($H3+$G3)),ROUND($F3/$G3,0),"-") -> - | N3: =IF(AND(N$1>=$H3,N$1<($H3+$G3)),ROUND($F3/$G3,0),"-") -> - | O3: =IF(AND(O$1>=$H3,O$1<($H3+$G3)),ROUND($F3/$G3,0),"-") -> - | P3: =IF(AND(P$1>=$H3,P$1<($H3+$G3)),ROUND($F3/$G3,0),"-") -> - | ... CT3: =IF(AND(CT$1>=$H3,CT$1<($H3+$G3)),ROUND($F3/$G3,0),"-") -> -
E4: Termination | F4: =SUM('BESS 10B'!S29,'BESS 10B'!S32:S33,'BESS 10B'!S37:S38) -> #VALUE! | G4: =MAX('BESS 10B'!O29,'BESS 10B'!O32:O33,'BESS 10B'!O37:O38)-MIN('BESS 10B'!O29,'BESS 10B'!O32:O33,'BESS 10B'!O37:O38)+1 -> 1 | H4: =MIN('BESS 10B'!O29,'BESS 10B'!O32:O33,'BESS 10B'!O37:O38) -> 46235 | I4: =IF(AND(I$1>=$H4,I$1<($H4+$G4)),ROUND($F4/$G4,0),"-") -> - | J4: =IF(AND(J$1>=$H4,J$1<($H4+$G4)),ROUND($F4/$G4,0),"-") -> - | K4: =IF(AND(K$1>=$H4,K$1<($H4+$G4)),ROUND($F4/$G4,0),"-") -> - | L4: =IF(AND(L$1>=$H4,L$1<($H4+$G4)),ROUND($F4/$G4,0),"-") -> - | M4: =IF(AND(M$1>=$H4,M$1<($H4+$G4)),ROUND($F4/$G4,0),"-") -> - | N4: =IF(AND(N$1>=$H4,N$1<($H4+$G4)),ROUND($F4/$G4,0),"-") -> - | O4: =IF(AND(O$1>=$H4,O$1<($H4+$G4)),ROUND($F4/$G4,0),"-") -> - | P4: =IF(AND(P$1>=$H4,P$1<($H4+$G4)),ROUND($F4/$G4,0),"-") -> - | ... CT4: =IF(AND(CT$1>=$H4,CT$1<($H4+$G4)),ROUND($F4/$G4,0),"-") -> -
E5: Testing | F5: =SUM('BESS 10B'!S40:S49) -> #VALUE! | G5: =MAX('BESS 10B'!O40:O49)-MIN('BESS 10B'!O40:O49)+1 -> 6 | H5: =MIN('BESS 10B'!O40:O49) -> 46233 | I5: =IF(AND(I$1>=$H5,I$1<($H5+$G5)),ROUND($F5/$G5,0),"-") -> - | J5: =IF(AND(J$1>=$H5,J$1<($H5+$G5)),ROUND($F5/$G5,0),"-") -> - | K5: =IF(AND(K$1>=$H5,K$1<($H5+$G5)),ROUND($F5/$G5,0),"-") -> - | L5: =IF(AND(L$1>=$H5,L$1<($H5+$G5)),ROUND($F5/$G5,0),"-") -> - | M5: =IF(AND(M$1>=$H5,M$1<($H5+$G5)),ROUND($F5/$G5,0),"-") -> - | N5: =IF(AND(N$1>=$H5,N$1<($H5+$G5)),ROUND($F5/$G5,0),"-") -> - | O5: =IF(AND(O$1>=$H5,O$1<($H5+$G5)),ROUND($F5/$G5,0),"-") -> - | P5: =IF(AND(P$1>=$H5,P$1<($H5+$G5)),ROUND($F5/$G5,0),"-") -> - | ... CT5: =IF(AND(CT$1>=$H5,CT$1<($H5+$G5)),ROUND($F5/$G5,0),"-") -> -
E6: CFT | F6: =SUM(Z6:BC6) -> 250 | G6: 30 | H6: =B2-3 -> 46236 | Z6: 5 | AA6: 5 | AB6: 5 | AC6: 5 | AD6: 5 | AE6: 5 | AF6: 5 | AG6: 5 | AH6: 5 | AI6: 5 | AJ6: 5 | AK6: 5 | AL6: 5 | AM6: 5 | AN6: 5 | AO6: 5 | AP6: 5 | AQ6: 5 | AR6: 5 | AS6: 5 | AT6: 5 | AU6: 5 | AV6: 5 | AW6: 5 | AX6: 30 | AY6: 30 | AZ6: 30 | BA6: 30 | BB6: 5 | BC6: 5
H7: Total | K7: =SUM(K2:K6) -> 0 | L7: =SUM(L2:L6) -> 0 | M7: =SUM(M2:M6) -> 0 | N7: =SUM(N2:N6) -> 0 | O7: =SUM(O2:O6) -> 0 | P7: =SUM(P2:P6) -> 0 | Q7: =SUM(Q2:Q6) -> 0 | R7: =SUM(R2:R6) -> 0 | ... CT7: =SUM(CT2:CT6) -> 0
A9: Block 2 | B9: ='BESS 10B'!F50 -> 46245 | C9: ='BESS 10B'!G50 -> 46250 | E9: Activity | F9: Mandays | G9: Days | H9: Min. Date | I9: 46195 | J9: 46196 | K9: =MIN('BESS 11'!O26:O33,'BESS 11'!O35) -> 0 | L9: =K9+1 -> 1 | M9: =L9+1 -> 2 | N9: =M9+1 -> 3 | O9: =N9+1 -> 4 | P9: =O9+1 -> 5 | Q9: =P9+1 -> 6 | R9: =Q9+1 -> 7 | S9: =R9+1 -> 8 | ... CT9: =CS9+1 -> 87
D10: ='BESS 10B'!H50 -> 46253 | E10: Erection | F10: =SUM('BESS 10B'!S63:S70,'BESS 10B'!S72) -> #VALUE! | G10: =MAX('BESS 10B'!O63:O70,'BESS 10B'!O72)-MIN('BESS 10B'!O63:O70,'BESS 10B'!O72)+1 -> 9 | H10: =MIN('BESS 10B'!O63:O70,'BESS 10B'!SN72) -> 46228 | I10: =IF(AND(I$1>=$H10,I$1<($H10+$G10)),ROUND($F10/$G10,0),"-") -> - | J10: =IF(AND(J$1>=$H10,J$1<($H10+$G10)),ROUND($F10/$G10,0),"-") -> - | K10: =IF(AND(K$1>=$H10,K$1<($H10+$G10)),ROUND($F10/$G10,0),"-") -> - | L10: =IF(AND(L$1>=$H10,L$1<($H10+$G10)),ROUND($F10/$G10,0),"-") -> - | M10: =IF(AND(M$1>=$H10,M$1<($H10+$G10)),ROUND($F10/$G10,0),"-") -> - | N10: =IF(AND(N$1>=$H10,N$1<($H10+$G10)),ROUND($F10/$G10,0),"-") -> - | O10: =IF(AND(O$1>=$H10,O$1<($H10+$G10)),ROUND($F10/$G10,0),"-") -> - | P10: =IF(AND(P$1>=$H10,P$1<($H10+$G10)),ROUND($F10/$G10,0),"-") -> - | ... CT10: =IF(AND(CT$1>=$H10,CT$1<($H10+$G10)),ROUND($F10/$G10,0),"-") -> -
E11: Cable Laying | F11: =SUM('BESS 10B'!S73,'BESS 10B'!S75:S76,'BESS 10B'!S79:S81) -> #VALUE! | G11: =MAX('BESS 10B'!O73,'BESS 10B'!O75:O76,'BESS 10B'!O79:O81)-MIN('BESS 10B'!O73,'BESS 10B'!O75:O76,'BESS 10B'!O79:O81)+1 -> 3 | H11: =MIN('BESS 10B'!O73,'BESS 10B'!O75:O76,'BESS 10B'!O79:O81) -> 46232 | I11: =IF(AND(I$1>=$H11,I$1<($H11+$G11)),ROUND($F11/$G11,0),"-") -> - | J11: =IF(AND(J$1>=$H11,J$1<($H11+$G11)),ROUND($F11/$G11,0),"-") -> - | K11: =IF(AND(K$1>=$H11,K$1<($H11+$G11)),ROUND($F11/$G11,0),"-") -> - | L11: =IF(AND(L$1>=$H11,L$1<($H11+$G11)),ROUND($F11/$G11,0),"-") -> - | M11: =IF(AND(M$1>=$H11,M$1<($H11+$G11)),ROUND($F11/$G11,0),"-") -> - | N11: =IF(AND(N$1>=$H11,N$1<($H11+$G11)),ROUND($F11/$G11,0),"-") -> - | O11: =IF(AND(O$1>=$H11,O$1<($H11+$G11)),ROUND($F11/$G11,0),"-") -> - | P11: =IF(AND(P$1>=$H11,P$1<($H11+$G11)),ROUND($F11/$G11,0),"-") -> - | ... CT11: =IF(AND(CT$1>=$H11,CT$1<($H11+$G11)),ROUND($F11/$G11,0),"-") -> -
E12: Termination | F12: =SUM('BESS 10B'!S74,'BESS 10B'!S77:S78,'BESS 10B'!S82:S83) -> #VALUE! | G12: =MAX('BESS 10B'!O74,'BESS 10B'!O77:O78,'BESS 10B'!O82:O83)-MIN('BESS 10B'!O74,'BESS 10B'!O77:O78,'BESS 10B'!O82:O83)+1 -> 6 | H12: =MIN('BESS 10B'!O74,'BESS 10B'!O77:O78,'BESS 10B'!O82:O83) -> 46234 | I12: =IF(AND(I$1>=$H12,I$1<($H12+$G12)),ROUND($F12/$G12,0),"-") -> - | J12: =IF(AND(J$1>=$H12,J$1<($H12+$G12)),ROUND($F12/$G12,0),"-") -> - | K12: =IF(AND(K$1>=$H12,K$1<($H12+$G12)),ROUND($F12/$G12,0),"-") -> - | L12: =IF(AND(L$1>=$H12,L$1<($H12+$G12)),ROUND($F12/$G12,0),"-") -> - | M12: =IF(AND(M$1>=$H12,M$1<($H12+$G12)),ROUND($F12/$G12,0),"-") -> - | N12: =IF(AND(N$1>=$H12,N$1<($H12+$G12)),ROUND($F12/$G12,0),"-") -> - | O12: =IF(AND(O$1>=$H12,O$1<($H12+$G12)),ROUND($F12/$G12,0),"-") -> - | P12: =IF(AND(P$1>=$H12,P$1<($H12+$G12)),ROUND($F12/$G12,0),"-") -> - | ... CT12: =IF(AND(CT$1>=$H12,CT$1<($H12+$G12)),ROUND($F12/$G12,0),"-") -> -
E13: Testing | F13: =SUM('BESS 10B'!S85:S94) -> #VALUE! | G13: =MAX('BESS 10B'!O85:O94)-MIN('BESS 10B'!O85:O94)+1 -> 12 | H13: =MIN('BESS 10B'!O85:O94) -> 46231 | I13: =IF(AND(I$1>=$H13,I$1<($H13+$G13)),ROUND($F13/$G13,0),"-") -> - | J13: =IF(AND(J$1>=$H13,J$1<($H13+$G13)),ROUND($F13/$G13,0),"-") -> - | K13: =IF(AND(K$1>=$H13,K$1<($H13+$G13)),ROUND($F13/$G13,0),"-") -> - | L13: =IF(AND(L$1>=$H13,L$1<($H13+$G13)),ROUND($F13/$G13,0),"-") -> - | M13: =IF(AND(M$1>=$H13,M$1<($H13+$G13)),ROUND($F13/$G13,0),"-") -> - | N13: =IF(AND(N$1>=$H13,N$1<($H13+$G13)),ROUND($F13/$G13,0),"-") -> - | O13: =IF(AND(O$1>=$H13,O$1<($H13+$G13)),ROUND($F13/$G13,0),"-") -> - | P13: =IF(AND(P$1>=$H13,P$1<($H13+$G13)),ROUND($F13/$G13,0),"-") -> - | ... CT13: =IF(AND(CT$1>=$H13,CT$1<($H13+$G13)),ROUND($F13/$G13,0),"-") -> -
E14: CFT | F14: =SUM(AL14:BO14) -> 250 | G14: 30 | H14: =B9-3 -> 46242 | AL14: 5 | AM14: 5 | AN14: 5 | AO14: 5 | AP14: 5 | AQ14: 5 | AR14: 5 | AS14: 5 | AT14: 5 | AU14: 5 | AV14: 5 | AW14: 5 | AX14: 5 | AY14: 5 | AZ14: 5 | BA14: 5 | BB14: 5 | BC14: 5 | BD14: 5 | BE14: 5 | BF14: 5 | BG14: 5 | BH14: 5 | BI14: 5 | BJ14: 30 | BK14: 30 | BL14: 30 | BM14: 30 | BN14: 5 | BO14: 5
H15: Total | K15: =SUM(K10:K14) -> 0 | L15: =SUM(L10:L14) -> 0 | M15: =SUM(M10:M14) -> 0 | N15: =SUM(N10:N14) -> 0 | O15: =SUM(O10:O14) -> 0 | P15: =SUM(P10:P14) -> 0 | Q15: =SUM(Q10:Q14) -> 0 | R15: =SUM(R10:R14) -> 0 | ... CT15: =SUM(CT10:CT14) -> 0
A17: Block 3 | B17: ='BESS 10B'!F95 -> 08 Aug 23 Aug | C17: ='BESS 10B'!G95 -> 13 Aug 28 Aug | E17: Activity | F17: Mandays | G17: Days | H17: Min. Date | I17: 46195 | J17: 46196 | K17: 46197 | L17: =K17+1 -> 46198 | M17: =L17+1 -> 46199 | N17: =M17+1 -> 46200 | O17: =N17+1 -> 46201 | P17: =O17+1 -> 46202 | Q17: =P17+1 -> 46203 | R17: =Q17+1 -> 46204 | S17: =R17+1 -> 46205 | ... CT17: =CS17+1 -> 46284
D18: ='BESS 10B'!H95 -> 16 Aug 31 Aug | E18: Erection | F18: =SUM('BESS 10B'!S108:S115,'BESS 10B'!S117) -> #VALUE! | G18: =MAX('BESS 10B'!O108:O115,'BESS 10B'!O117)-MIN('BESS 10B'!O108:O115,'BESS 10B'!O117)+1 -> 5 | H18: =MIN('BESS 10B'!S108:S115,'BESS 10B'!S117) -> #VALUE! | I18: =IF(AND(I$1>=$H18,I$1<($H18+$G18)),ROUND($F18/$G18,0),"-") -> #VALUE! | J18: =IF(AND(J$1>=$H18,J$1<($H18+$G18)),ROUND($F18/$G18,0),"-") -> #VALUE! | K18: =IF(AND(K$1>=$H18,K$1<($H18+$G18)),ROUND($F18/$G18,0),"-") -> #VALUE! | L18: =IF(AND(L$1>=$H18,L$1<($H18+$G18)),ROUND($F18/$G18,0),"-") -> #VALUE! | M18: =IF(AND(M$1>=$H18,M$1<($H18+$G18)),ROUND($F18/$G18,0),"-") -> #VALUE! | N18: =IF(AND(N$1>=$H18,N$1<($H18+$G18)),ROUND($F18/$G18,0),"-") -> #VALUE! | O18: =IF(AND(O$1>=$H18,O$1<($H18+$G18)),ROUND($F18/$G18,0),"-") -> #VALUE! | P18: =IF(AND(P$1>=$H18,P$1<($H18+$G18)),ROUND($F18/$G18,0),"-") -> #VALUE! | ... CT18: =IF(AND(CT$1>=$H18,CT$1<($H18+$G18)),ROUND($F18/$G18,0),"-") -> #VALUE!
E19: Cable Laying | F19: =SUM('BESS 10B'!S118,'BESS 10B'!S120:S121,'BESS 10B'!S124:S126) -> #VALUE! | G19: =MAX('BESS 10B'!O118,'BESS 10B'!O120:O121,'BESS 10B'!O124:O126)-MIN('BESS 10B'!O118,'BESS 10B'!O120:O121,'BESS 10B'!O124:O126)+1 -> 5 | H19: =MIN('BESS 10B'!O118,'BESS 10B'!O120:O121,'BESS 10B'!O124:O126) -> 46242 | I19: =IF(AND(I$1>=$H19,I$1<($H19+$G19)),ROUND($F19/$G19,0),"-") -> - | J19: =IF(AND(J$1>=$H19,J$1<($H19+$G19)),ROUND($F19/$G19,0),"-") -> - | K19: =IF(AND(K$1>=$H19,K$1<($H19+$G19)),ROUND($F19/$G19,0),"-") -> - | L19: =IF(AND(L$1>=$H19,L$1<($H19+$G19)),ROUND($F19/$G19,0),"-") -> - | M19: =IF(AND(M$1>=$H19,M$1<($H19+$G19)),ROUND($F19/$G19,0),"-") -> - | N19: =IF(AND(N$1>=$H19,N$1<($H19+$G19)),ROUND($F19/$G19,0),"-") -> - | O19: =IF(AND(O$1>=$H19,O$1<($H19+$G19)),ROUND($F19/$G19,0),"-") -> - | P19: =IF(AND(P$1>=$H19,P$1<($H19+$G19)),ROUND($F19/$G19,0),"-") -> - | ... CT19: =IF(AND(CT$1>=$H19,CT$1<($H19+$G19)),ROUND($F19/$G19,0),"-") -> -
E20: Termination | F20: =SUM('BESS 10B'!S119,'BESS 10B'!S122:S123,'BESS 10B'!S127:S128) -> #VALUE! | G20: =MAX('BESS 10B'!O119,'BESS 10B'!O121:O122,'BESS 10B'!O125:O127)-MIN('BESS 10B'!O119,'BESS 10B'!O121:O122,'BESS 10B'!O125:O127)+1 -> 8 | H20: =MIN('BESS 10B'!O119,'BESS 10B'!O121:O122,'BESS 10B'!O125:O127) -> 46244 | I20: =IF(AND(I$1>=$H20,I$1<($H20+$G20)),ROUND($F20/$G20,0),"-") -> - | J20: =IF(AND(J$1>=$H20,J$1<($H20+$G20)),ROUND($F20/$G20,0),"-") -> - | K20: =IF(AND(K$1>=$H20,K$1<($H20+$G20)),ROUND($F20/$G20,0),"-") -> - | L20: =IF(AND(L$1>=$H20,L$1<($H20+$G20)),ROUND($F20/$G20,0),"-") -> - | M20: =IF(AND(M$1>=$H20,M$1<($H20+$G20)),ROUND($F20/$G20,0),"-") -> - | N20: =IF(AND(N$1>=$H20,N$1<($H20+$G20)),ROUND($F20/$G20,0),"-") -> - | O20: =IF(AND(O$1>=$H20,O$1<($H20+$G20)),ROUND($F20/$G20,0),"-") -> - | P20: =IF(AND(P$1>=$H20,P$1<($H20+$G20)),ROUND($F20/$G20,0),"-") -> - | ... CT20: =IF(AND(CT$1>=$H20,CT$1<($H20+$G20)),ROUND($F20/$G20,0),"-") -> -
E21: Testing | F21: =SUM('BESS 10B'!S130:S139) -> #VALUE! | G21: =MAX('BESS 10B'!O130:O139)-MIN('BESS 10B'!O130:O139)+1 -> 10 | H21: =MIN('BESS 10B'!O130:O139) -> 46246 | I21: =IF(AND(I$1>=$H21,I$1<($H21+$G21)),ROUND($F21/$G21,0),"-") -> - | J21: =IF(AND(J$1>=$H21,J$1<($H21+$G21)),ROUND($F21/$G21,0),"-") -> - | K21: =IF(AND(K$1>=$H21,K$1<($H21+$G21)),ROUND($F21/$G21,0),"-") -> - | L21: =IF(AND(L$1>=$H21,L$1<($H21+$G21)),ROUND($F21/$G21,0),"-") -> - | M21: =IF(AND(M$1>=$H21,M$1<($H21+$G21)),ROUND($F21/$G21,0),"-") -> - | N21: =IF(AND(N$1>=$H21,N$1<($H21+$G21)),ROUND($F21/$G21,0),"-") -> - | O21: =IF(AND(O$1>=$H21,O$1<($H21+$G21)),ROUND($F21/$G21,0),"-") -> - | P21: =IF(AND(P$1>=$H21,P$1<($H21+$G21)),ROUND($F21/$G21,0),"-") -> - | ... CT21: =IF(AND(CT$1>=$H21,CT$1<($H21+$G21)),ROUND($F21/$G21,0),"-") -> -
E22: CFT | F22: =SUM(AN22:BQ22) -> 250 | G22: 30 | H22: =B17-3 -> #VALUE! | AN22: 5 | AO22: 5 | AP22: 5 | AQ22: 5 | AR22: 5 | AS22: 5 | AT22: 5 | AU22: 5 | AV22: 5 | AW22: 5 | AX22: 5 | AY22: 5 | AZ22: 5 | BA22: 5 | BB22: 5 | BC22: 5 | BD22: 5 | BE22: 5 | BF22: 5 | BG22: 5 | BH22: 5 | BI22: 5 | BJ22: 5 | BK22: 5 | BL22: 30 | BM22: 30 | BN22: 30 | BO22: 30 | BP22: 5 | BQ22: 5
H23: Total | K23: =SUM(K18:K22) -> #VALUE! | L23: =SUM(L18:L22) -> #VALUE! | M23: =SUM(M18:M22) -> #VALUE! | N23: =SUM(N18:N22) -> #VALUE! | O23: =SUM(O18:O22) -> #VALUE! | P23: =SUM(P18:P22) -> #VALUE! | Q23: =SUM(Q18:Q22) -> #VALUE! | R23: =SUM(R18:R22) -> #VALUE! | ... CT23: =SUM(CT18:CT22) -> #VALUE!
A25: Block 4 | B25: ='BESS 10B'!F140 -> 30 Aug 21 Sep | C25: ='BESS 10B'!G140 -> 04 Sep 26 Sep | E25: Activity | F25: Mandays | G25: Days | H25: Min. Date | I25: 46195 | J25: 46196 | K25: 46197 | L25: =K25+1 -> 46198 | M25: =L25+1 -> 46199 | N25: =M25+1 -> 46200 | O25: =N25+1 -> 46201 | P25: =O25+1 -> 46202 | Q25: =P25+1 -> 46203 | R25: =Q25+1 -> 46204 | S25: =R25+1 -> 46205 | ... CT25: =CS25+1 -> 46284
