Workbook

Sheet SPV wise Summary
A1: ADANI GREEN ENERGY KHAVADA PH-II 200WTGs (1040 MWac)
A3: S.No | B3: Description | C3: PSS Number | D3: Total Scope | E3: Achieved | F3: Balance | H3: PSS Number | I3: SPV Name | J3: Total Scope | K3: Achieved | L3: Balance | N3: PSS Number | O3: SPV Name | P3: Total Scope | Q3: Achieved | R3: Balance | T3: PSS Number | U3: SPV Name | V3: Total Scope | W3: Achieved | X3: Balance | Z3: PSS Number | AA3: SPV Name | AB3: Total Scope | AC3: Achieved | AD3: Balance | AF3: PSS Number | AG3: SPV Name | AH3: Total Scope | AI3: Achieved | AJ3: Balance
A5: I | B5: WTG CIVIL & MECH
A6: =ROW(A1) -> 1 | B6: Soil Test | D6: =SUM(J6,P6,V6,AB6,AH6) -> 0 | E6: =SUM(K6,Q6,W6,AC6,AI6) -> 0 | F6: =D6-E6 -> 0 | J6: =COUNTIFS('WTG PH-III'!$B$5:$B$198,$H$6,'WTG PH-III'!$C$5:$C$198,$I$6) -> 0 | K6: =COUNTIFS('WTG PH-III'!$B$5:$B$198,$H$6,'WTG PH-III'!$C$5:$C$198,$I$6,'WTG PH-III'!$P$5:$P$198,">0") -> 0 | L6: =J6-K6 -> 0 | P6: =COUNTIFS('WTG PH-III'!$B$5:$B$198,$N$6,'WTG PH-III'!$C$5:$C$198,$O$6) -> 0 | Q6: =COUNTIFS('WTG PH-III'!$B$5:$B$198,$N$6,'WTG PH-III'!$C$5:$C$198,$O$6,'WTG PH-III'!$P$5:$P$198,">0") -> 0 | R6: =P6-Q6 -> 0 | V6: =COUNTIFS('WTG PH-III'!$B$5:$B$198,$T$6,'WTG PH-III'!$C$5:$C$198,$U$6) -> 0 | W6: =COUNTIFS('WTG PH-III'!$B$5:$B$198,$T$6,'WTG PH-III'!$C$5:$C$198,$U$6,'WTG PH-III'!$P$5:$P$198,">0") -> 0 | X6: =V6-W6 -> 0 | AB6: =COUNTIFS('WTG PH-III'!$B$5:$B$198,$Z$6,'WTG PH-III'!$C$5:$C$198,$AA$6) -> 0 | AC6: =COUNTIFS('WTG PH-III'!$B$5:$B$198,$Z$6,'WTG PH-III'!$C$5:$C$198,$AA$6,'WTG PH-III'!$P$5:$P$198,">0") -> 0 | AD6: =AB6-AC6 -> 0 | AH6: =COUNTIFS('WTG PH-III'!$B$5:$B$198,$AF$6,'WTG PH-III'!$C$5:$C$198,$AG$6) -> 0 | AI6: =COUNTIFS('WTG PH-III'!$B$5:$B$198,$AF$6,'WTG PH-III'!$C$5:$C$198,$AG$6,'WTG PH-III'!$P$5:$P$198,">0") -> 0 | AJ6: =AH6-AI6 -> 0
A7: =ROW(A2) -> 2 | B7: Stone Column Drawing's Status | D7: =D6 -> 0 | J7: =J6 -> 0 | P7: =P6 -> 0 | V7: =V6 -> 0 | AB7: =AB6 -> 0 | AH7: =AH6 -> 0
A8: =ROW(A3) -> 3 | B8: Stone Column | D8: =D7 -> 0 | E8: =SUM(K8,Q8,W8,AC8,AI8) -> 0 | F8: =D8-E8 -> 0 | J8: =J7 -> 0 | K8: =COUNTIFS('WTG PH-III'!$B$5:$B$198,$H$8,'WTG PH-III'!$C$5:$C$198,$I$8,'WTG PH-III'!$X$5:$X$198,">0") -> 0 | L8: =J8-K8 -> 0 | P8: =P7 -> 0 | Q8: =COUNTIFS('WTG PH-III'!$B$5:$B$198,$N$8,'WTG PH-III'!$C$5:$C$198,$O$8,'WTG PH-III'!$X$5:$X$198,">0") -> 0 | R8: =P8-Q8 -> 0 | V8: =V7 -> 0 | W8: =COUNTIFS('WTG PH-III'!$B$5:$B$198,$T$8,'WTG PH-III'!$C$5:$C$198,$U$8,'WTG PH-III'!$X$5:$X$198,">0") -> 0 | X8: =V8-W8 -> 0 | AB8: =AB7 -> 0 | AC8: =COUNTIFS('WTG PH-III'!$B$5:$B$198,$Z$8,'WTG PH-III'!$C$5:$C$198,$AA$8,'WTG PH-III'!$X$5:$X$198,">0") -> 0 | AD8: =AB8-AC8 -> 0 | AH8: =AH7 -> 0 | AI8: =COUNTIFS('WTG PH-III'!$B$5:$B$198,$AF$8,'WTG PH-III'!$C$5:$C$198,$AG$8,'WTG PH-III'!$X$5:$X$198,">0") -> 0 | AJ8: =AH8-AI8 -> 0
A9: =ROW(A4) -> 4 | B9: Plateload test | D9: =D8 -> 0 | E9: =SUM(K9,Q9,W9,AC9,AI9) -> 0 | F9: =D9-E9 -> 0 | J9: =J8 -> 0 | K9: =COUNTIFS('WTG PH-III'!$B$5:$B$198,$H$9,'WTG PH-III'!$C$5:$C$198,$I$9,'WTG PH-III'!$AG$5:$AG$198,">0") -> 0 | L9: =J9-K9 -> 0 | P9: =P8 -> 0 | Q9: =COUNTIFS('WTG PH-III'!$B$5:$B$198,$N$9,'WTG PH-III'!$C$5:$C$198,$O$9,'WTG PH-III'!$AG$5:$AG$198,">0") -> 0 | R9: =P9-Q9 -> 0 | V9: =V8 -> 0 | W9: =COUNTIFS('WTG PH-III'!$B$5:$B$198,$T$9,'WTG PH-III'!$C$5:$C$198,$U$9,'WTG PH-III'!$AG$5:$AG$198,">0") -> 0 | X9: =V9-W9 -> 0 | AB9: =AB8 -> 0 | AC9: =COUNTIFS('WTG PH-III'!$B$5:$B$198,$Z$9,'WTG PH-III'!$C$5:$C$198,$AA$9,'WTG PH-III'!$AG$5:$AG$198,">0") -> 0 | AD9: =AB9-AC9 -> 0 | AH9: =AH8 -> 0 | AI9: =COUNTIFS('WTG PH-III'!$B$5:$B$198,$AF$9,'WTG PH-III'!$C$5:$C$198,$AG$9,'WTG PH-III'!$AG$5:$AG$198,">0") -> 0 | AJ9: =AH9-AI9 -> 0
A10: =ROW(A5) -> 5 | B10: Excavation | D10: =D9 -> 0 | E10: =SUM(K10,Q10,W10,AC10,AI10) -> 0 | F10: =D10-E10 -> 0 | J10: =J9 -> 0 | K10: =COUNTIFS('WTG PH-III'!$B$5:$B$198,$H$10,'WTG PH-III'!$C$5:$C$198,$I$10,'WTG PH-III'!$AM$5:$AM$198,">0") -> 0 | L10: =J10-K10 -> 0 | P10: =P9 -> 0 | Q10: =COUNTIFS('WTG PH-III'!$B$5:$B$198,$N$10,'WTG PH-III'!$C$5:$C$198,$O$10,'WTG PH-III'!$AM$5:$AM$198,">0") -> 0 | R10: =P10-Q10 -> 0 | V10: =V9 -> 0 | W10: =COUNTIFS('WTG PH-III'!$B$5:$B$198,$T$10,'WTG PH-III'!$C$5:$C$198,$U$10,'WTG PH-III'!$AM$5:$AM$198,">0") -> 0 | X10: =V10-W10 -> 0 | AB10: =AB9 -> 0 | AC10: =COUNTIFS('WTG PH-III'!$B$5:$B$198,$Z$10,'WTG PH-III'!$C$5:$C$198,$AA$10,'WTG PH-III'!$AM$5:$AM$198,">0") -> 0 | AD10: =AB10-AC10 -> 0 | AH10: =AH9 -> 0 | AI10: =COUNTIFS('WTG PH-III'!$B$5:$B$198,$AF$10,'WTG PH-III'!$C$5:$C$198,$AG$10,'WTG PH-III'!$AM$5:$AM$198,">0") -> 0 | AJ10: =AH10-AI10 -> 0
A11: =ROW(A6) -> 6 | B11: PCC | D11: =D10 -> 0 | E11: =SUM(K11,Q11,W11,AC11,AI11) -> 0 | F11: =D11-E11 -> 0 | J11: =J10 -> 0 | K11: =COUNTIFS('WTG PH-III'!$B$5:$B$198,$H$11,'WTG PH-III'!$C$5:$C$198,$I$11,'WTG PH-III'!$BA$5:$BA$198,">0") -> 0 | L11: =J11-K11 -> 0 | P11: =P10 -> 0 | Q11: =COUNTIFS('WTG PH-III'!$B$5:$B$198,$N$11,'WTG PH-III'!$C$5:$C$198,$O$11,'WTG PH-III'!$BA$5:$BA$198,">0") -> 0 | R11: =P11-Q11 -> 0 | V11: =V10 -> 0 | W11: =COUNTIFS('WTG PH-III'!$B$5:$B$198,$T$11,'WTG PH-III'!$C$5:$C$198,$U$11,'WTG PH-III'!$BA$5:$BA$198,">0") -> 0 | X11: =V11-W11 -> 0 | AB11: =AB10 -> 0 | AC11: =COUNTIFS('WTG PH-III'!$B$5:$B$198,$Z$11,'WTG PH-III'!$C$5:$C$198,$AA$11,'WTG PH-III'!$BA$5:$BA$198,">0") -> 0 | AD11: =AB11-AC11 -> 0 | AH11: =AH10 -> 0 | AI11: =COUNTIFS('WTG PH-III'!$B$5:$B$198,$AF$11,'WTG PH-III'!$C$5:$C$198,$AG$11,'WTG PH-III'!$BA$5:$BA$198,">0") -> 0 | AJ11: =AH11-AI11 -> 0
A12: =ROW(A7) -> 7 | B12: Anchor Cage & Assembly | D12: =D11 -> 0 | E12: =SUM(K12,Q12,W12,AC12,AI12) -> 0 | F12: =D12-E12 -> 0 | J12: =J11 -> 0 | K12: =COUNTIFS('WTG PH-III'!$B$5:$B$198,$H$12,'WTG PH-III'!$C$5:$C$198,$I$12,'WTG PH-III'!$BH$5:$BH$198,">0") -> 0 | L12: =J12-K12 -> 0 | P12: =P11 -> 0 | Q12: =COUNTIFS('WTG PH-III'!$B$5:$B$198,$N$12,'WTG PH-III'!$C$5:$C$198,$O$12,'WTG PH-III'!$BH$5:$BH$198,">0") -> 0 | R12: =P12-Q12 -> 0 | V12: =V11 -> 0 | W12: =COUNTIFS('WTG PH-III'!$B$5:$B$198,$T$12,'WTG PH-III'!$C$5:$C$198,$U$12,'WTG PH-III'!$BH$5:$BH$198,">0") -> 0 | X12: =V12-W12 -> 0 | AB12: =AB11 -> 0 | AC12: =COUNTIFS('WTG PH-III'!$B$5:$B$198,$Z$12,'WTG PH-III'!$C$5:$C$198,$AA$12,'WTG PH-III'!$BH$5:$BH$198,">0") -> 0 | AD12: =AB12-AC12 -> 0 | AH12: =AH11 -> 0 | AI12: =COUNTIFS('WTG PH-III'!$B$5:$B$198,$AF$12,'WTG PH-III'!$C$5:$C$198,$AG$12,'WTG PH-III'!$BH$5:$BH$198,">0") -> 0 | AJ12: =AH12-AI12 -> 0
A13: =ROW(A8) -> 8 | B13: Steel Binding works | D13: =D12 -> 0 | E13: =SUM(K13,Q13,W13,AC13,AI13) -> 0 | F13: =D13-E13 -> 0 | J13: =J12 -> 0 | K13: =COUNTIFS('WTG PH-III'!$B$5:$B$198,$H$13,'WTG PH-III'!$C$5:$C$198,$I$13,'WTG PH-III'!$BO$5:$BO$198,">0") -> 0 | L13: =J13-K13 -> 0 | P13: =P12 -> 0 | Q13: =COUNTIFS('WTG PH-III'!$B$5:$B$198,$N$13,'WTG PH-III'!$C$5:$C$198,$O$13,'WTG PH-III'!$BO$5:$BO$198,">0") -> 0 | R13: =P13-Q13 -> 0 | V13: =V12 -> 0 | W13: =COUNTIFS('WTG PH-III'!$B$5:$B$198,$T$13,'WTG PH-III'!$C$5:$C$198,$U$13,'WTG PH-III'!$BO$5:$BO$198,">0") -> 0 | X13: =V13-W13 -> 0 | AB13: =AB12 -> 0 | AC13: =COUNTIFS('WTG PH-III'!$B$5:$B$198,$Z$13,'WTG PH-III'!$C$5:$C$198,$AA$13,'WTG PH-III'!$BO$5:$BO$198,">0") -> 0 | AD13: =AB13-AC13 -> 0 | AH13: =AH12 -> 0 | AI13: =COUNTIFS('WTG PH-III'!$B$5:$B$198,$AF$13,'WTG PH-III'!$C$5:$C$198,$AG$13,'WTG PH-III'!$BO$5:$BO$198,">0") -> 0 | AJ13: =AH13-AI13 -> 0
A14: =ROW(A9) -> 9 | B14: Raft Casting | D14: =D13 -> 0 | E14: =SUM(K14,Q14,W14,AC14,AI14) -> 0 | F14: =D14-E14 -> 0 | J14: =J13 -> 0 | K14: =COUNTIFS('WTG PH-III'!$B$5:$B$198,$H$14,'WTG PH-III'!$C$5:$C$198,$I$14,'WTG PH-III'!$BV$5:$BV$198,">0") -> 0 | L14: =J14-K14 -> 0 | P14: =P13 -> 0 | Q14: =COUNTIFS('WTG PH-III'!$B$5:$B$198,$N$14,'WTG PH-III'!$C$5:$C$198,$O$14,'WTG PH-III'!$BV$5:$BV$198,">0") -> 0 | R14: =P14-Q14 -> 0 | V14: =V13 -> 0 | W14: =COUNTIFS('WTG PH-III'!$B$5:$B$198,$T$14,'WTG PH-III'!$C$5:$C$198,$U$14,'WTG PH-III'!$BV$5:$BV$198,">0") -> 0 | X14: =V14-W14 -> 0 | AB14: =AB13 -> 0 | AC14: =COUNTIFS('WTG PH-III'!$B$5:$B$198,$Z$14,'WTG PH-III'!$C$5:$C$198,$AA$14,'WTG PH-III'!$BV$5:$BV$198,">0") -> 0 | AD14: =AB14-AC14 -> 0 | AH14: =AH13 -> 0 | AI14: =COUNTIFS('WTG PH-III'!$B$5:$B$198,$AF$14,'WTG PH-III'!$C$5:$C$198,$AG$14,'WTG PH-III'!$BV$5:$BV$198,">0") -> 0 | AJ14: =AH14-AI14 -> 0
A15: =ROW(A10) -> 10 | B15: Backfilling | D15: =D14 -> 0 | E15: =SUM(K15,Q15,W15,AC15,AI15) -> 0 | F15: =D15-E15 -> 0 | J15: =J14 -> 0 | K15: =COUNTIFS('WTG PH-III'!$B$5:$B$198,$H$15,'WTG PH-III'!$C$5:$C$198,$I$15,'WTG PH-III'!$CD$5:$CD$198,">0") -> 0 | L15: =J15-K15 -> 0 | P15: =P14 -> 0 | Q15: =COUNTIFS('WTG PH-III'!$B$5:$B$198,$N$15,'WTG PH-III'!$C$5:$C$198,$O$15,'WTG PH-III'!$CD$5:$CD$198,">0") -> 0 | R15: =P15-Q15 -> 0 | V15: =V14 -> 0 | W15: =COUNTIFS('WTG PH-III'!$B$5:$B$198,$T$15,'WTG PH-III'!$C$5:$C$198,$U$15,'WTG PH-III'!$CD$5:$CD$198,">0") -> 0 | X15: =V15-W15 -> 0 | AB15: =AB14 -> 0 | AC15: =COUNTIFS('WTG PH-III'!$B$5:$B$198,$Z$15,'WTG PH-III'!$C$5:$C$198,$AA$15,'WTG PH-III'!$CD$5:$CD$198,">0") -> 0 | AD15: =AB15-AC15 -> 0 | AH15: =AH14 -> 0 | AI15: =COUNTIFS('WTG PH-III'!$B$5:$B$198,$AF$15,'WTG PH-III'!$C$5:$C$198,$AG$15,'WTG PH-III'!$CD$5:$CD$198,">0") -> 0 | AJ15: =AH15-AI15 -> 0
A16: =ROW(A11) -> 11 | B16: Grouting | D16: =D15 -> 0 | E16: =SUM(K16,Q16,W16,AC16,AI16) -> 0 | F16: =D16-E16 -> 0 | J16: =J15 -> 0 | K16: =COUNTIFS('WTG PH-III'!$B$5:$B$198,$H$16,'WTG PH-III'!$C$5:$C$198,$I$16,'WTG PH-III'!$CK$5:$CK$198,">0") -> 0 | L16: =J16-K16 -> 0 | P16: =P15 -> 0 | Q16: =COUNTIFS('WTG PH-III'!$B$5:$B$198,$N$16,'WTG PH-III'!$C$5:$C$198,$O$16,'WTG PH-III'!$CK$5:$CK$198,">0") -> 0 | R16: =P16-Q16 -> 0 | V16: =V15 -> 0 | W16: =COUNTIFS('WTG PH-III'!$B$5:$B$198,$T$16,'WTG PH-III'!$C$5:$C$198,$U$16,'WTG PH-III'!$CK$5:$CK$198,">0") -> 0 | X16: =V16-W16 -> 0 | AB16: =AB15 -> 0 | AC16: =COUNTIFS('WTG PH-III'!$B$5:$B$198,$Z$16,'WTG PH-III'!$C$5:$C$198,$AA$16,'WTG PH-III'!$CK$5:$CK$198,">0") -> 0 | AD16: =AB16-AC16 -> 0 | AH16: =AH15 -> 0 | AI16: =COUNTIFS('WTG PH-III'!$B$5:$B$198,$AF$16,'WTG PH-III'!$C$5:$C$198,$AG$16,'WTG PH-III'!$CK$5:$CK$198,">0") -> 0 | AJ16: =AH16-AI16 -> 0
A17: =ROW(A12) -> 12 | B17: USS & Transformer Foundation | D17: =D16 -> 0 | E17: =SUM(K17,Q17,W17,AC17,AI17) -> 0 | F17: =D17-E17 -> 0 | J17: =J16 -> 0 | K17: =COUNTIFS('WTG PH-III'!$B$5:$B$198,$H$17,'WTG PH-III'!$C$5:$C$198,$I$17,'WTG PH-III'!$CT$5:$CT$198,">0") -> 0 | L17: =J17-K17 -> 0 | P17: =P16 -> 0 | Q17: =COUNTIFS('WTG PH-III'!$B$5:$B$198,$N$17,'WTG PH-III'!$C$5:$C$198,$O$17,'WTG PH-III'!$CT$5:$CT$198,">0") -> 0 | R17: =P17-Q17 -> 0 | V17: =V16 -> 0 | W17: =COUNTIFS('WTG PH-III'!$B$5:$B$198,$T$17,'WTG PH-III'!$C$5:$C$198,$U$17,'WTG PH-III'!$CT$5:$CT$198,">0") -> 0 | X17: =V17-W17 -> 0 | AB17: =AB16 -> 0 | AC17: =COUNTIFS('WTG PH-III'!$B$5:$B$198,$Z$17,'WTG PH-III'!$C$5:$C$198,$AA$17,'WTG PH-III'!$CT$5:$CT$198,">0") -> 0 | AD17: =AB17-AC17 -> 0 | AH17: =AH16 -> 0 | AI17: =COUNTIFS('WTG PH-III'!$B$5:$B$198,$AF$17,'WTG PH-III'!$C$5:$C$198,$AG$17,'WTG PH-III'!$CT$5:$CT$198,">0") -> 0 | AJ17: =AH17-AI17 -> 0
A18: =ROW(A13) -> 13 | B18: WTG Connecting Road | D18: =D17 -> 0 | E18: =SUM(K18,Q18,W18,AC18,AI18) -> 0 | F18: =D18-E18 -> 0 | J18: =J17 -> 0 | K18: =COUNTIFS('WTG PH-III'!$B$5:$B$198,$H$18,'WTG PH-III'!$C$5:$C$198,$I$18,'WTG PH-III'!$DA$5:$DA$198,">0") -> 0 | L18: =J18-K18 -> 0 | P18: =P17 -> 0 | Q18: =COUNTIFS('WTG PH-III'!$B$5:$B$198,$N$18,'WTG PH-III'!$C$5:$C$198,$O$18,'WTG PH-III'!$DA$5:$DA$198,">0") -> 0 | R18: =P18-Q18 -> 0 | V18: =V17 -> 0 | W18: =COUNTIFS('WTG PH-III'!$B$5:$B$198,$T$18,'WTG PH-III'!$C$5:$C$198,$U$18,'WTG PH-III'!$DA$5:$DA$198,">0") -> 0 | X18: =V18-W18 -> 0 | AB18: =AB17 -> 0 | AC18: =COUNTIFS('WTG PH-III'!$B$5:$B$198,$Z$18,'WTG PH-III'!$C$5:$C$198,$AA$18,'WTG PH-III'!$DA$5:$DA$198,">0") -> 0 | AD18: =AB18-AC18 -> 0 | AH18: =AH17 -> 0 | AI18: =COUNTIFS('WTG PH-III'!$B$5:$B$198,$AF$18,'WTG PH-III'!$C$5:$C$198,$AG$18,'WTG PH-III'!$DA$5:$DA$198,">0") -> 0 | AJ18: =AH18-AI18 -> 0
A19: =ROW(A14) -> 14 | B19: Crane Pad | D19: =D18 -> 0 | E19: =SUM(K19,Q19,W19,AC19,AI19) -> 0 | F19: =D19-E19 -> 0 | J19: =J18 -> 0 | K19: =COUNTIFS('WTG PH-III'!$B$5:$B$198,$H$19,'WTG PH-III'!$C$5:$C$198,$I$19,'WTG PH-III'!$DP$5:$DP$198,">0") -> 0 | L19: =J19-K19 -> 0 | P19: =P18 -> 0 | Q19: =COUNTIFS('WTG PH-III'!$B$5:$B$198,$N$19,'WTG PH-III'!$C$5:$C$198,$O$19,'WTG PH-III'!$DP$5:$DP$198,">0") -> 0 | R19: =P19-Q19 -> 0 | V19: =V18 -> 0 | W19: =COUNTIFS('WTG PH-III'!$B$5:$B$198,$T$19,'WTG PH-III'!$C$5:$C$198,$U$19,'WTG PH-III'!$DP$5:$DP$198,">0") -> 0 | X19: =V19-W19 -> 0 | AB19: =AB18 -> 0 | AC19: =COUNTIFS('WTG PH-III'!$B$5:$B$198,$Z$19,'WTG PH-III'!$C$5:$C$198,$AA$19,'WTG PH-III'!$DP$5:$DP$198,">0") -> 0 | AD19: =AB19-AC19 -> 0 | AH19: =AH18 -> 0 | AI19: =COUNTIFS('WTG PH-III'!$B$5:$B$198,$AF$19,'WTG PH-III'!$C$5:$C$198,$AG$19,'WTG PH-III'!$DP$5:$DP$198,">0") -> 0 | AJ19: =AH19-AI19 -> 0
A20: =ROW(A15) -> 15 | B20: WTG Erection | D20: =D19 -> 0 | E20: =SUM(K20,Q20,W20,AC20,AI20) -> 0 | F20: =D20-E20 -> 0 | J20: =J19 -> 0 | K20: =COUNTIFS('WTG PH-III'!$B$5:$B$198,$H$20,'WTG PH-III'!$C$5:$C$198,$I$20,'WTG PH-III'!$DW$5:$DW$198,">0") -> 0 | L20: =J20-K20 -> 0 | P20: =P19 -> 0 | Q20: =COUNTIFS('WTG PH-III'!$B$5:$B$198,$N$20,'WTG PH-III'!$C$5:$C$198,$O$20,'WTG PH-III'!$DW$5:$DW$198,">0") -> 0 | R20: =P20-Q20 -> 0 | V20: =V19 -> 0 | W20: =COUNTIFS('WTG PH-III'!$B$5:$B$198,$T$20,'WTG PH-III'!$C$5:$C$198,$U$20,'WTG PH-III'!$DW$5:$DW$198,">0") -> 0 | X20: =V20-W20 -> 0 | AB20: =AB19 -> 0 | AC20: =COUNTIFS('WTG PH-III'!$B$5:$B$198,$Z$20,'WTG PH-III'!$C$5:$C$198,$AA$20,'WTG PH-III'!$DW$5:$DW$198,">0") -> 0 | AD20: =AB20-AC20 -> 0 | AH20: =AH19 -> 0 | AI20: =COUNTIFS('WTG PH-III'!$B$5:$B$198,$AF$20,'WTG PH-III'!$C$5:$C$198,$AG$20,'WTG PH-III'!$DW$5:$DW$198,">0") -> 0 | AJ20: =AH20-AI20 -> 0
A21: =ROW(A16) -> 16 | B21: MCC | D21: =D20 -> 0 | E21: =SUM(K21,Q21,W21,AC21,AI21) -> 0 | F21: =D21-E21 -> 0 | J21: =J20 -> 0 | K21: =COUNTIFS('WTG PH-III'!$B$5:$B$198,$H$21,'WTG PH-III'!$C$5:$C$198,$I$21,'WTG PH-III'!$EK$5:$EK$198,">0") -> 0 | L21: =J21-K21 -> 0 | P21: =P20 -> 0 | Q21: =COUNTIFS('WTG PH-III'!$B$5:$B$198,$N$21,'WTG PH-III'!$C$5:$C$198,$O$21,'WTG PH-III'!$EK$5:$EK$198,">0") -> 0 | R21: =P21-Q21 -> 0 | V21: =V20 -> 0 | W21: =COUNTIFS('WTG PH-III'!$B$5:$B$198,$T$21,'WTG PH-III'!$C$5:$C$198,$U$21,'WTG PH-III'!$EK$5:$EK$198,">0") -> 0 | X21: =V21-W21 -> 0 | AB21: =AB20 -> 0 | AC21: =COUNTIFS('WTG PH-III'!$B$5:$B$198,$Z$21,'WTG PH-III'!$C$5:$C$198,$AA$21,'WTG PH-III'!$EK$5:$EK$198,">0") -> 0 | AD21: =AB21-AC21 -> 0 | AH21: =AH20 -> 0 | AI21: =COUNTIFS('WTG PH-III'!$B$5:$B$198,$AF$21,'WTG PH-III'!$C$5:$C$198,$AG$21,'WTG PH-III'!$EK$5:$EK$198,">0") -> 0 | AJ21: =AH21-AI21 -> 0
A22: =ROW(A17) -> 17 | B22: Pre-Comm | D22: =D21 -> 0 | E22: =SUM(K22,Q22,W22,AC22,AI22) -> 0 | F22: =D22-E22 -> 0 | J22: =J21 -> 0 | K22: =COUNTIFS('WTG PH-III'!$B$5:$B$198,$H$22,'WTG PH-III'!$C$5:$C$198,$I$22,'WTG PH-III'!$ER$5:$ER$198,">0") -> 0 | L22: =J22-K22 -> 0 | P22: =P21 -> 0 | Q22: =COUNTIFS('WTG PH-III'!$B$5:$B$198,$N$22,'WTG PH-III'!$C$5:$C$198,$O$22,'WTG PH-III'!$ER$5:$ER$198,">0") -> 0 | R22: =P22-Q22 -> 0 | V22: =V21 -> 0 | W22: =COUNTIFS('WTG PH-III'!$B$5:$B$198,$T$22,'WTG PH-III'!$C$5:$C$198,$U$22,'WTG PH-III'!$ER$5:$ER$198,">0") -> 0 | X22: =V22-W22 -> 0 | AB22: =AB21 -> 0 | AC22: =COUNTIFS('WTG PH-III'!$B$5:$B$198,$Z$22,'WTG PH-III'!$C$5:$C$198,$AA$22,'WTG PH-III'!$ER$5:$ER$198,">0") -> 0 | AD22: =AB22-AC22 -> 0 | AH22: =AH21 -> 0 | AI22: =COUNTIFS('WTG PH-III'!$B$5:$B$198,$AF$22,'WTG PH-III'!$C$5:$C$198,$AG$22,'WTG PH-III'!$ER$5:$ER$198,">0") -> 0 | AJ22: =AH22-AI22 -> 0
A23: =ROW(A18) -> 18 | B23: WTG Commissioining | D23: =D22 -> 0 | E23: =SUM(K23,Q23,W23,AC23,AI23) -> 0 | F23: =D23-E23 -> 0 | J23: =J22 -> 0 | K23: =COUNTIFS('WTG PH-III'!$B$5:$B$198,$H$23,'WTG PH-III'!$C$5:$C$198,$I$23,'WTG PH-III'!$GA$5:$GA$198,">0") -> 0 | L23: =J23-K23 -> 0 | P23: =P22 -> 0 | Q23: =COUNTIFS('WTG PH-III'!$B$5:$B$198,$N$23,'WTG PH-III'!$C$5:$C$198,$O$23,'WTG PH-III'!$GA$5:$GA$198,">0") -> 0 | R23: =P23-Q23 -> 0 | V23: =V22 -> 0 | W23: =COUNTIFS('WTG PH-III'!$B$5:$B$198,$T$23,'WTG PH-III'!$C$5:$C$198,$U$23,'WTG PH-III'!$GA$5:$GA$198,">0") -> 0 | X23: =V23-W23 -> 0 | AB23: =AB22 -> 0 | AC23: =COUNTIFS('WTG PH-III'!$B$5:$B$198,$Z$23,'WTG PH-III'!$C$5:$C$198,$AA$23,'WTG PH-III'!$GA$5:$GA$198,">0") -> 0 | AD23: =AB23-AC23 -> 0 | AH23: =AH22 -> 0 | AI23: =COUNTIFS('WTG PH-III'!$B$5:$B$198,$AF$23,'WTG PH-III'!$C$5:$C$198,$AG$23,'WTG PH-III'!$GA$5:$GA$198,">0") -> 0 | AJ23: =AH23-AI23 -> 0
A24: II | B24: WTG ELECTRICAL (USS, Trafo & 33kV)
A25: 1 | B25: USS Erection & Readiness | C25: PSS-4 | D25: =D23 -> 0 | E25: =SUM(K25,Q25,W25,AC25,AI25) -> 0 | F25: =D25-E25 -> 0 | J25: =J23 -> 0 | K25: =COUNTIFS('WTG PH-III'!$B$5:$B$198,$H$25,'WTG PH-III'!$C$5:$C$198,$I$25,'WTG PH-III'!$ED$5:$ED$198,">0") -> 0 | L25: =J25-K25 -> 0 | P25: =P23 -> 0 | Q25: =COUNTIFS('WTG PH-III'!$B$5:$B$198,$N$25,'WTG PH-III'!$C$5:$C$198,$O$25,'WTG PH-III'!$ED$5:$ED$198,">0") -> 0 | R25: =P25-Q25 -> 0 | V25: =V23 -> 0 | W25: =COUNTIFS('WTG PH-III'!$B$5:$B$198,$T$25,'WTG PH-III'!$C$5:$C$198,$U$25,'WTG PH-III'!$ED$5:$ED$198,">0") -> 0 | X25: =V25-W25 -> 0 | AB25: =AB23 -> 0 | AC25: =COUNTIFS('WTG PH-III'!$B$5:$B$198,$Z$25,'WTG PH-III'!$C$5:$C$198,$AA$25,'WTG PH-III'!$ED$5:$ED$198,">0") -> 0 | AD25: =AB25-AC25 -> 0 | AH25: =AH23 -> 0 | AI25: =COUNTIFS('WTG PH-III'!$B$5:$B$198,$AF$25,'WTG PH-III'!$C$5:$C$198,$AG$25,'WTG PH-III'!$ED$5:$ED$198,">0") -> 0 | AJ25: =AH25-AI25 -> 0
A26: 2 | B26: USS Testing | C26: PSS-4 | D26: =D25 -> 0 | E26: =SUM(K26,Q26,W26,AC26,AI26) -> 0 | F26: =D26-E26 -> 0 | J26: =J25 -> 0 | K26: =COUNTIFS('WTG PH-III'!$B$5:$B$198,$H$26,'WTG PH-III'!$C$5:$C$198,$I$26,'WTG PH-III'!$EY$5:$EY$198,">0") -> 0 | L26: =J26-K26 -> 0 | P26: =P25 -> 0 | Q26: =COUNTIFS('WTG PH-III'!$B$5:$B$198,$N$26,'WTG PH-III'!$C$5:$C$198,$O$26,'WTG PH-III'!$EY$5:$EY$198,">0") -> 0 | R26: =P26-Q26 -> 0 | V26: =V25 -> 0 | W26: =COUNTIFS('WTG PH-III'!$B$5:$B$198,$T$26,'WTG PH-III'!$C$5:$C$198,$U$26,'WTG PH-III'!$EY$5:$EY$198,">0") -> 0 | X26: =V26-W26 -> 0 | AB26: =AB25 -> 0 | AC26: =COUNTIFS('WTG PH-III'!$B$5:$B$198,$Z$26,'WTG PH-III'!$C$5:$C$198,$AA$26,'WTG PH-III'!$EY$5:$EY$198,">0") -> 0 | AD26: =AB26-AC26 -> 0 | AH26: =AH25 -> 0 | AI26: =COUNTIFS('WTG PH-III'!$B$5:$B$198,$AF$26,'WTG PH-III'!$C$5:$C$198,$AG$26,'WTG PH-III'!$EY$5:$EY$198,">0") -> 0 | AJ26: =AH26-AI26 -> 0
A27: I | B27: WTG CIVIL & MECH
A28: =ROW(A23) -> 23 | B28: Soil Test | C28: PSS-8 | D28: =SUM(J28,P28,V28,AB28,AH28) -> 0 | E28: =SUM(K28,Q28,W28,AC28,AI28) -> 0 | F28: =D28-E28 -> 0 | J28: =COUNTIFS('WTG PH-III'!$B$5:$B$198,$H$28,'WTG PH-III'!$C$5:$C$198,$I$28) -> 0 | K28: =COUNTIFS('WTG PH-III'!$B$5:$B$198,$H$28,'WTG PH-III'!$C$5:$C$198,$I$28,'WTG PH-III'!$P$5:$P$198,">0") -> 0 | L28: =J28-K28 -> 0 | P28: =COUNTIFS('WTG PH-III'!$B$5:$B$198,$N$28,'WTG PH-III'!$C$5:$C$198,$O$28) -> 0 | Q28: =COUNTIFS('WTG PH-III'!$B$5:$B$198,$N$28,'WTG PH-III'!$C$5:$C$198,$O$28,'WTG PH-III'!$P$5:$P$198,">0") -> 0 | R28: =P28-Q28 -> 0 | AH28: =COUNTIFS('WTG PH-III'!$B$5:$B$198,$AF$28,'WTG PH-III'!$C$5:$C$198,$AG$28) -> 0 | AI28: =COUNTIFS('WTG PH-III'!$B$5:$B$198,$AF$28,'WTG PH-III'!$C$5:$C$198,$AG$28,'WTG PH-III'!$P$5:$P$198,">0") -> 0 | AJ28: =AH28-AI28 -> 0
A29: =ROW(A24) -> 24 | B29: Stone Column Drawing's Status | C29: PSS-8 | D29: =D28 -> 0 | J29: =J28 -> 0 | P29: =P28 -> 0 | AH29: =AH28 -> 0
A30: =ROW(A25) -> 25 | B30: Stone Column | C30: PSS-8 | D30: =D29 -> 0 | E30: =SUM(K30,Q30,W30,AC30,AI30) -> 0 | F30: =D30-E30 -> 0 | J30: =J29 -> 0 | K30: =COUNTIFS('WTG PH-III'!$B$5:$B$198,$H$30,'WTG PH-III'!$C$5:$C$198,$I$30,'WTG PH-III'!$X$5:$X$198,">0") -> 0 | L30: =J30-K30 -> 0 | P30: =P29 -> 0 | Q30: =COUNTIFS('WTG PH-III'!$B$5:$B$198,$N$30,'WTG PH-III'!$C$5:$C$198,$O$30,'WTG PH-III'!$X$5:$X$198,">0") -> 0 | R30: =P30-Q30 -> 0 | AH30: =AH29 -> 0 | AI30: =COUNTIFS('WTG PH-III'!$B$5:$B$198,$AF$30,'WTG PH-III'!$C$5:$C$198,$AG$30,'WTG PH-III'!$X$5:$X$198,">0") -> 0 | AJ30: =AH30-AI30 -> 0
A31: =ROW(A26) -> 26 | B31: Plateload test | C31: PSS-8 | D31: =D30 -> 0 | E31: =SUM(K31,Q31,W31,AC31,AI31) -> 0 | F31: =D31-E31 -> 0 | J31: =J30 -> 0 | K31: =COUNTIFS('WTG PH-III'!$B$5:$B$198,$H$31,'WTG PH-III'!$C$5:$C$198,$I$31,'WTG PH-III'!$AG$5:$AG$198,">0") -> 0 | L31: =J31-K31 -> 0 | P31: =P30 -> 0 | Q31: =COUNTIFS('WTG PH-III'!$B$5:$B$198,$N$31,'WTG PH-III'!$C$5:$C$198,$O$31,'WTG PH-III'!$AG$5:$AG$198,">0") -> 0 | R31: =P31-Q31 -> 0 | AH31: =AH30 -> 0 | AI31: =COUNTIFS('WTG PH-III'!$B$5:$B$198,$AF$31,'WTG PH-III'!$C$5:$C$198,$AG$31,'WTG PH-III'!$AG$5:$AG$198,">0") -> 0 | AJ31: =AH31-AI31 -> 0
A32: =ROW(A27) -> 27 | B32: Excavation | C32: PSS-8 | D32: =D31 -> 0 | E32: =SUM(K32,Q32,W32,AC32,AI32) -> 0 | F32: =D32-E32 -> 0 | J32: =J31 -> 0 | K32: =COUNTIFS('WTG PH-III'!$B$5:$B$198,$H$32,'WTG PH-III'!$C$5:$C$198,$I$32,'WTG PH-III'!$AM$5:$AM$198,">0") -> 0 | L32: =J32-K32 -> 0 | P32: =P31 -> 0 | Q32: =COUNTIFS('WTG PH-III'!$B$5:$B$198,$N$32,'WTG PH-III'!$C$5:$C$198,$O$32,'WTG PH-III'!$AM$5:$AM$198,">0") -> 0 | R32: =P32-Q32 -> 0 | AH32: =AH31 -> 0 | AI32: =COUNTIFS('WTG PH-III'!$B$5:$B$198,$AF$32,'WTG PH-III'!$C$5:$C$198,$AG$32,'WTG PH-III'!$AM$5:$AM$198,">0") -> 0 | AJ32: =AH32-AI32 -> 0
A33: =ROW(A28) -> 28 | B33: PCC | C33: PSS-8 | D33: =D32 -> 0 | E33: =SUM(K33,Q33,W33,AC33,AI33) -> 0 | F33: =D33-E33 -> 0 | J33: =J32 -> 0 | K33: =COUNTIFS('WTG PH-III'!$B$5:$B$198,$H$33,'WTG PH-III'!$C$5:$C$198,$I$33,'WTG PH-III'!$BA$5:$BA$198,">0") -> 0 | L33: =J33-K33 -> 0 | P33: =P32 -> 0 | Q33: =COUNTIFS('WTG PH-III'!$B$5:$B$198,$N$33,'WTG PH-III'!$C$5:$C$198,$O$33,'WTG PH-III'!$BA$5:$BA$198,">0") -> 0 | R33: =P33-Q33 -> 0 | AH33: =AH32 -> 0 | AI33: =COUNTIFS('WTG PH-III'!$B$5:$B$198,$AF$33,'WTG PH-III'!$C$5:$C$198,$AG$33,'WTG PH-III'!$BA$5:$BA$198,">0") -> 0 | AJ33: =AH33-AI33 -> 0
A34: =ROW(A29) -> 29 | B34: Anchor Cage & Assembly | C34: PSS-8 | D34: =D33 -> 0 | E34: =SUM(K34,Q34,W34,AC34,AI34) -> 0 | F34: =D34-E34 -> 0 | J34: =J33 -> 0 | K34: =COUNTIFS('WTG PH-III'!$B$5:$B$198,$H$34,'WTG PH-III'!$C$5:$C$198,$I$34,'WTG PH-III'!$BH$5:$BH$198,">0") -> 0 | L34: =J34-K34 -> 0 | P34: =P33 -> 0 | Q34: =COUNTIFS('WTG PH-III'!$B$5:$B$198,$N$34,'WTG PH-III'!$C$5:$C$198,$O$34,'WTG PH-III'!$BH$5:$BH$198,">0") -> 0 | R34: =P34-Q34 -> 0 | AH34: =AH33 -> 0 | AI34: =COUNTIFS('WTG PH-III'!$B$5:$B$198,$AF$34,'WTG PH-III'!$C$5:$C$198,$AG$34,'WTG PH-III'!$BH$5:$BH$198,">0") -> 0 | AJ34: =AH34-AI34 -> 0
A35: =ROW(A30) -> 30 | B35: Steel Binding works | C35: PSS-8 | D35: =D34 -> 0 | E35: =SUM(K35,Q35,W35,AC35,AI35) -> 0 | F35: =D35-E35 -> 0 | J35: =J34 -> 0 | K35: =COUNTIFS('WTG PH-III'!$B$5:$B$198,$H$35,'WTG PH-III'!$C$5:$C$198,$I$35,'WTG PH-III'!$BO$5:$BO$198,">0") -> 0 | L35: =J35-K35 -> 0 | P35: =P34 -> 0 | Q35: =COUNTIFS('WTG PH-III'!$B$5:$B$198,$N$35,'WTG PH-III'!$C$5:$C$198,$O$35,'WTG PH-III'!$BO$5:$BO$198,">0") -> 0 | R35: =P35-Q35 -> 0 | AH35: =AH34 -> 0 | AI35: =COUNTIFS('WTG PH-III'!$B$5:$B$198,$AF$35,'WTG PH-III'!$C$5:$C$198,$AG$35,'WTG PH-III'!$BO$5:$BO$198,">0") -> 0 | AJ35: =AH35-AI35 -> 0
A36: =ROW(A31) -> 31 | B36: Raft Casting | C36: PSS-8 | D36: =D35 -> 0 | E36: =SUM(K36,Q36,W36,AC36,AI36) -> 0 | F36: =D36-E36 -> 0 | J36: =J35 -> 0 | K36: =COUNTIFS('WTG PH-III'!$B$5:$B$198,$H$36,'WTG PH-III'!$C$5:$C$198,$I$36,'WTG PH-III'!$BV$5:$BV$198,">0") -> 0 | L36: =J36-K36 -> 0 | P36: =P35 -> 0 | Q36: =COUNTIFS('WTG PH-III'!$B$5:$B$198,$N$36,'WTG PH-III'!$C$5:$C$198,$O$36,'WTG PH-III'!$BV$5:$BV$198,">0") -> 0 | R36: =P36-Q36 -> 0 | AH36: =AH35 -> 0 | AI36: =COUNTIFS('WTG PH-III'!$B$5:$B$198,$AF$36,'WTG PH-III'!$C$5:$C$198,$AG$36,'WTG PH-III'!$BV$5:$BV$198,">0") -> 0 | AJ36: =AH36-AI36 -> 0
A37: =ROW(A32) -> 32 | B37: Backfilling | C37: PSS-8 | D37: =D36 -> 0 | E37: =SUM(K37,Q37,W37,AC37,AI37) -> 0 | F37: =D37-E37 -> 0 | J37: =J36 -> 0 | K37: =COUNTIFS('WTG PH-III'!$B$5:$B$198,$H$37,'WTG PH-III'!$C$5:$C$198,$I$37,'WTG PH-III'!$CD$5:$CD$198,">0") -> 0 | L37: =J37-K37 -> 0 | P37: =P36 -> 0 | Q37: =COUNTIFS('WTG PH-III'!$B$5:$B$198,$N$37,'WTG PH-III'!$C$5:$C$198,$O$37,'WTG PH-III'!$CD$5:$CD$198,">0") -> 0 | R37: =P37-Q37 -> 0 | AH37: =AH36 -> 0 | AI37: =COUNTIFS('WTG PH-III'!$B$5:$B$198,$AF$37,'WTG PH-III'!$C$5:$C$198,$AG$37,'WTG PH-III'!$CD$5:$CD$198,">0") -> 0 | AJ37: =AH37-AI37 -> 0
A38: =ROW(A33) -> 33 | B38: Grouting | C38: PSS-8 | D38: =D37 -> 0 | E38: =SUM(K38,Q38,W38,AC38,AI38) -> 0 | F38: =D38-E38 -> 0 | J38: =J37 -> 0 | K38: =COUNTIFS('WTG PH-III'!$B$5:$B$198,$H$38,'WTG PH-III'!$C$5:$C$198,$I$38,'WTG PH-III'!$CK$5:$CK$198,">0") -> 0 | L38: =J38-K38 -> 0 | P38: =P37 -> 0 | Q38: =COUNTIFS('WTG PH-III'!$B$5:$B$198,$N$38,'WTG PH-III'!$C$5:$C$198,$O$38,'WTG PH-III'!$CK$5:$CK$198,">0") -> 0 | R38: =P38-Q38 -> 0 | AH38: =AH37 -> 0 | AI38: =COUNTIFS('WTG PH-III'!$B$5:$B$198,$AF$38,'WTG PH-III'!$C$5:$C$198,$AG$38,'WTG PH-III'!$CK$5:$CK$198,">0") -> 0 | AJ38: =AH38-AI38 -> 0
A39: =ROW(A34) -> 34 | B39: USS & Transformer Foundation | C39: PSS-8 | D39: =D38 -> 0 | E39: =SUM(K39,Q39,W39,AC39,AI39) -> 0 | F39: =D39-E39 -> 0 | J39: =J38 -> 0 | K39: =COUNTIFS('WTG PH-III'!$B$5:$B$198,$H$39,'WTG PH-III'!$C$5:$C$198,$I$39,'WTG PH-III'!$CT$5:$CT$198,">0") -> 0 | L39: =J39-K39 -> 0 | P39: =P38 -> 0 | Q39: =COUNTIFS('WTG PH-III'!$B$5:$B$198,$N$39,'WTG PH-III'!$C$5:$C$198,$O$39,'WTG PH-III'!$CT$5:$CT$198,">0") -> 0 | R39: =P39-Q39 -> 0 | AH39: =AH38 -> 0 | AI39: =COUNTIFS('WTG PH-III'!$B$5:$B$198,$AF$39,'WTG PH-III'!$C$5:$C$198,$AG$39,'WTG PH-III'!$CT$5:$CT$198,">0") -> 0 | AJ39: =AH39-AI39 -> 0
A40: =ROW(A35) -> 35 | B40: WTG Connecting Road | C40: PSS-8 | D40: =D39 -> 0 | E40: =SUM(K40,Q40,W40,AC40,AI40) -> 0 | F40: =D40-E40 -> 0 | J40: =J39 -> 0 | K40: =COUNTIFS('WTG PH-III'!$B$5:$B$198,$H$40,'WTG PH-III'!$C$5:$C$198,$I$40,'WTG PH-III'!$DA$5:$DA$198,">0") -> 0 | L40: =J40-K40 -> 0 | P40: =P39 -> 0 | Q40: =COUNTIFS('WTG PH-III'!$B$5:$B$198,$N$40,'WTG PH-III'!$C$5:$C$198,$O$40,'WTG PH-III'!$DA$5:$DA$198,">0") -> 0 | R40: =P40-Q40 -> 0 | AH40: =AH39 -> 0 | AI40: =COUNTIFS('WTG PH-III'!$B$5:$B$198,$AF$40,'WTG PH-III'!$C$5:$C$198,$AG$40,'WTG PH-III'!$DA$5:$DA$198,">0") -> 0 | AJ40: =AH40-AI40 -> 0
A41: =ROW(A36) -> 36 | B41: Crane Pad | C41: PSS-8 | D41: =D40 -> 0 | E41: =SUM(K41,Q41,W41,AC41,AI41) -> 0 | F41: =D41-E41 -> 0 | J41: =J40 -> 0 | K41: =COUNTIFS('WTG PH-III'!$B$5:$B$198,$H$41,'WTG PH-III'!$C$5:$C$198,$I$41,'WTG PH-III'!$DP$5:$DP$198,">0") -> 0 | L41: =J41-K41 -> 0 | P41: =P40 -> 0 | Q41: =COUNTIFS('WTG PH-III'!$B$5:$B$198,$N$41,'WTG PH-III'!$C$5:$C$198,$O$41,'WTG PH-III'!$DP$5:$DP$198,">0") -> 0 | R41: =P41-Q41 -> 0 | AH41: =AH40 -> 0 | AI41: =COUNTIFS('WTG PH-III'!$B$5:$B$198,$AF$41,'WTG PH-III'!$C$5:$C$198,$AG$41,'WTG PH-III'!$DP$5:$DP$198,">0") -> 0 | AJ41: =AH41-AI41 -> 0
A42: =ROW(A37) -> 37 | B42: WTG Erection | C42: PSS-8 | D42: =D41 -> 0 | E42: =SUM(K42,Q42,W42,AC42,AI42) -> 0 | F42: =D42-E42 -> 0 | J42: =J41 -> 0 | K42: =COUNTIFS('WTG PH-III'!$B$5:$B$198,$H$42,'WTG PH-III'!$C$5:$C$198,$I$42,'WTG PH-III'!$DW$5:$DW$198,">0") -> 0 | L42: =J42-K42 -> 0 | P42: =P41 -> 0 | Q42: =COUNTIFS('WTG PH-III'!$B$5:$B$198,$N$42,'WTG PH-III'!$C$5:$C$198,$O$42,'WTG PH-III'!$DW$5:$DW$198,">0") -> 0 | R42: =P42-Q42 -> 0 | AH42: =AH41 -> 0 | AI42: =COUNTIFS('WTG PH-III'!$B$5:$B$198,$AF$42,'WTG PH-III'!$C$5:$C$198,$AG$42,'WTG PH-III'!$DW$5:$DW$198,">0") -> 0 | AJ42: =AH42-AI42 -> 0
...

Sheet Sheet2
A1: WTG 243 | B1: WTG 230
A2: WTG 133 | B2: WTG 208
A3: WTG 405 | B3: WTG 186
A4: WTG 244 | B4: WTG 164
A5: WTG 327 | B5: WTG 141
A6: WTG 329 | B6: WTG 121
A7: WTG 233A | B7: WTG 123
A8: WTG 353 | B8: WTG 143
A9: WTG 354 | B9: WTG 144
A10: WTG 373 | B10: WTG 145
A11: WTG 377 | B11: WTG 400
A12: WTG 378 | B12: WTG 376
... A158: WTG 141 | B158: WTG 398
A159: WTG 164
A160: WTG 352
A161: WTG 186

Sheet SUMMARY
A1: ADANI GREEN ENERGY KHAVDA PH-III 194 WTGs (1008.8 MWac) | O1: Reporting Date | Q1: =Q2+1 -> 46081 | T1: 46076 | U1: =T1+6 -> 46082
O2: Progress Date | Q2: 46080
A3: S.No | B3: Description | C3: Total Scope | D3: Achieved | E3: Balance | G3: Weekly Plan (23-Feb'26 -01 -Mar'26) | K3: Monthly Plan | O3: Cumulative | S3: SPV
G4: Plan | H4: Achieved | I4: Balance | K4: Plan | L4: Achieved | M4: Balance | O4: Plan | P4: Achieved | Q4: Balance | S4: ARE3L | T4: ASEJ6PL | U4: AHEJ5L | V4: AGE25BL | W4: AGE25CL | X4: AGE26AL | Y4: AGE25CL | Z4: AGE26AL
A5: I | B5: WTG CIVIL & MECH | S5: PSS-08 | T5: PSS-08 | U5: PSS-05 | V5: PSS-09 | W5: PSS-11 | X5: PSS-12 | Y5: PSS-14 | Z5: PSS-14
A6: =ROW(A1) -> 1 | B6: Soil Test | C6: 194 | D6: 194 | E6: =C6-D6 -> 0 | G6: 0 | H6: 0 | I6: 0 | O6: 194 | P6: 194 | Q6: =O6-P6 -> 0 | S6: =COUNTIFS('WTG PH-III'!$P$5:$P$205,"Done",'WTG PH-III'!$C$5:$C$205,S$4,'WTG PH-III'!$B$5:$B$205,SUMMARY!S$5) -> 5 | T6: =COUNTIFS('WTG PH-III'!$P$5:$P$205,"Done",'WTG PH-III'!$C$5:$C$205,T$4,'WTG PH-III'!$B$5:$B$205,SUMMARY!T$5) -> 12 | U6: =COUNTIFS('WTG PH-III'!$P$5:$P$205,"Done",'WTG PH-III'!$C$5:$C$205,U$4,'WTG PH-III'!$B$5:$B$205,SUMMARY!U$5) -> 39 | V6: =COUNTIFS('WTG PH-III'!$P$5:$P$205,"Done",'WTG PH-III'!$C$5:$C$205,V$4,'WTG PH-III'!$B$5:$B$205,SUMMARY!V$5) -> 2 | W6: =COUNTIFS('WTG PH-III'!$P$5:$P$205,"Done",'WTG PH-III'!$C$5:$C$205,W$4,'WTG PH-III'!$B$5:$B$205,SUMMARY!W$5) -> 36 | X6: =COUNTIFS('WTG PH-III'!$P$5:$P$205,"Done",'WTG PH-III'!$C$5:$C$205,X$4,'WTG PH-III'!$B$5:$B$205,SUMMARY!X$5) -> 27 | Y6: =COUNTIFS('WTG PH-III'!$P$5:$P$205,"Done",'WTG PH-III'!$C$5:$C$205,Y$4,'WTG PH-III'!$B$5:$B$205,SUMMARY!Y$5) -> 13 | Z6: =COUNTIFS('WTG PH-III'!$P$5:$P$205,"Done",'WTG PH-III'!$C$5:$C$205,Z$4,'WTG PH-III'!$B$5:$B$205,SUMMARY!Z$5) -> 60 | AA6: =SUM(S6:Z6) -> 194 | AB6: =AA6=D6 -> TRUE
A7: =ROW(A2) -> 2 | B7: Stone Column Drawing's Status | C7: 194 | D7: =COUNTIF('Stone Column Progress'!G6:G199,'Stone Column Progress'!G6) -> 194 | E7: =C7-D7 -> 0 | G7: 0 | H7: 0 | I7: 0 | O7: 194 | P7: =D7 -> 194 | Q7: =O7-P7 -> 0 | S7: =COUNTIFS('Stone Column Progress'!$C$6:$C$199,SUMMARY!S$4,'Stone Column Progress'!$F$6:$F$199,SUMMARY!S$5,'Stone Column Progress'!$G$6:$G$199,"Released") -> 5 | T7: =COUNTIFS('Stone Column Progress'!$C$6:$C$199,SUMMARY!T$4,'Stone Column Progress'!$F$6:$F$199,SUMMARY!T$5,'Stone Column Progress'!$G$6:$G$199,"Released") -> 12 | U7: =COUNTIFS('Stone Column Progress'!$C$6:$C$199,SUMMARY!U$4,'Stone Column Progress'!$F$6:$F$199,SUMMARY!U$5,'Stone Column Progress'!$G$6:$G$199,"Released") -> 39 | V7: =COUNTIFS('Stone Column Progress'!$C$6:$C$199,SUMMARY!V$4,'Stone Column Progress'!$F$6:$F$199,SUMMARY!V$5,'Stone Column Progress'!$G$6:$G$199,"Released") -> 2 | W7: =COUNTIFS('Stone Column Progress'!$C$6:$C$199,SUMMARY!W$4,'Stone Column Progress'!$F$6:$F$199,SUMMARY!W$5,'Stone Column Progress'!$G$6:$G$199,"Released") -> 36 | X7: =COUNTIFS('Stone Column Progress'!$C$6:$C$199,SUMMARY!X$4,'Stone Column Progress'!$F$6:$F$199,SUMMARY!X$5,'Stone Column Progress'!$G$6:$G$199,"Released") -> 27 | Y7: =COUNTIFS('Stone Column Progress'!$C$6:$C$199,SUMMARY!Y$4,'Stone Column Progress'!$F$6:$F$199,SUMMARY!Y$5,'Stone Column Progress'!$G$6:$G$199,"Released") -> 13 | Z7: =COUNTIFS('Stone Column Progress'!$C$6:$C$199,SUMMARY!Z$4,'Stone Column Progress'!$F$6:$F$199,SUMMARY!Z$5,'Stone Column Progress'!$G$6:$G$199,"Released") -> 60
A8: =ROW(A3) -> 3 | B8: Stone Column | C8: 194 | D8: ='WTG PH-III'!X4 -> 192 | E8: =C8-D8 -> 2 | G8: =COUNTIFS('WTG PH-III'!$U$5:$U$198,">="&T1,'WTG PH-III'!$U$5:$U$198,"<="&U1) -> 0 | H8: =COUNTIFS('WTG PH-III'!$X$5:$X$198,">="&T1,'WTG PH-III'!$X$5:$X$198,"<="&U1) -> 0 | I8: =G8-H8 -> 0 | K8: 5 | L8: 2 | M8: =K8-L8 -> 3 | O8: =COUNTIFS('WTG PH-III'!$U$5:$U$198,">=8-feb-25",'WTG PH-III'!$U$5:$U$198,"<="&U1) -> 194 | P8: =COUNTIFS('WTG PH-III'!$X$5:$X$198,">=08-May-24",'WTG PH-III'!$X$5:$X$198,"<="&U1) -> 192 | Q8: =O8-P8 -> 2 | S8: =COUNTIFS('WTG PH-III'!$X$5:$X$205,">0",'WTG PH-III'!$C$5:$C$205,S$4,'WTG PH-III'!$B$5:$B$205,SUMMARY!S$5) -> 5 | T8: =COUNTIFS('WTG PH-III'!$X$5:$X$205,">0",'WTG PH-III'!$C$5:$C$205,T$4,'WTG PH-III'!$B$5:$B$205,SUMMARY!T$5) -> 12 | U8: =COUNTIFS('WTG PH-III'!$X$5:$X$205,">0",'WTG PH-III'!$C$5:$C$205,U$4,'WTG PH-III'!$B$5:$B$205,SUMMARY!U$5) -> 39 | V8: =COUNTIFS('WTG PH-III'!$X$5:$X$205,">0",'WTG PH-III'!$C$5:$C$205,V$4,'WTG PH-III'!$B$5:$B$205,SUMMARY!V$5) -> 2 | W8: =COUNTIFS('WTG PH-III'!$X$5:$X$205,">0",'WTG PH-III'!$C$5:$C$205,W$4,'WTG PH-III'!$B$5:$B$205,SUMMARY!W$5) -> 36 | X8: =COUNTIFS('WTG PH-III'!$X$5:$X$205,">0",'WTG PH-III'!$C$5:$C$205,X$4,'WTG PH-III'!$B$5:$B$205,SUMMARY!X$5) -> 27 | Y8: =COUNTIFS('WTG PH-III'!$X$5:$X$205,">0",'WTG PH-III'!$C$5:$C$205,Y$4,'WTG PH-III'!$B$5:$B$205,SUMMARY!Y$5) -> 13 | Z8: =COUNTIFS('WTG PH-III'!$X$5:$X$205,">0",'WTG PH-III'!$C$5:$C$205,Z$4,'WTG PH-III'!$B$5:$B$205,SUMMARY!Z$5) -> 58 | AA8: =SUM(S8:Z8) -> 192 | AB8: =AA8=D8 -> TRUE
A9: =ROW(A4) -> 4 | B9: Plateload test | C9: 63 | D9: ='WTG PH-III'!AG4 -> 61 | E9: =C9-D9 -> 2 | G9: 0 | H9: =COUNTIFS('WTG PH-III'!$AG$5:$AG$198,">="&T1,'WTG PH-III'!$AG$5:$AG$198,"<="&U1) -> 1 | I9: =G9-H9 -> -1 | K9: 7 | M9: 7 | O9: 63 | P9: =COUNTIFS('WTG PH-III'!$AG$5:$AG$198,">=08-Feb-25",'WTG PH-III'!$AG$5:$AG$198,"<="&U1) -> 57 | Q9: =O9-P9 -> 6 | S9: =COUNTIFS('WTG PH-III'!$AG$5:$AG$205,">0",'WTG PH-III'!$C$5:$C$205,S$4,'WTG PH-III'!$B$5:$B$205,SUMMARY!S$5) -> 1 | T9: =COUNTIFS('WTG PH-III'!$AG$5:$AG$205,">0",'WTG PH-III'!$C$5:$C$205,T$4,'WTG PH-III'!$B$5:$B$205,SUMMARY!T$5) -> 5 | U9: =(COUNTIFS('WTG PH-III'!$AG$5:$AG$205,">0",'WTG PH-III'!$C$5:$C$205,U$4,'WTG PH-III'!$B$5:$B$205,SUMMARY!U$5))+1 -> 10 | V9: =COUNTIFS('WTG PH-III'!$AG$5:$AG$205,">0",'WTG PH-III'!$C$5:$C$205,V$4,'WTG PH-III'!$B$5:$B$205,SUMMARY!V$5) -> 0 | W9: =COUNTIFS('WTG PH-III'!$AG$5:$AG$205,">0",'WTG PH-III'!$C$5:$C$205,W$4,'WTG PH-III'!$B$5:$B$205,SUMMARY!W$5) -> 12 | X9: =COUNTIFS('WTG PH-III'!$AG$5:$AG$205,">0",'WTG PH-III'!$C$5:$C$205,X$4,'WTG PH-III'!$B$5:$B$205,SUMMARY!X$5)+2 -> 10 | Y9: =COUNTIFS('WTG PH-III'!$AG$5:$AG$205,">0",'WTG PH-III'!$C$5:$C$205,Y$4,'WTG PH-III'!$B$5:$B$205,SUMMARY!Y$5) -> 5 | Z9: =COUNTIFS('WTG PH-III'!$AG$5:$AG$205,">0",'WTG PH-III'!$C$5:$C$205,Z$4,'WTG PH-III'!$B$5:$B$205,SUMMARY!Z$5) -> 17 | AA9: =SUM(S9:Z9) -> 60 | AB9: =AA9=D9 -> FALSE
A10: =ROW(A5) -> 5 | B10: Excavation | C10: 194 | D10: ='WTG PH-III'!AM4 -> 187 | E10: =C10-D10 -> 7 | G10: =COUNTIFS('WTG PH-III'!$AJ$5:$AJ$198,">="&T1,'WTG PH-III'!$AJ$5:$AJ$198,"<="&U1) -> 0 | H10: =COUNTIFS('WTG PH-III'!$AM$5:$AM$198,">="&T1,'WTG PH-III'!$AM$5:$AM$198,"<="&U1) -> 2 | I10: =G10-H10 -> -2 | K10: =COUNTIFS('WTG PH-III'!AJ5:AJ18,">=01-Apr-24",'WTG PH-III'!AJ5:AJ18,"<=30-Apr-24") -> 0 | M10: =K10-L10 -> 0 | O10: =COUNTIFS('WTG PH-III'!$AJ$5:$AJ$198,">=8-feb-25",'WTG PH-III'!$AJ$5:$AJ$198,"<="&U1) -> 194 | P10: =COUNTIFS('WTG PH-III'!$AM$5:$AM$198,">=08-Feb-25",'WTG PH-III'!$AM$5:$AM$198,"<="&U1) -> 187 | Q10: =O10-P10 -> 7 | S10: =COUNTIFS('WTG PH-III'!$AM$5:$AM$205,">0",'WTG PH-III'!$C$5:$C$205,S$4,'WTG PH-III'!$B$5:$B$205,SUMMARY!S$5) -> 5 | T10: =COUNTIFS('WTG PH-III'!$AM$5:$AM$205,">0",'WTG PH-III'!$C$5:$C$205,T$4,'WTG PH-III'!$B$5:$B$205,SUMMARY!T$5) -> 11 | U10: =COUNTIFS('WTG PH-III'!$AM$5:$AM$205,">0",'WTG PH-III'!$C$5:$C$205,U$4,'WTG PH-III'!$B$5:$B$205,SUMMARY!U$5) -> 39 | V10: =COUNTIFS('WTG PH-III'!$AM$5:$AM$205,">0",'WTG PH-III'!$C$5:$C$205,V$4,'WTG PH-III'!$B$5:$B$205,SUMMARY!V$5) -> 2 | W10: =COUNTIFS('WTG PH-III'!$AM$5:$AM$205,">0",'WTG PH-III'!$C$5:$C$205,W$4,'WTG PH-III'!$B$5:$B$205,SUMMARY!W$5) -> 36 | X10: =COUNTIFS('WTG PH-III'!$AM$5:$AM$205,">0",'WTG PH-III'!$C$5:$C$205,X$4,'WTG PH-III'!$B$5:$B$205,SUMMARY!X$5) -> 27 | Y10: =COUNTIFS('WTG PH-III'!$AM$5:$AM$205,">0",'WTG PH-III'!$C$5:$C$205,Y$4,'WTG PH-III'!$B$5:$B$205,SUMMARY!Y$5) -> 12 | Z10: =COUNTIFS('WTG PH-III'!$AM$5:$AM$205,">0",'WTG PH-III'!$C$5:$C$205,Z$4,'WTG PH-III'!$B$5:$B$205,SUMMARY!Z$5) -> 55 | AA10: =SUM(S10:Z10) -> 187 | AB10: =AA10=D10 -> TRUE
A11: =ROW(A6) -> 6 | B11: PCC | C11: 194 | D11: ='WTG PH-III'!BA4 -> 180 | E11: =C11-D11 -> 14 | G11: =COUNTIFS('WTG PH-III'!$AX$5:$AX$198,">="&T1,'WTG PH-III'!$AX$5:$AX$198,"<="&U1) -> 0 | H11: =COUNTIFS('WTG PH-III'!$BA$5:$BA$198,">="&T1,'WTG PH-III'!$BA$5:$BA$198,"<="&U1) -> 2 | I11: =G11-H11 -> -2 | K11: =COUNTIFS('WTG PH-III'!AX5:AX18,">=01-Apr-24",'WTG PH-III'!AX5:AX18,"<=30-Apr-24") -> 0 | M11: =K11-L11 -> 0 | O11: =COUNTIFS('WTG PH-III'!$AX$5:$AX$198,">=8-feb-25",'WTG PH-III'!$AX$5:$AX$198,"<="&U1) -> 194 | P11: =COUNTIFS('WTG PH-III'!$BA$5:$BA$198,">=08-Feb-25",'WTG PH-III'!$BA$5:$BA$198,"<="&U1) -> 180 | Q11: =O11-P11 -> 14 | S11: =COUNTIFS('WTG PH-III'!$BA$5:$BA$205,">0",'WTG PH-III'!$C$5:$C$205,S$4,'WTG PH-III'!$B$5:$B$205,SUMMARY!S$5) -> 5 | T11: =COUNTIFS('WTG PH-III'!$BA$5:$BA$205,">0",'WTG PH-III'!$C$5:$C$205,T$4,'WTG PH-III'!$B$5:$B$205,SUMMARY!T$5) -> 11 | U11: =COUNTIFS('WTG PH-III'!$BA$5:$BA$205,">0",'WTG PH-III'!$C$5:$C$205,U$4,'WTG PH-III'!$B$5:$B$205,SUMMARY!U$5) -> 39 | V11: =COUNTIFS('WTG PH-III'!$BA$5:$BA$205,">0",'WTG PH-III'!$C$5:$C$205,V$4,'WTG PH-III'!$B$5:$B$205,SUMMARY!V$5) -> 2 | W11: =COUNTIFS('WTG PH-III'!$BA$5:$BA$205,">0",'WTG PH-III'!$C$5:$C$205,W$4,'WTG PH-III'!$B$5:$B$205,SUMMARY!W$5) -> 36 | X11: =COUNTIFS('WTG PH-III'!$BA$5:$BA$205,">0",'WTG PH-III'!$C$5:$C$205,X$4,'WTG PH-III'!$B$5:$B$205,SUMMARY!X$5) -> 27 | Y11: =COUNTIFS('WTG PH-III'!$BA$5:$BA$205,">0",'WTG PH-III'!$C$5:$C$205,Y$4,'WTG PH-III'!$B$5:$B$205,SUMMARY!Y$5) -> 12 | Z11: =COUNTIFS('WTG PH-III'!$BA$5:$BA$205,">0",'WTG PH-III'!$C$5:$C$205,Z$4,'WTG PH-III'!$B$5:$B$205,SUMMARY!Z$5) -> 48 | AA11: =SUM(S11:Z11) -> 180 | AB11: =AA11=D11 -> TRUE
A12: =ROW(A7) -> 7 | B12: Anchor Cage & Assembly | C12: 194 | D12: ='WTG PH-III'!BH4 -> 177 | E12: =C12-D12 -> 17 | G12: =COUNTIFS('WTG PH-III'!$BE$5:$BE$198,">="&T1,'WTG PH-III'!$BE$5:$BE$198,"<="&U1) -> 0 | H12: =COUNTIFS('WTG PH-III'!$BH$5:$BH$198,">="&T1,'WTG PH-III'!$BH$5:$BH$198,"<="&U1) -> 3 | I12: =G12-H12 -> -3 | K12: =COUNTIFS('WTG PH-III'!BE5:BE18,">=01-Apr-24",'WTG PH-III'!BE5:BE18,"<=30-Apr-24") -> 0 | M12: =K12-L12 -> 0 | O12: =COUNTIFS('WTG PH-III'!$BE$5:$BE$198,">=8-feb-25",'WTG PH-III'!$BE$5:$BE$198,"<="&U1) -> 194 | P12: =COUNTIFS('WTG PH-III'!$BH$5:$BH$198,">=08-Feb-25",'WTG PH-III'!$BH$5:$BH$198,"<="&U1) -> 177 | Q12: =O12-P12 -> 17 | S12: =COUNTIFS('WTG PH-III'!$BH$5:$BH$205,">0",'WTG PH-III'!$C$5:$C$205,S$4,'WTG PH-III'!$B$5:$B$205,SUMMARY!S$5) -> 5 | T12: =COUNTIFS('WTG PH-III'!$BH$5:$BH$205,">0",'WTG PH-III'!$C$5:$C$205,T$4,'WTG PH-III'!$B$5:$B$205,SUMMARY!T$5) -> 11 | U12: =COUNTIFS('WTG PH-III'!$BH$5:$BH$205,">0",'WTG PH-III'!$C$5:$C$205,U$4,'WTG PH-III'!$B$5:$B$205,SUMMARY!U$5) -> 39 | V12: =COUNTIFS('WTG PH-III'!$BH$5:$BH$205,">0",'WTG PH-III'!$C$5:$C$205,V$4,'WTG PH-III'!$B$5:$B$205,SUMMARY!V$5) -> 2 | W12: =COUNTIFS('WTG PH-III'!$BH$5:$BH$205,">0",'WTG PH-III'!$C$5:$C$205,W$4,'WTG PH-III'!$B$5:$B$205,SUMMARY!W$5) -> 36 | X12: =COUNTIFS('WTG PH-III'!$BH$5:$BH$205,">0",'WTG PH-III'!$C$5:$C$205,X$4,'WTG PH-III'!$B$5:$B$205,SUMMARY!X$5) -> 27 | Y12: =COUNTIFS('WTG PH-III'!$BH$5:$BH$205,">0",'WTG PH-III'!$C$5:$C$205,Y$4,'WTG PH-III'!$B$5:$B$205,SUMMARY!Y$5) -> 12 | Z12: =COUNTIFS('WTG PH-III'!$BH$5:$BH$205,">0",'WTG PH-III'!$C$5:$C$205,Z$4,'WTG PH-III'!$B$5:$B$205,SUMMARY!Z$5) -> 45 | AA12: =SUM(S12:Z12) -> 177 | AB12: =AA12=D12 -> TRUE
A13: =ROW(A8) -> 8 | B13: Steel Binding works | C13: 194 | D13: ='WTG PH-III'!BO4 -> 173 | E13: =C13-D13 -> 21 | G13: =COUNTIFS('WTG PH-III'!$BL$5:$BL$198,">="&T1,'WTG PH-III'!$BL$5:$BL$198,"<="&U1) -> 0 | H13: =COUNTIFS('WTG PH-III'!BO5:BO198,">="&T1,'WTG PH-III'!BO5:BO198,"<="&U1) -> 3 | I13: =G13-H13 -> -3 | K13: =COUNTIFS('WTG PH-III'!BL5:BL18,">=01-Apr-24",'WTG PH-III'!BL5:BL18,"<=30-Apr-24") -> 0 | M13: =K13-L13 -> 0 | O13: =COUNTIFS('WTG PH-III'!$BL$5:$BL$198,">=8-feb-25",'WTG PH-III'!$BL$5:$BL$198,"<="&U1) -> 194 | P13: =COUNTIFS('WTG PH-III'!$BO$5:$BO$198,">=08-Feb-25",'WTG PH-III'!$BO$5:$BO$198,"<="&U1) -> 173 | Q13: =O13-P13 -> 21 | S13: =COUNTIFS('WTG PH-III'!$BO$5:$BO$205,">0",'WTG PH-III'!$C$5:$C$205,S$4,'WTG PH-III'!$B$5:$B$205,SUMMARY!S$5) -> 5 | T13: =COUNTIFS('WTG PH-III'!$BO$5:$BO$205,">0",'WTG PH-III'!$C$5:$C$205,T$4,'WTG PH-III'!$B$5:$B$205,SUMMARY!T$5) -> 10 | U13: =COUNTIFS('WTG PH-III'!$BO$5:$BO$205,">0",'WTG PH-III'!$C$5:$C$205,U$4,'WTG PH-III'!$B$5:$B$205,SUMMARY!U$5) -> 39 | V13: =COUNTIFS('WTG PH-III'!$BO$5:$BO$205,">0",'WTG PH-III'!$C$5:$C$205,V$4,'WTG PH-III'!$B$5:$B$205,SUMMARY!V$5) -> 2 | W13: =COUNTIFS('WTG PH-III'!$BO$5:$BO$205,">0",'WTG PH-III'!$C$5:$C$205,W$4,'WTG PH-III'!$B$5:$B$205,SUMMARY!W$5) -> 36 | X13: =COUNTIFS('WTG PH-III'!$BO$5:$BO$205,">0",'WTG PH-III'!$C$5:$C$205,X$4,'WTG PH-III'!$B$5:$B$205,SUMMARY!X$5) -> 27 | Y13: =COUNTIFS('WTG PH-III'!$BO$5:$BO$205,">0",'WTG PH-III'!$C$5:$C$205,Y$4,'WTG PH-III'!$B$5:$B$205,SUMMARY!Y$5) -> 12 | Z13: =COUNTIFS('WTG PH-III'!$BO$5:$BO$205,">0",'WTG PH-III'!$C$5:$C$205,Z$4,'WTG PH-III'!$B$5:$B$205,SUMMARY!Z$5) -> 42 | AA13: =SUM(S13:Z13) -> 173 | AB13: =AA13=D13 -> TRUE
A14: =ROW(A9) -> 9 | B14: Raft Casting | C14: 194 | D14: ='WTG PH-III'!BV4 -> 172 | E14: =C14-D14 -> 22 | G14: =COUNTIFS('WTG PH-III'!$BS$5:$BS$198,">="&T1,'WTG PH-III'!$BS$5:$BS$198,"<="&U1) -> 0 | H14: =COUNTIFS('WTG PH-III'!$BV$5:$BV$198,">="&T1,'WTG PH-III'!$BV$5:$BV$198,"<="&U1) -> 6 | I14: =G14-H14 -> -6 | K14: =COUNTIFS('WTG PH-III'!BS5:BS18,">=01-Apr-24",'WTG PH-III'!BS5:BS18,"<=30-Apr-24") -> 0 | M14: =K14-L14 -> 0 | O14: =COUNTIFS('WTG PH-III'!$BS$5:$BS$198,">=8-feb-25",'WTG PH-III'!$BS$5:$BS$198,"<="&U1) -> 194 | P14: =COUNTIFS('WTG PH-III'!$BV$5:$BV$198,">=08-Feb-25",'WTG PH-III'!$BV$5:$BV$198,"<="&U1) -> 172 | Q14: =O14-P14 -> 22 | S14: =COUNTIFS('WTG PH-III'!$BV$5:$BV$205,">0",'WTG PH-III'!$C$5:$C$205,S$4,'WTG PH-III'!$B$5:$B$205,SUMMARY!S$5) -> 5 | T14: =COUNTIFS('WTG PH-III'!$BV$5:$BV$205,">0",'WTG PH-III'!$C$5:$C$205,T$4,'WTG PH-III'!$B$5:$B$205,SUMMARY!T$5) -> 10 | U14: =COUNTIFS('WTG PH-III'!$BV$5:$BV$205,">0",'WTG PH-III'!$C$5:$C$205,U$4,'WTG PH-III'!$B$5:$B$205,SUMMARY!U$5) -> 39 | V14: =COUNTIFS('WTG PH-III'!$BV$5:$BV$205,">0",'WTG PH-III'!$C$5:$C$205,V$4,'WTG PH-III'!$B$5:$B$205,SUMMARY!V$5) -> 2 | W14: =COUNTIFS('WTG PH-III'!$BV$5:$BV$205,">0",'WTG PH-III'!$C$5:$C$205,W$4,'WTG PH-III'!$B$5:$B$205,SUMMARY!W$5) -> 36 | X14: =COUNTIFS('WTG PH-III'!$BV$5:$BV$205,">0",'WTG PH-III'!$C$5:$C$205,X$4,'WTG PH-III'!$B$5:$B$205,SUMMARY!X$5) -> 27 | Y14: =COUNTIFS('WTG PH-III'!$BV$5:$BV$205,">0",'WTG PH-III'!$C$5:$C$205,Y$4,'WTG PH-III'!$B$5:$B$205,SUMMARY!Y$5) -> 12 | Z14: =COUNTIFS('WTG PH-III'!$BV$5:$BV$205,">0",'WTG PH-III'!$C$5:$C$205,Z$4,'WTG PH-III'!$B$5:$B$205,SUMMARY!Z$5) -> 41 | AA14: =SUM(S14:Z14) -> 172 | AB14: =AA14=D14 -> TRUE
A15: =ROW(A10) -> 10 | B15: Backfilling | C15: 194 | D15: ='WTG PH-III'!CD4 -> 76 | E15: =C15-D15 -> 118 | G15: =COUNTIFS('WTG PH-III'!$CA$5:$CA$198,">="&T1,'WTG PH-III'!$CA$5:$CA$198,"<="&U1) -> 0 | H15: =COUNTIFS('WTG PH-III'!$CD$5:$CD$198,">="&T1,'WTG PH-III'!$CD$5:$CD$198,"<="&U1) -> 1 | I15: =G15-H15 -> -1 | K15: =COUNTIFS('WTG PH-III'!CA5:CA18,">=01-Apr-24",'WTG PH-III'!CA5:CA18,"<=30-Apr-24") -> 0 | M15: =K15-L15 -> 0 | O15: =COUNTIFS('WTG PH-III'!$CA$5:$CA$198,">=8-feb-25",'WTG PH-III'!$CA$5:$CA$198,"<="&U1) -> 194 | P15: =COUNTIFS('WTG PH-III'!$CD$5:$CD$198,">=08-Feb-25",'WTG PH-III'!$CD$5:$CD$198,"<="&U1) -> 76 | Q15: =O15-P15 -> 118 | S15: =COUNTIFS('WTG PH-III'!$CD$5:$CD$205,">0",'WTG PH-III'!$C$5:$C$205,S$4,'WTG PH-III'!$B$5:$B$205,SUMMARY!S$5) -> 5 | T15: =COUNTIFS('WTG PH-III'!$CD$5:$CD$205,">0",'WTG PH-III'!$C$5:$C$205,T$4,'WTG PH-III'!$B$5:$B$205,SUMMARY!T$5) -> 6 | U15: =COUNTIFS('WTG PH-III'!$CD$5:$CD$205,">0",'WTG PH-III'!$C$5:$C$205,U$4,'WTG PH-III'!$B$5:$B$205,SUMMARY!U$5) -> 26 | V15: =COUNTIFS('WTG PH-III'!$CD$5:$CD$205,">0",'WTG PH-III'!$C$5:$C$205,V$4,'WTG PH-III'!$B$5:$B$205,SUMMARY!V$5) -> 0 | W15: =COUNTIFS('WTG PH-III'!$CD$5:$CD$205,">0",'WTG PH-III'!$C$5:$C$205,W$4,'WTG PH-III'!$B$5:$B$205,SUMMARY!W$5) -> 29 | X15: =COUNTIFS('WTG PH-III'!$CD$5:$CD$205,">0",'WTG PH-III'!$C$5:$C$205,X$4,'WTG PH-III'!$B$5:$B$205,SUMMARY!X$5) -> 8 | Y15: =COUNTIFS('WTG PH-III'!$CD$5:$CD$205,">0",'WTG PH-III'!$C$5:$C$205,Y$4,'WTG PH-III'!$B$5:$B$205,SUMMARY!Y$5) -> 2 | Z15: =COUNTIFS('WTG PH-III'!$CD$5:$CD$205,">0",'WTG PH-III'!$C$5:$C$205,Z$4,'WTG PH-III'!$B$5:$B$205,SUMMARY!Z$5) -> 0 | AA15: =COUNTIFS('WTG PH-III'!$CD$5:$CD$201,">0",'WTG PH-III'!$C$5:$C$205,AA$4,'WTG PH-III'!$B$5:$B$205,SUMMARY!AA$5) -> #VALUE! | AB15: =COUNTIFS('WTG PH-III'!$CD$5:$CD$201,">0",'WTG PH-III'!$C$5:$C$205,AB$4,'WTG PH-III'!$B$5:$B$205,SUMMARY!AB$5) -> #VALUE!
A16: =ROW(A11) -> 11 | B16: Grouting | C16: 194 | D16: ='WTG PH-III'!CK4 -> 163 | E16: =C16-D16 -> 31 | G16: =COUNTIFS('WTG PH-III'!$CH$5:$CH$198,">="&T1,'WTG PH-III'!$CH$5:$CH$198,"<="&U1) -> 0 | H16: =COUNTIFS('WTG PH-III'!$CK$5:$CK$198,">="&T1,'WTG PH-III'!$CK$5:$CK$198,"<="&U1) -> 7 | I16: =G16-H16 -> -7 | K16: =COUNTIFS('WTG PH-III'!CH5:CH18,">=01-Apr-24",'WTG PH-III'!CH5:CH18,"<=30-Apr-24") -> 0 | M16: =K16-L16 -> 0 | O16: =COUNTIFS('WTG PH-III'!$CH$5:$CH$198,">=8-feb-25",'WTG PH-III'!$CH$5:$CH$198,"<="&U1) -> 194 | P16: =COUNTIFS('WTG PH-III'!$CK$5:$CK$198,">=08-Feb-25",'WTG PH-III'!$CK$5:$CK$198,"<="&U1) -> 163 | Q16: =O16-P16 -> 31 | S16: =COUNTIFS('WTG PH-III'!$CK$5:$CK$205,">0",'WTG PH-III'!$C$5:$C$205,S$4,'WTG PH-III'!$B$5:$B$205,SUMMARY!S$5) -> 5 | T16: =COUNTIFS('WTG PH-III'!$CK$5:$CK$205,">0",'WTG PH-III'!$C$5:$C$205,T$4,'WTG PH-III'!$B$5:$B$205,SUMMARY!T$5) -> 10 | U16: =COUNTIFS('WTG PH-III'!$CK$5:$CK$205,">0",'WTG PH-III'!$C$5:$C$205,U$4,'WTG PH-III'!$B$5:$B$205,SUMMARY!U$5) -> 39 | V16: =COUNTIFS('WTG PH-III'!$CK$5:$CK$205,">0",'WTG PH-III'!$C$5:$C$205,V$4,'WTG PH-III'!$B$5:$B$205,SUMMARY!V$5) -> 2 | W16: =COUNTIFS('WTG PH-III'!$CK$5:$CK$205,">0",'WTG PH-III'!$C$5:$C$205,W$4,'WTG PH-III'!$B$5:$B$205,SUMMARY!W$5) -> 36 | X16: =COUNTIFS('WTG PH-III'!$CK$5:$CK$205,">0",'WTG PH-III'!$C$5:$C$205,X$4,'WTG PH-III'!$B$5:$B$205,SUMMARY!X$5) -> 27 | Y16: =COUNTIFS('WTG PH-III'!$CK$5:$CK$205,">0",'WTG PH-III'!$C$5:$C$205,Y$4,'WTG PH-III'!$B$5:$B$205,SUMMARY!Y$5) -> 11 | Z16: =COUNTIFS('WTG PH-III'!$CK$5:$CK$205,">0",'WTG PH-III'!$C$5:$C$205,Z$4,'WTG PH-III'!$B$5:$B$205,SUMMARY!Z$5) -> 33 | AA16: =SUM(S16:Z16) -> 163 | AB16: =AA16=D16 -> TRUE
A17: =ROW(A12) -> 12 | B17: USS & Transformer Foundation | C17: 194 | D17: ='WTG PH-III'!CT4 -> 148 | E17: =C17-D17 -> 46 | G17: =COUNTIFS('WTG PH-III'!$CQ$5:$CQ$198,">="&T1,'WTG PH-III'!$CQ$5:$CQ$198,"<="&U1) -> 0 | H17: =COUNTIFS('WTG PH-III'!$CT$5:$CT$198,">="&T1,'WTG PH-III'!$CT$5:$CT$198,"<="&U1) -> 7 | I17: =G17-H17 -> -7 | K17: =COUNTIFS('WTG PH-III'!CQ5:CQ18,">=01-Apr-24",'WTG PH-III'!CQ5:CQ18,"<=30-Apr-24") -> 0 | M17: =K17-L17 -> 0 | O17: =COUNTIFS('WTG PH-III'!$CQ$5:$CQ$198,">=8-feb-25",'WTG PH-III'!$CQ$5:$CQ$198,"<="&U1) -> 194 | P17: =COUNTIFS('WTG PH-III'!$CT$5:$CT$198,">=08-Feb-25",'WTG PH-III'!$CT$5:$CT$198,"<="&U1) -> 148 | Q17: =O17-P17 -> 46 | S17: =COUNTIFS('WTG PH-III'!$CT$5:$CT$205,">0",'WTG PH-III'!$C$5:$C$205,S$4,'WTG PH-III'!$B$5:$B$205,SUMMARY!S$5) -> 5 | T17: =COUNTIFS('WTG PH-III'!$CT$5:$CT$205,">0",'WTG PH-III'!$C$5:$C$205,T$4,'WTG PH-III'!$B$5:$B$205,SUMMARY!T$5) -> 10 | U17: =COUNTIFS('WTG PH-III'!$CT$5:$CT$205,">0",'WTG PH-III'!$C$5:$C$205,U$4,'WTG PH-III'!$B$5:$B$205,SUMMARY!U$5) -> 39 | V17: =COUNTIFS('WTG PH-III'!$CT$5:$CT$205,">0",'WTG PH-III'!$C$5:$C$205,V$4,'WTG PH-III'!$B$5:$B$205,SUMMARY!V$5) -> 2 | W17: =COUNTIFS('WTG PH-III'!$CT$5:$CT$205,">0",'WTG PH-III'!$C$5:$C$205,W$4,'WTG PH-III'!$B$5:$B$205,SUMMARY!W$5) -> 36 | X17: =COUNTIFS('WTG PH-III'!$CT$5:$CT$205,">0",'WTG PH-III'!$C$5:$C$205,X$4,'WTG PH-III'!$B$5:$B$205,SUMMARY!X$5) -> 27 | Y17: =COUNTIFS('WTG PH-III'!$CT$5:$CT$205,">0",'WTG PH-III'!$C$5:$C$205,Y$4,'WTG PH-III'!$B$5:$B$205,SUMMARY!Y$5) -> 12 | Z17: =COUNTIFS('WTG PH-III'!$CT$5:$CT$205,">0",'WTG PH-III'!$C$5:$C$205,Z$4,'WTG PH-III'!$B$5:$B$205,SUMMARY!Z$5) -> 17 | AA17: =SUM(S17:Z17) -> 148 | AB17: =AA17=D17 -> TRUE
A18: =ROW(A13) -> 13 | B18: WTG Connecting Road | C18: 194 | D18: ='WTG PH-III'!DA4 -> 193 | E18: =C18-D18 -> 1 | G18: =COUNTIFS('WTG PH-III'!$CX$5:$CX$199,">="&T1,'WTG PH-III'!$CX$5:$CX$199,"<="&U1) -> 0 | H18: =COUNTIFS('WTG PH-III'!$DA$5:$DA$199,">="&T1,'WTG PH-III'!$DA$5:$DA$199,"<="&U1) -> 0 | I18: =G18-H18 -> 0 | O18: =COUNTIFS('WTG PH-III'!$CX$5:$CX$198,">=8-feb-25",'WTG PH-III'!$CX$5:$CX$198,"<="&U1) -> 194 | P18: =COUNTIFS('WTG PH-III'!$DA$5:$DA$198,">=08-Feb-25",'WTG PH-III'!$DA$5:$DA$198,"<="&U1)+COUNTIFS('WTG PH-III'!DA5:DA198,"Done") -> 193 | Q18: =O18-P18 -> 1 | S18: =COUNTIFS('WTG PH-III'!$DA$5:$DA$205,">0",'WTG PH-III'!$C$5:$C$205,S$4,'WTG PH-III'!$B$5:$B$205,SUMMARY!S$5) -> 5 | T18: =COUNTIFS('WTG PH-III'!$DA$5:$DA$205,">0",'WTG PH-III'!$C$5:$C$205,T$4,'WTG PH-III'!$B$5:$B$205,SUMMARY!T$5) -> 10 | U18: =COUNTIFS('WTG PH-III'!$DA$5:$DA$205,">0",'WTG PH-III'!$C$5:$C$205,U$4,'WTG PH-III'!$B$5:$B$205,SUMMARY!U$5)+COUNTIFS('WTG PH-III'!$DA$5:$DA$205,"Done",'WTG PH-III'!$C$5:$C$205,U$4,'WTG PH-III'!$B$5:$B$205,SUMMARY!U$5) -> 39 | V18: =COUNTIFS('WTG PH-III'!$DA$5:$DA$205,">0",'WTG PH-III'!$C$5:$C$205,V$4,'WTG PH-III'!$B$5:$B$205,SUMMARY!V$5) -> 1 | W18: =COUNTIFS('WTG PH-III'!$DA$5:$DA$205,">0",'WTG PH-III'!$C$5:$C$205,W$4,'WTG PH-III'!$B$5:$B$205,SUMMARY!W$5) -> 32 | X18: =COUNTIFS('WTG PH-III'!$DA$5:$DA$205,">0",'WTG PH-III'!$C$5:$C$205,X$4,'WTG PH-III'!$B$5:$B$205,SUMMARY!X$5) -> 17 | Y18: =COUNTIFS('WTG PH-III'!$DA$5:$DA$205,">0",'WTG PH-III'!$C$5:$C$205,Y$4,'WTG PH-III'!$B$5:$B$205,SUMMARY!Y$5) -> 5 | Z18: =COUNTIFS('WTG PH-III'!$DA$5:$DA$205,">0",'WTG PH-III'!$C$5:$C$205,Z$4,'WTG PH-III'!$B$5:$B$205,SUMMARY!Z$5) -> 20 | AA18: =SUM(S18:Z18) -> 129 | AB18: =AA18=D18 -> FALSE
A19: =ROW(A14) -> 14 | B19: Crane Pad | C19: 194 | D19: ='WTG PH-III'!DP4 -> 153 | E19: =C19-D19 -> 41 | G19: =COUNTIFS('WTG PH-III'!$DM$5:$DM$199,">="&T1,'WTG PH-III'!$DM$5:$DM$199,"<="&U1) -> 0 | H19: =COUNTIFS('WTG PH-III'!$DP$5:$DP$199,">="&T1,'WTG PH-III'!$DP$5:$DP$199,"<="&U1) -> 8 | I19: =G19-H19 -> -8 | O19: =COUNTIFS('WTG PH-III'!$DM$5:$DM$198,">=8-feb-25",'WTG PH-III'!$DM$5:$DM$198,"<="&U1) -> 194 | P19: =COUNTIFS('WTG PH-III'!$DP$5:$DP$198,">=08-Feb-25",'WTG PH-III'!$DP$5:$DP$198,"<="&U1) -> 153 | Q19: =O19-P19 -> 41 | S19: =COUNTIFS('WTG PH-III'!$DP$5:$DP$205,">0",'WTG PH-III'!$C$5:$C$205,S$4,'WTG PH-III'!$B$5:$B$205,SUMMARY!S$5) -> 5 | T19: =COUNTIFS('WTG PH-III'!$DP$5:$DP$205,">0",'WTG PH-III'!$C$5:$C$205,T$4,'WTG PH-III'!$B$5:$B$205,SUMMARY!T$5) -> 11 | U19: =COUNTIFS('WTG PH-III'!$DP$5:$DP$205,">0",'WTG PH-III'!$C$5:$C$205,U$4,'WTG PH-III'!$B$5:$B$205,SUMMARY!U$5) -> 39 | V19: =COUNTIFS('WTG PH-III'!$DP$5:$DP$205,">0",'WTG PH-III'!$C$5:$C$205,V$4,'WTG PH-III'!$B$5:$B$205,SUMMARY!V$5) -> 2 | W19: =COUNTIFS('WTG PH-III'!$DP$5:$DP$205,">0",'WTG PH-III'!$C$5:$C$205,W$4,'WTG PH-III'!$B$5:$B$205,SUMMARY!W$5) -> 36 | X19: =COUNTIFS('WTG PH-III'!$DP$5:$DP$205,">0",'WTG PH-III'!$C$5:$C$205,X$4,'WTG PH-III'!$B$5:$B$205,SUMMARY!X$5) -> 27 | Y19: =COUNTIFS('WTG PH-III'!$DP$5:$DP$205,">0",'WTG PH-III'!$C$5:$C$205,Y$4,'WTG PH-III'!$B$5:$B$205,SUMMARY!Y$5) -> 11 | Z19: =COUNTIFS('WTG PH-III'!$DP$5:$DP$205,">0",'WTG PH-III'!$C$5:$C$205,Z$4,'WTG PH-III'!$B$5:$B$205,SUMMARY!Z$5) -> 22 | AA19: =SUM(S19:Z19) -> 153 | AB19: =AA19=D19 -> TRUE
A20: =ROW(A15) -> 15 | B20: WTG Erection | C20: 194 | D20: ='WTG PH-III'!DW4 -> 119 | E20: =C20-D20 -> 75 | G20: =COUNTIFS('WTG PH-III'!$DT$5:$DT$199,">="&T1,'WTG PH-III'!$DT$5:$DT$199,"<="&U1) -> 10 | H20: =COUNTIFS('WTG PH-III'!$DW$5:$DW$198,">="&T1,'WTG PH-III'!$DW$5:$DW$198,"<="&U1) -> 4 | I20: =G20-H20 -> 6 | M20: =K20-L20 -> 0 | O20: =COUNTIFS('WTG PH-III'!$DT$5:$DT$198,">=8-feb-25",'WTG PH-III'!$DT$5:$DT$198,"<="&U1) -> 194 | P20: =COUNTIFS('WTG PH-III'!$DW$5:$DW$198,">=08-Feb-25",'WTG PH-III'!$DW$5:$DW$198,"<="&U1) -> 119 | Q20: =O20-P20 -> 75 | S20: =COUNTIFS('WTG PH-III'!$DW$5:$DW$205,">0",'WTG PH-III'!$C$5:$C$205,S$4,'WTG PH-III'!$B$5:$B$205,SUMMARY!S$5) -> 5 | T20: =COUNTIFS('WTG PH-III'!$DW$5:$DW$205,">0",'WTG PH-III'!$C$5:$C$205,T$4,'WTG PH-III'!$B$5:$B$205,SUMMARY!T$5) -> 9 | U20: =COUNTIFS('WTG PH-III'!$DW$5:$DW$205,">0",'WTG PH-III'!$C$5:$C$205,U$4,'WTG PH-III'!$B$5:$B$205,SUMMARY!U$5) -> 39 | V20: =COUNTIFS('WTG PH-III'!$DW$5:$DW$205,">0",'WTG PH-III'!$C$5:$C$205,V$4,'WTG PH-III'!$B$5:$B$205,SUMMARY!V$5) -> 2 | W20: =COUNTIFS('WTG PH-III'!$DW$5:$DW$205,">0",'WTG PH-III'!$C$5:$C$205,W$4,'WTG PH-III'!$B$5:$B$205,SUMMARY!W$5) -> 36 | X20: =COUNTIFS('WTG PH-III'!$DW$5:$DW$205,">0",'WTG PH-III'!$C$5:$C$205,X$4,'WTG PH-III'!$B$5:$B$205,SUMMARY!X$5) -> 23 | Y20: =COUNTIFS('WTG PH-III'!$DW$5:$DW$205,">0",'WTG PH-III'!$C$5:$C$205,Y$4,'WTG PH-III'!$B$5:$B$205,SUMMARY!Y$5) -> 5 | Z20: =COUNTIFS('WTG PH-III'!$DW$5:$DW$205,">0",'WTG PH-III'!$C$5:$C$205,Z$4,'WTG PH-III'!$B$5:$B$205,SUMMARY!Z$5) -> 0 | AA20: =SUM(S20:Z20) -> 119 | AB20: =AA20=D20 -> TRUE
A21: =ROW(A16) -> 16 | B21: MCC | C21: 194 | D21: ='WTG PH-III'!EK4 -> 113 | E21: =C21-D21 -> 81 | G21: =COUNTIFS('WTG PH-III'!$EH$5:$EH$198,">="&T1,'WTG PH-III'!$EH$5:$EH$198,"<="&U1) -> 9 | H21: =COUNTIFS('WTG PH-III'!$EK$5:$EK$198,">="&T1,'WTG PH-III'!$EK$5:$EK$198,"<="&U1) -> 7 | I21: =G21-H21 -> 2 | M21: =K21-L21 -> 0 | O21: =COUNTIFS('WTG PH-III'!$EH$5:$EH$198,">=8-feb-25",'WTG PH-III'!$EH$5:$EH$198,"<="&U1) -> 184 | P21: =COUNTIFS('WTG PH-III'!$EK$5:$EK$198,">=08-Feb-25",'WTG PH-III'!$EK$5:$EK$198,"<="&U1) -> 113 | Q21: =O21-P21 -> 71 | S21: =COUNTIFS('WTG PH-III'!$EK$5:$EK$205,">0",'WTG PH-III'!$C$5:$C$205,S$4,'WTG PH-III'!$B$5:$B$205,SUMMARY!S$5) -> 5 | T21: =COUNTIFS('WTG PH-III'!$EK$5:$EK$205,">0",'WTG PH-III'!$C$5:$C$205,T$4,'WTG PH-III'!$B$5:$B$205,SUMMARY!T$5) -> 8 | U21: =COUNTIFS('WTG PH-III'!$EK$5:$EK$205,">0",'WTG PH-III'!$C$5:$C$205,U$4,'WTG PH-III'!$B$5:$B$205,SUMMARY!U$5) -> 39 | V21: =COUNTIFS('WTG PH-III'!$EK$5:$EK$205,">0",'WTG PH-III'!$C$5:$C$205,V$4,'WTG PH-III'!$B$5:$B$205,SUMMARY!V$5) -> 2 | W21: =COUNTIFS('WTG PH-III'!$EK$5:$EK$205,">0",'WTG PH-III'!$C$5:$C$205,W$4,'WTG PH-III'!$B$5:$B$205,SUMMARY!W$5) -> 36 | X21: =COUNTIFS('WTG PH-III'!$EK$5:$EK$205,">0",'WTG PH-III'!$C$5:$C$205,X$4,'WTG PH-III'!$B$5:$B$205,SUMMARY!X$5) -> 20 | Y21: =COUNTIFS('WTG PH-III'!$EK$5:$EK$205,">0",'WTG PH-III'!$C$5:$C$205,Y$4,'WTG PH-III'!$B$5:$B$205,SUMMARY!Y$5) -> 3 | Z21: =COUNTIFS('WTG PH-III'!$EK$5:$EK$205,">0",'WTG PH-III'!$C$5:$C$205,Z$4,'WTG PH-III'!$B$5:$B$205,SUMMARY!Z$5) -> 0 | AA21: =SUM(S21:Z21) -> 113 | AB21: =AA21=D21 -> TRUE
A22: =ROW(A17) -> 17 | B22: Pre-Comm | C22: 194 | D22: ='WTG PH-III'!ER4 -> 108 | E22: =C22-D22 -> 86 | G22: =COUNTIFS('WTG PH-III'!$EO$5:$EO$198,">="&T1,'WTG PH-III'!$EO$5:$EO$198,"<="&U1) -> 7 | H22: =COUNTIFS('WTG PH-III'!$ER$5:$ER$198,">="&T1,'WTG PH-III'!$ER$5:$ER$198,"<="&U1) -> 5 | I22: =G22-H22 -> 2 | M22: =K22-L22 -> 0 | O22: =COUNTIFS('WTG PH-III'!$EO$5:$EO$198,">=8-feb-25",'WTG PH-III'!$EO$5:$EO$198,"<="&U1) -> 181 | P22: =COUNTIFS('WTG PH-III'!$ER$5:$ER$198,">=08-Feb-25",'WTG PH-III'!$ER$5:$ER$198,"<="&U1) -> 108 | Q22: =O22-P22 -> 73 | S22: =COUNTIFS('WTG PH-III'!$ER$5:$ER$205,">0",'WTG PH-III'!$C$5:$C$205,S$4,'WTG PH-III'!$B$5:$B$205,SUMMARY!S$5) -> 5 | T22: =COUNTIFS('WTG PH-III'!$ER$5:$ER$205,">0",'WTG PH-III'!$C$5:$C$205,T$4,'WTG PH-III'!$B$5:$B$205,SUMMARY!T$5) -> 7 | U22: =COUNTIFS('WTG PH-III'!$ER$5:$ER$205,">0",'WTG PH-III'!$C$5:$C$205,U$4,'WTG PH-III'!$B$5:$B$205,SUMMARY!U$5) -> 39 | V22: =COUNTIFS('WTG PH-III'!$ER$5:$ER$205,">0",'WTG PH-III'!$C$5:$C$205,V$4,'WTG PH-III'!$B$5:$B$205,SUMMARY!V$5) -> 2 | W22: =COUNTIFS('WTG PH-III'!$ER$5:$ER$205,">0",'WTG PH-III'!$C$5:$C$205,W$4,'WTG PH-III'!$B$5:$B$205,SUMMARY!W$5) -> 36 | X22: =COUNTIFS('WTG PH-III'!$ER$5:$ER$205,">0",'WTG PH-III'!$C$5:$C$205,X$4,'WTG PH-III'!$B$5:$B$205,SUMMARY!X$5) -> 17 | Y22: =COUNTIFS('WTG PH-III'!$ER$5:$ER$205,">0",'WTG PH-III'!$C$5:$C$205,Y$4,'WTG PH-III'!$B$5:$B$205,SUMMARY!Y$5) -> 2 | Z22: =COUNTIFS('WTG PH-III'!$ER$5:$ER$205,">0",'WTG PH-III'!$C$5:$C$205,Z$4,'WTG PH-III'!$B$5:$B$205,SUMMARY!Z$5) -> 0 | AA22: =SUM(S22:Z22) -> 108 | AB22: =AA22=D22 -> TRUE
A23: =ROW(A18) -> 18 | B23: WTG Commissioining | C23: 194 | D23: ='WTG PH-III'!GA4 -> 82 | E23: =C23-D23 -> 112 | G23: =COUNTIFS('WTG PH-III'!$FX$5:$FX$198,">="&T1,'WTG PH-III'!$FX$5:$FX$198,"<="&U1) -> 1 | H23: =COUNTIFS('WTG PH-III'!$GA$5:$GA$198,">="&T1,'WTG PH-III'!$GA$5:$GA$198,"<="&U1) -> 4 | I23: =G23-H23 -> -3 | O23: =COUNTIFS('WTG PH-III'!$FX$5:$FX$198,">=8-feb-25",'WTG PH-III'!$FX$5:$FX$198,"<="&U1) -> 172 | P23: =COUNTIFS('WTG PH-III'!$GA$5:$GA$198,">=08-Feb-25",'WTG PH-III'!$GA$5:$GA$198,"<="&U1) -> 82 | Q23: =O23-P23 -> 90 | S23: =COUNTIFS('WTG PH-III'!$GA$5:$GA$205,">0",'WTG PH-III'!$C$5:$C$205,S$4,'WTG PH-III'!$B$5:$B$205,SUMMARY!S$5) -> 5 | T23: =COUNTIFS('WTG PH-III'!$GA$5:$GA$205,">0",'WTG PH-III'!$C$5:$C$205,T$4,'WTG PH-III'!$B$5:$B$205,SUMMARY!T$5) -> 0 | U23: =COUNTIFS('WTG PH-III'!$GA$5:$GA$205,">0",'WTG PH-III'!$C$5:$C$205,U$4,'WTG PH-III'!$B$5:$B$205,SUMMARY!U$5) -> 39 | V23: =COUNTIFS('WTG PH-III'!$GA$5:$GA$205,">0",'WTG PH-III'!$C$5:$C$205,V$4,'WTG PH-III'!$B$5:$B$205,SUMMARY!V$5) -> 2 | W23: =COUNTIFS('WTG PH-III'!$GA$5:$GA$205,">0",'WTG PH-III'!$C$5:$C$205,W$4,'WTG PH-III'!$B$5:$B$205,SUMMARY!W$5) -> 36 | X23: =COUNTIFS('WTG PH-III'!$GA$5:$GA$205,">0",'WTG PH-III'!$C$5:$C$205,X$4,'WTG PH-III'!$B$5:$B$205,SUMMARY!X$5) -> 0 | Y23: =COUNTIFS('WTG PH-III'!$GA$5:$GA$205,">0",'WTG PH-III'!$C$5:$C$205,Y$4,'WTG PH-III'!$B$5:$B$205,SUMMARY!Y$5) -> 0 | Z23: =COUNTIFS('WTG PH-III'!$GA$5:$GA$205,">0",'WTG PH-III'!$C$5:$C$205,Z$4,'WTG PH-III'!$B$5:$B$205,SUMMARY!Z$5) -> 0 | AA23: =SUM(S23:Z23) -> 82 | AB23: =AA23=D23 -> TRUE
A24: II | B24: WTG ELECTRICAL (USS, Trafo & 33kV)
A25: 1 | B25: USS Erection | C25: 194 | D25: ='WTG PH-III'!ED4 -> 117 | E25: =C25-D25 -> 77 | G25: =COUNTIFS('WTG PH-III'!$EA$5:$EA$198,">="&T1,'WTG PH-III'!$EA$5:$EA$198,"<="&U1) -> 0 | H25: =COUNTIFS('WTG PH-III'!$ED$5:$ED$198,">="&T1,'WTG PH-III'!$ED$5:$ED$198,"<="&U1) -> 2 | I25: =G25-H25 -> -2 | M25: =K25-L25 -> 0 | O25: =COUNTIFS('WTG PH-III'!$EA$5:$EA$198,">=8-feb-25",'WTG PH-III'!$EA$5:$EA$198,"<="&U1) -> 194 | P25: =COUNTIFS('WTG PH-III'!$ED$5:$ED$198,">=08-Feb-25",'WTG PH-III'!$ED$5:$ED$198,"<="&U1) -> 117 | Q25: =O25-P25 -> 77 | S25: =COUNTIFS('WTG PH-III'!$ED$5:$ED$205,">0",'WTG PH-III'!$C$5:$C$205,S$4,'WTG PH-III'!$B$5:$B$205,SUMMARY!S$5) -> 5 | T25: =COUNTIFS('WTG PH-III'!$ED$5:$ED$205,">0",'WTG PH-III'!$C$5:$C$205,T$4,'WTG PH-III'!$B$5:$B$205,SUMMARY!T$5) -> 7 | U25: =COUNTIFS('WTG PH-III'!$ED$5:$ED$205,">0",'WTG PH-III'!$C$5:$C$205,U$4,'WTG PH-III'!$B$5:$B$205,SUMMARY!U$5) -> 39 | V25: =COUNTIFS('WTG PH-III'!$ED$5:$ED$205,">0",'WTG PH-III'!$C$5:$C$205,V$4,'WTG PH-III'!$B$5:$B$205,SUMMARY!V$5) -> 2 | W25: =COUNTIFS('WTG PH-III'!$ED$5:$ED$205,">0",'WTG PH-III'!$C$5:$C$205,W$4,'WTG PH-III'!$B$5:$B$205,SUMMARY!W$5) -> 36 | X25: =COUNTIFS('WTG PH-III'!$ED$5:$ED$205,">0",'WTG PH-III'!$C$5:$C$205,X$4,'WTG PH-III'!$B$5:$B$205,SUMMARY!X$5) -> 25 | Y25: =COUNTIFS('WTG PH-III'!$ED$5:$ED$205,">0",'WTG PH-III'!$C$5:$C$205,Y$4,'WTG PH-III'!$B$5:$B$205,SUMMARY!Y$5) -> 3 | Z25: =COUNTIFS('WTG PH-III'!$ED$5:$ED$205,">0",'WTG PH-III'!$C$5:$C$205,X$4,'WTG PH-III'!$B$5:$B$205,SUMMARY!Z$5) -> 0 | AA25: =SUM(S25:Z25) -> 117 | AB25: =AA25=D25 -> TRUE
